Workbook
Name ㄹㄹㄹ: #REF!
Name ㄹㄹㄹ: #REF!
Name ㄹㄹㄹ: #REF!
Name ㅁ1: #REF!
Name ㅁ1: #REF!
Name ㅁ1: #REF!
Name ㅁ1: #REF!
Name ㅇㅇ: #REF!
Name ㅇㅇㅇ: #REF!

Sheet 수입예산 총괄표
A1: 수입예산 총괄표(출연금+위탁사업비)
H2: (단위 : 천 원)
A3: 과 목 | F3: 예산액 | G3: 전년도예산액 | H3: 비교증감
A4: 구분 | B4: 관 | C4: 항 | D4: 세항 | E4: 목
A5: 총계(사업예산+자본예산) | F5: =F6 -> 24529000 | G5: =G6 -> 2420000 | H5: =F5-G5 -> 22109000
A6: 자체수입금 | F6: =SUM(F7,F20) -> 24529000 | G6: =SUM(G7,G20) -> 2420000 | H6: =F6-G6 -> 22109000
B7: 600 사업수익 | F7: =SUM(F8,F17) -> 24529000 | G7: =G8 -> 1560000 | H7: =F7-G7 -> 22969000
C8: 610 영업수익 | F8: =SUM(F9,F11,F13,F15) -> 24511000 | G8: =G14 -> 1560000 | H8: =F8-G8 -> 22951000
D9: 623 대행사업수익 | F9: =F10 -> 22550000 | G9: =G10 -> 0 | H9: =F9-G9 -> 22550000
E10: 01 직접관리비수익 | F10: 22550000 | G10: 0 | H10: =F10-G10 -> 22550000
D11: 647 기부금수익 | F11: =F12 -> 0 | G11: =G12 -> 0 | H11: =F11-G11 -> 0
E12: 01 기부금수익 | F12: 0 | G12: 0 | H12: =F12-G12 -> 0
D13: 648 출연금 수익 | F13: =F14 -> 1861000 | G13: =G14 -> 1560000 | H13: =F13-G13 -> 301000
E14: 02 자치단체출연금수익 | F14: 1861000 | G14: 1560000 | H14: =F14-G14 -> 301000
D15: 649 후원금 수익 | F15: =F16 -> 100000 | G15: =G16 -> 0 | H15: =F15-G15 -> 100000
E16: 01 지정후원금수익 | F16: 100000 | G16: 0 | H16: =F16-G16 -> 100000
C17: 670 영업외수익 | F17: =F18 -> 18000 | G17: =G18 -> 0 | H17: =F17-G17 -> 18000
D18: 671 이자수익 | F18: =F19 -> 18000 | G18: =G19 -> 0 | H18: =F18-G18 -> 18000
E19: 01 예금이자수익 | F19: 18000 | G19: 0 | H19: =F19-G19 -> 18000
B20: 100 자본적수입 | F20: =F21 -> 0 | G20: 860000 | H20: =F20-G20 -> -860000
C21: 170 자본잉여금수입 | F21: =F22 -> 0 | G21: 860000 | H21: =F21-G21 -> -860000
D22: 177 출연금 수입 | F22: =F23 -> 0 | G22: 860000 | H22: =F22-G22 -> -860000
E23: 01 정부출연금 | F23: 0 | G23: 860000 | H23: =F23-G23 -> -860000

Sheet 지출예산 총괄표
A1: 지출예산 총괄표(출연금+위탁사업비)
G2: 1979000 | I2: (단위 : 천 원)
A3: 과 목 | G3: 예산액 | H3: 전년도예산액 | I3: 비교증감
A4: 구분 | B4: 정책사업
A5: 총계(출연금+위탁사업비) | G5: =G6+G19 -> 24529000 | H5: 2420000 | I5: =G5-H5 -> 22109000
A6: 출연금(사업예산+자본예산) | G6: =SUM(G7,G17) -> 1979000 | H6: 2420000 | I6: =G6-H6 -> -441000
A7: 사업예산 | G7: =SUM(G8:G16) -> 1979000 | H7: 2420000 | I7: =G7-H7 -> -441000
B8: 2026여수세계섬박람회 행정관리 | G8: =행정관리부!H5 -> 927348 | H8: 306750 | I8: =G8-H8 -> 620598
B9: 2026여수세계섬박람회 기획홍보 | G9: =기획홍보부!H5 -> 151892 | H9: 864500 | I9: =G9-H9 -> -712608
B10: 2026여수세계섬박람회 수익사업 | G10: =수익사업부!H5 -> 86166 | H10: 47200 | I10: =G10-H10 -> 38966
B11: 2026여수세계섬박람회 유치협력 | G11: =유치협력부!H5 -> 62518 | H11: 221270 | I11: =G11-H11 -> -158752
B12: 2026여수세계섬박람회 운영 | G12: =운영부!H5 -> 358632 | H12: 104400 | I12: =G12-H12 -> 254232
B13: 2026여수세계섬박람회 행사 | G13: =행사부!H5 -> 25268 | H13: 0 | I13: =G13-H13 -> 25268
B14: 2026여수세계섬박람회 시설조성 | G14: =시설조성부!H5 -> 25268 | H14: 47200 | I14: =G14-H14 -> -21932
B15: 2026여수세계섬박람회 전시연출 | G15: =전시연출부!H5 -> 25268 | H15: 104400 | I15: =G15-H15 -> -79132
B16: 예비비 | G16: =예비비!H6 -> 316640 | H16: 724280 | I16: =G16-H16 -> -407640
A17: 자본예산 | G17: =G18 -> 0 | H17: 0 | I17: =G17-H17 -> 0
B18: 예비비(자본) | G18: =예비비!H13 -> 0 | H18: 0 | I18: =G18-H18 -> 0
A19: 위탁사업비(사업예산+자본예산) | G19: =G20+G25 -> 22550000 | H19: 0 | I19: =G19-H19 -> 22550000
A20: 사업예산 | G20: =SUM(G21:G24) -> 5450000 | H20: 0 | I20: =G20-H20 -> 5450000
B21: 2026여수세계섬박람회 기획홍보(위탁) | G21: ='기획본부(위탁)'!H6 -> 2000000 | H21: 0 | I21: =G21-H21 -> 2000000
B22: 2026여수세계섬박람회 유치협력(위탁) | G22: ='기획본부(위탁)'!H30 -> 950000 | H22: 0 | I22: =G22-H22 -> 950000
B23: 2026여수세계섬박람회 행사(위탁) | G23: ='운영본부(위탁)'!H6 -> 1000000 | H23: 0 | I23: =G23-H23 -> 1000000
B24: 2026여수세계섬박람회 전시연출(위탁) | G24: ='운영본부(위탁)'!H19 -> 1500000 | H24: 0 | I24: =G24-H24 -> 1500000
A25: 자본예산 | G25: =SUM(G26:G27) -> 17100000 | H25: 0 | I25: =G25-H25 -> 17100000
B26: 2026여수세계섬박람회 시설조성(위탁) | G26: ='운영본부(위탁)'!H27 -> 10300000 | H26: 0 | I26: =G26-H26 -> 10300000
B27: 2026여수세계섬박람회 전시연출(위탁) | G27: ='운영본부(위탁)'!H57 -> 6800000 | H27: 0 | I27: =G27-H27 -> 6800000

Sheet 지출예산
A1: 지출예산 총괄표
G2: 1979000 | I2: (단위 : 천 원)
A3: 과 목 | G3: 당년도예산액 (A) | H3: 전년도예산액 (B) | I3: 증 감 (A-B)
A4: 구분 | B4: 정책사업 | C4: 단위사업 | D4: 세부사업 | E4: 목 | F4: 세목
A5: 총계 | G5: =G6+G174 -> 1979000 | H5: 2420000 | I5: =G5-H5 -> -441000
A6: 사업예산 | G6: =SUM(G42,G101,G75,G7,G114,G133,G145,G157,G169) -> 1979000 | H6: 2420000 | I6: =G6-H6 -> -441000
B7: 2026여수세계섬박람회 행정관리 | G7: =SUM(G8,G16) -> 927348 | H7: 306750 | I7: =G7-H7 -> 620598
C8: 2026여수세계섬박람회 행정 업무추진 | G8: =SUM(G9,G12) -> 80420 | H8: =SUM(H9,H12) -> 44930 | I8: =G8-H8 -> 35490
D9: 직원역량강화 워크숍 | G9: =G10 -> 32960 | H9: =H10 -> 18180 | I9: =G9-H9 -> 14780
E10: 교육훈련비 | G10: =행정관리부!H10 -> 32960 | H10: =H11 -> 18180 | I10: =G10-H10 -> 14780
F11: 교육훈련경비 | G11: =행정관리부!H11 -> 32960 | H11: =행정관리부!I11 -> 18180 | I11: =G11-H11 -> 14780
D12: 이사회 및 각종 위원회 운영 | G12: =G13 -> 47460 | H12: =SUM(H13) -> 26750 | I12: =G12-H12 -> 20710
E13: 일반운영비 | G13: =행정관리부!H16 -> 47460 | H13: =행정관리부!I16 -> 26750 | I13: =G13-H13 -> 20710
F14: 사무관리비 | G14: =행정관리부!H17 -> 45060 | H14: =행정관리부!I17 -> 25100 | I14: =G14-H14 -> 19960
F15: 회의비 | G15: =행정관리부!H28 -> 2400 | H15: =행정관리부!I28 -> 250 | I15: =G15-H15 -> 2150
C16: 사무국운영 | G16: =G17 -> 846928 | H16: =H17 -> 254000 | I16: =G16-H16 -> 592928
D17: 기본경비 | G17: =SUM(G18,G22,G24,G28,G30,G32,G35,G37,G40) -> 846928 | H17: =SUM(H18,H22,H24,H28,H30,H32,H35,H37,H40) -> 254000 | I17: =G17-H17 -> 592928
E18: 인건비 | G18: =행정관리부!H33 -> 609331 | H18: =행정관리부!I33 -> 94800 | I18: =G18-H18 -> 514531
F19: 보수 | G19: =행정관리부!H34 -> 392400 | H19: =행정관리부!I34 -> 94800 | I19: =G19-H19 -> 297600
F20: 기타직보수 | G20: =행정관리부!H39 -> 186102 | H20: =행정관리부!I39 -> 0 | I20: =G20-H20 -> 186102
F21: 기간제근로자등보수 | G21: =행정관리부!H44 -> 30829 | H21: =행정관리부!I44 -> 0 | I21: =G21-H21 -> 30829
E22: 퇴직급여 | G22: =행정관리부!H48 -> 10500 | H22: =행정관리부!I48 -> 0 | I22: =G22-H22 -> 10500
F23: 퇴직급여충당금 | G23: =행정관리부!H49 -> 10500 | H23: =행정관리부!I49 -> 0 | I23: =G23-H23 -> 10500
E24: 일반운영비 | G24: =행정관리부!H52 -> 115440 | H24: =행정관리부!I52 -> 93320 | I24: =G24-H24 -> 22120
F25: 사무관리비 | G25: =행정관리부!H53 -> 72560 | H25: =행정관리부!I53 -> 40400 | I25: =G25-H25 -> 32160
F26: 공공운영비 | G26: =행정관리부!H68 -> 21760 | H26: =행정관리부!I68 -> 11160 | I26: =G26-H26 -> 10600
F27: 복리후생비 | G27: =행정관리부!H75 -> 21120 | H27: =행정관리부!I75 -> 41760 | I27: =G27-H27 -> -20640
E28: 여비 | G28: =행정관리부!H81 -> 18000 | H28: =행정관리부!I81 -> 15400 | I28: =G28-H28 -> 2600
F29: 국내여비 | G29: =행정관리부!H82 -> 18000 | H29: =행정관리부!I82 -> 15400 | I29: =G29-H29 -> 2600
E30: 업무추진비 | G30: =행정관리부!H85 -> 38400 | H30: =행정관리부!I85 -> 26600 | I30: =G30-H30 -> 11800
F31: 사업업무추진비 | G31: =행정관리부!H86 -> 38400 | H31: =행정관리부!I86 -> 26600 | I31: =G31-H31 -> 11800
E32: 직무수행경비 | G32: =행정관리부!H93 -> 25920 | H32: =행정관리부!I93 -> 14760 | I32: =G32-H32 -> 11160
F33: 직급보조비 | G33: =행정관리부!H94 -> 19200 | H33: =행정관리부!I94 -> 9000 | I33: =G33-H33 -> 10200
F34: 특정업무경비 | G34: =행정관리부!H97 -> 6720 | H34: =행정관리부!I97 -> 5760 | I34: =G34-H34 -> 960
E35: 수선유지교체비 | G35: =행정관리부!H99 -> 5000 | H35: =행정관리부!I99 -> 2000 | I35: =G35-H35 -> 3000
F36: 수선유지비 | G36: =행정관리부!H100 -> 5000 | H36: =행정관리부!I100 -> 2000 | I36: =G36-H36 -> 3000
E37: 관서업무비 | G37: =행정관리부!H102 -> 4740 | H37: =행정관리부!I102 -> 7120 | I37: =G37-H37 -> -2380
F38: 정원가산업무비 | G38: =행정관리부!H103 -> 2640 | H38: =행정관리부!I103 -> 2320 | I38: =G38-H38 -> 320
F39: 부서업무비 | G39: =행정관리부!H105 -> 2100 | H39: =행정관리부!I105 -> 4800 | I39: =G39-H39 -> -2700
E40: 연금부담금 등 | G40: =행정관리부!H108 -> 19597 | H40: =행정관리부!I108 -> 0 | I40: =G40-H40 -> 19597
...

Sheet 행정관리부
A1: 지출예산(세부사업) - 행정관리부 | M1: 단위 : 천원
A2: 구 분 | B2: 사업 | E2: 편성목 | H2: 당년도예산액 (A) | I2: 전년도예산액 (B) | J2: 증 감 (A-B) | K2: 산 출 기 초
B3: 정책 | C3: 단위 | D3: 세부 | E3: 그룹 | F3: 목 | G3: 세목
A4: 총계(사업예산 + 자본예산) | H4: =H5 -> 927348 | I4: =I5 -> 306750 | J4: =H4-I4 -> 620598
A5: 사업예산 | H5: =H6 -> 927348 | I5: =I6 -> 306750 | J5: =H5-I5 -> 620598
B6: 2026여수세계섬박람회 행정관리 | H6: =SUM(H7,H30) -> 927348 | I6: =SUM(I7,I30) -> 306750 | J6: =H6-I6 -> 620598
C7: 2026여수세계섬박람회 행정 업무추진 | H7: =SUM(H8,H14) -> 80420 | I7: =SUM(I8,I14) -> 52750 | J7: =H7-I7 -> 27670
D8: 직원역랑강화 워크숍 | H8: =H9 -> 32960 | I8: 18180 | J8: =H8-I8 -> 14780
E9: 200 물건비 | H9: =H10 -> 32960 | I9: 18180 | J9: =H9-I9 -> 14780
F10: 213 교육훈련비 | H10: =H11 -> 32960 | I10: 18180 | J10: =H10-I10 -> 14780
G11: 교육훈련경비 | H11: =M11 -> 32960 | I11: 18180 | J11: =H11-I11 -> 14780 | K11: [교육훈련경비] | M11: =SUM(M12:M13) -> 32960
K12: ○ 직원역량강화 교육 강사수당 : 370,000원*2명*4회 | L12: = | M12: 2960
K13: ○ 현장체험 등 워크숍 운영 경비 : 15,000,000원*2회 | L13: = | M13: 30000
D14: 이사회 및 각종 위원회 운영 | H14: =H15 -> 47460 | I14: 34570 | J14: =H14-I14 -> 12890
E15: 200 물건비 | H15: =H16 -> 47460 | I15: 34570 | J15: =H15-I15 -> 12890
F16: 201 일반운영비 | H16: =SUM(H17,H28) -> 47460 | I16: 26750 | J16: =H16-I16 -> 20710
G17: 01 사무관리비 | H17: =SUM(M17,M20,M26) -> 45060 | I17: 25100 | J17: =H17-I17 -> 19960 | K17: [일반수용비] | M17: =SUM(M18:M19) -> 2560
K18: ○ 이사회 책자 제작 및 소모품 구입 : 20,000원*13명*6회 | L18: = | M18: 1560
K19: ○ 이사회 변경등기 및 법무사 수수료 : 1,000,000원*1식 | L19: = | M19: 1000
K20: [운영수당] | M20: =SUM(M21:M25) -> 30500
K21: ○ 이사회 참석수당 : 150,000원*13명*6회 | L21: = | M21: 11700
K22: ○ 이사회 참석자 실비보상 : 110,000원*13명*6회 | L22: = | M22: 8580
K23: ○ 인사위원회 참석수당 : 100,000원*3명*5회 | L23: = | M23: 1500
K24: ○ 명예위원장, 부위원장, 특별위원회 위원 등 행사 참석 실비 : 110,000원*13명*4회 | L24: = | M24: 5720
K25: ○ 계약심의위원회 수당 등 지급 : 100,000원*6명*5회 | L25: = | M25: 3000
K26: [임차료] | M26: =M27 -> 12000
K27: ○ 이사회 개최를 위한 회의실 임차료 : 300,000원*4회 | L27: = | M27: 12000
G28: 14 회의비 | H28: =M28 -> 2400 | I28: 250 | J28: =H28-I28 -> 2150 | K28: [회의비] | M28: =M29 -> 2400
K29: ○ 이사회 등 회의 운영비 : 400,000원*6회 | L29: = | M29: 2400
C30: 사무국운영 | H30: =H31 -> 846928 | I30: 254000 | J30: =H30-I30 -> 592928
D31: 기본경비 | H31: =SUM(H32,H51,H107) -> 846928 | I31: 254000 | J31: =H31-I31 -> 592928
E32: 100 인건비 | H32: =SUM(H33,H48) -> 619831 | I32: 94800 | J32: =H32-I32 -> 525031
F33: 101 인건비 | H33: =SUM(H34,H39,H44) -> 609331 | I33: 94800 | J33: =H33-I33 -> 514531
G34: 01 보수 | H34: =SUM(M34,M37) -> 392400 | I34: 94800 | J34: =H34-I34 -> 297600 | K34: [직원파견수당] | M34: =SUM(M35:M36) -> 302400
K35: ○ 4급이상 : 600,000원*2명*12월 | L35: = | M35: 14400
K36: ○ 5급이하 : 400,000원*60명*12월 | L36: = | M36: 288000
K37: [주거지원비] | M37: =M38 -> 90000
K38: ○ 타시군(도) 주거지원비 : 500,000원*15명*12월 | L38: = | M38: 90000
G39: 02 기타직 보수 | H39: =SUM(M39,M42) -> 186102 | I39: 0 | J39: =H39-I39 -> 186102 | K39: [사무총장] | M39: =SUM(M40:M41) -> 102102
K40: ○ 연봉 : 8,468,460원*12월 | L40: = | M40: 101622
...

Sheet 기획홍보부
A1: 지출예산(세부사업) - 기획홍보부 | M1: 단위 : 천원
A2: 구 분 | B2: 사업 | E2: 편성목 | H2: 당년도예산액 (A) | I2: 전년도예산액 (B) | J2: 증 감 (A-B) | K2: 산 출 기 초
B3: 정책 | C3: 단위 | D3: 세부 | E3: 그룹 | F3: 목 | G3: 세목
A4: 총계(사업예산 + 자본예산) | H4: =H5 -> 151892 | I4: =I5 -> 864500 | J4: =H4-I4 -> -712608
A5: 사업예산 | H5: =H6 -> 151892 | I5: 864500 | J5: =H5-I5 -> -712608
B6: 2026여수세계섬박람회 기획홍보 | H6: =SUM(H7,H19,H25,H43) -> 151892 | I6: 864500 | J6: =H6-I6 -> -712608
C7: 2026여수세계섬박람회 기획 | H7: =H8 -> 28600 | I7: 320050 | J7: =H7-I7 -> -291450
D8: 자문위원회 운영 | H8: =H9 -> 28600 | I8: 31500 | J8: =H8-I8 -> -2900
E9: 200 물건비 | H9: =SUM(H10) -> 28600 | I9: 31500 | J9: =H9-I9 -> -2900
F10: 201 일반운영비 | H10: =SUM(H11,H15,H17) -> 28600 | I10: 31500 | J10: =H10-I10 -> -2900
G11: 01 사무관리비 | H11: =M11 -> 28000 | I11: 30000 | J11: =H11-I11 -> -2000 | K11: [운영수당] | M11: =SUM(M12:M14) -> 28000
K12: ○ 자문위원회 자문수당(대면) : 150,000원*3회*32명 | L12: = | M12: 14400
K13: ○ 자문위원회 자문수당(서면) : 100,000원*3회*32명 | L13: = | M13: 9600
K14: ○ 자문위원회 참석자 실비 보상 : 4,000,000원*1식 | L14: = | M14: 4000
G15: 03 행사운영비 | H15: =M15 -> 300 | I15: 1000 | J15: =H15-I15 -> -700 | K15: [행사운영비] | M15: =M16 -> 300
K16: ○ 자문위원회 운영 행사운영비 : 100,000원*3회 | L16: = | M16: 300
G17: 14 회의비 | H17: =M17 -> 300 | I17: 500 | J17: =H17-I17 -> -200 | K17: [회의비] | M17: =M18 -> 300
K18: ○ 자문위원회 회의 운영비 : 50,000원*6회 | L18: = | M18: 300
C19: 2026여수세계섬박람회 홍보 | H19: =H20 -> 50000 | I19: 526850 | J19: =H19-I19 -> -476850
D20: 홈페이지 유지관리 | H20: =H21 -> 50000 | I20: 25000 | J20: =H20-I20 -> 25000
E21: 200 물건비 | H21: =H22 -> 50000 | I21: 25000 | J21: =H21-I21 -> 25000
F22: 214 수선유지교체비 | H22: =H23 -> 50000 | I22: 25000 | J22: =H22-I22 -> 25000
G23: 05 수선유지비 | H23: =M23 -> 50000 | I23: 25000 | J23: =H23-I23 -> 25000 | K23: [수선유지비] | M23: =SUM(M24:M24) -> 50000
K24: ○ 누리집 유지관리 용역 : 50,000,000원*1식 | L24: = | M24: 50000
C25: 기획홍보부 부서운영 | H25: =H26 -> 28292 | I25: 19800 | J25: =H25-I25 -> 8492
D26: 기본경비 | H26: =H27 -> 28292 | I26: 19800 | J26: =H26-I26 -> 8492
E27: 200 물건비 | H27: =SUM(H28,H33,H37,H40) -> 28292 | I27: 19800 | J27: =H27-I27 -> 8492
F28: 201 일반운영비 | H28: =H29+H31 -> 9792 | I28: 3600 | J28: =H28-I28 -> 6192
G29: 01 사무관리비 | H29: =M29 -> 2880 | I29: 3600 | J29: =H29-I29 -> -720 | K29: [일반수용비] | M29: =SUM(M30:M30) -> 2880
K30: ○ 부서 운영을 위한 소모품 구입 : 240,000원*12월 | L30: = | M30: 2880
G31: 15 복리후생비 | H31: =M31 -> 6912 | I31: 0 | J31: =H31-I31 -> 6912 | K31: [급량비] | M31: =SUM(M32:M32) -> 6912
K32: ○ 기본업무수행 급량비 : 9,000원*8명*8일*12월 | L32: = | M32: 6912
F33: 202 여비 | H33: =H34 -> 14400 | I33: 13200 | J33: =H33-I33 -> 1200
G34: 01 국내여비 | H34: =M34 -> 14400 | I34: 13200 | J34: =H34-I34 -> 1200 | K34: [국내여비] | M34: =SUM(M35:M36) -> 14400
K35: ○ 기획홍보부 기본업무 수행 관내여비 : 20,000원*8명*2일*12월 | L35: = | M35: 3840
K36: ○ 기획홍보부 기본업무 수행 관외여비 : 110,000원*8명*12월 | L36: = | M36: 10560
F37: 203 업무추진비 | H37: =H38 -> 2000 | I37: 3000 | J37: =H37-I37 -> -1000
G38: 07 사업업무추진비 | H38: =M38 -> 2000 | I38: 3000 | J38: =H38-I38 -> -1000 | K38: [사업업무추진비] | M38: =M39 -> 2000
K39: ○ 기획홍보부 업무추진 : 2,000,000원*1식 | L39: = | M39: 2000
F40: 217 관서업무비 | H40: =H41 -> 2100 | I40: 0 | J40: =H40-I40 -> 2100
...

Sheet 수익사업부
A1: 지출예산(세부사업) - 수익사업부 | M1: 단위 : 천원
A2: 구 분 | B2: 사업 | E2: 편성목 | H2: 당년도예산액 (A) | I2: 전년도예산액 (B) | J2: 증 감 (A-B) | K2: 산 출 기 초
B3: 정책 | C3: 단위 | D3: 세부 | E3: 그룹 | F3: 목 | G3: 세목
A4: 총계(사업예산 + 자본예산) | H4: =H5 -> 86166 | I4: =I5 -> 47200 | J4: =H4-I4 -> 38966
A5: 사업예산 | H5: =H6 -> 86166 | I5: 47200 | J5: =H5-I5 -> 38966
B6: 2026여수세계섬박람회 수익사업 | H6: =SUM(H7,H34) -> 86166 | I6: 47200 | J6: =H6-I6 -> 38966
C7: 2026여수세계섬박람회 수익사업 | H7: =SUM(H8,H18,H24) -> 53850 | I7: 0 | J7: =H7-I7 -> 53850
D8: 박람회 휘장업무 추진 | H8: =H9 -> 14450 | I8: 0 | J8: =H8-I8 -> 14450
E9: 200 물건비 | H9: =H10 -> 14450 | I9: 0 | J9: =H9-I9 -> 14450
F10: 201 일반운영비 | H10: =H11+H16 -> 14450 | I10: 0 | J10: =H10-I10 -> 14450
G11: 01 사무관리비 | H11: =M11 -> 10450 | I11: 0 | J11: =H11-I11 -> 10450 | K11: [일반수용비] | M11: =SUM(M12:M15) -> 10450
K12: ○ 후원·기부 유치를 위한 홍보물 제작 : 5,000,000원*1식 | L12: = | M12: 5000
K13: ○ 공식상품화권자 선정 심사수당 : 250,000원*7명*1회 | L13: = | M13: 1750
K14: ○ 공식상품화권자 선정 심사위원 교통비 등 기타실비 : 700,000원*1식 | L14: = | M14: 700
K15: ○ 박람회 인정상품 엠블럼 제작 : 3,000,000원*1식 | L15: = | M15: 3000 | N15: ○ 직원 병가 및 휴직 등 공백발생 시 채용(인건비 23년 기준)
G16: 03 행사운영비 | H16: =M16 -> 4000 | I16: 0 | J16: =H16-I16 -> 4000 | K16: [행사운영비] | M16: =SUM(M17:M17) -> 4000
K17: ○ 후원 협약식 개최 : 800,000원*5회 | L17: = | M17: 4000
D18: 박람회 기부금품 관리 | H18: =SUM(H19) -> 7000 | I18: 0 | J18: =H18-I18 -> 7000
E19: 200 물건비 | H19: =H20 -> 7000 | I19: 0 | J19: =H19-I19 -> 7000
F20: 201 일반운영비 | H20: =H21 -> 7000 | I20: 0 | J20: =H20-I20 -> 7000
G21: 01 사무관리비 | H21: =M21 -> 7000 | I21: 0 | J21: =H21-I21 -> 7000 | K21: [일반수용비] | M21: =SUM(M22:M23) -> 7000
K22: ○ 기부금품 전달식 개최 : 300,000원*10회 | L22: = | M22: 3000
K23: ○ 기부자 예우 물품 제작 : 20,000원*200개 | L23: = | M23: 4000
D24: 박람회 입장권 사업 | H24: =SUM(H25,H30) -> 32400 | I24: 0 | J24: =H24-I24 -> 32400
E25: 200 물건비 | H25: =H26 -> 22400 | I25: 0 | J25: =H25-I25 -> 22400
F26: 201 일반운영비 | H26: =H27 -> 22400 | I26: 0 | J26: =H26-I26 -> 22400
G27: 01 사무관리비 | H27: =M27 -> 22400 | I27: 0 | J27: =H27-I27 -> 22400 | K27: [일반수용비] | M27: =SUM(M28:M29) -> 22400
K28: ○ 입장권 판촉 홍보물 제작 : 20,000,000원*1식 | L28: = | M28: 20000
K29: ○ 입장권 사업 추진 사무용품 구입 : 200,000원*12월 | L29: = | M29: 2400
E30: 300 경상이전 | H30: =H31 -> 10000 | I30: 0 | J30: =H30-I30 -> 10000
F31: 301 일반보상금 | H31: =H32 -> 10000 | I31: 0 | J31: =H31-I31 -> 10000
G32: 14 기타보상금 | H32: =M32 -> 10000 | I32: 0 | J32: =H32-I32 -> 10000 | K32: [기타보상금] | M32: =M33 -> 10000
K33: ○ 입장권 구매보상금 지급 : 10,000,000원*1식 | L33: = | M33: 10000
C34: 수익사업부 부서운영 | H34: =H35 -> 32316 | I34: 47200 | J34: =H34-I34 -> -14884
D35: 기본경비 | H35: =H36 -> 32316 | I35: 47200 | J35: =H35-I35 -> -14884
E36: 200 물건비 | H36: =SUM(H37,H44,H48,H51) -> 32316 | I36: 47200 | J36: =H36-I36 -> -14884
F37: 201 일반운영비 | H37: =SUM(H38,H40,H42) -> 12016 | I37: 21100 | J37: =H37-I37 -> -9084
G38: 01 사무관리비 | H38: =M38 -> 3240 | I38: 20350 | J38: =H38-I38 -> -17110 | K38: [일반수용비] | M38: =SUM(M39:M39) -> 3240
K39: ○ 부서 운영을 위한 소모품 구입 : 270,000원*12월 | L39: = | M39: 3240 | N39: ○ 수영강사 공무직 전환으로 본부 일괄 편성
G40: 02 공공운영비 | H40: =M40 -> 1000 | I40: 750 | J40: =H40-I40 -> 250 | K40: [우편료] | M40: =SUM(M41) -> 1000 | N40: '- 새벽출근(05:30)에 따른 야간근무 | P40: 10380 | Q40: 0.5 | R40: 0.5 | S40: 4 | T40: 5 | U40: 52
...

Sheet 유치협력부
A1: 지출예산(세부사업) - 유치협력부 | M1: 단위 : 천원
A2: 구 분 | B2: 사업 | E2: 편성목 | H2: 당년도예산액 (A) | I2: 전년도예산액 (B) | J2: 증 감 (A-B) | K2: 산 출 기 초
B3: 정책 | C3: 단위 | D3: 세부 | E3: 그룹 | F3: 목 | G3: 세목
A4: 총계(사업예산 + 자본예산) | H4: =H5 -> 62518 | I4: =I5 -> 221270 | J4: =H4-I4 -> -158752
A5: 사업예산 | H5: =H6 -> 62518 | I5: 221270 | J5: =H5-I5 -> -158752
B6: 2026여수세계섬박람회 유치협력 | H6: =H7 -> 62518 | I6: 221270 | J6: =H6-I6 -> -158752
C7: 유치협력부 부서운영 | H7: =H8 -> 62518 | I7: 17600 | J7: =H7-I7 -> 44918
D8: 기본경비 | H8: =H9 -> 62518 | I8: 17600 | J8: =H8-I8 -> 44918
E9: 200 물건비 | H9: =SUM(H10,H19,H25,H29) -> 62518 | I9: 17600 | J9: =H9-I9 -> 44918
F10: 201 일반운영비 | H10: =SUM(H11,H15,H17) -> 19818 | I10: 3600 | J10: =H10-I10 -> 16218
G11: 01 사무관리비 | H11: =M11 -> 5770 | I11: 3600 | J11: =H11-I11 -> 2170 | K11: [일반수용비] | M11: =SUM(M12:M14) -> 5770
K12: ○ 부서 운영을 위한 소모품 구입 : 210,000원*12월 | L12: = | M12: 2520
K13: ○ 국내외 유치마케팅 대행사 선정 심사수당 : 250,000원*9명*1회 | L13: = | M13: 2250
K14: ○ 국내외 유치마케팅 대행사 선정 심사위원 교통비 등 기타실비 : 1,000,000원*1식 | L14: = | M14: 1000
G15: 02 공공운영비 | H15: =M15 -> 8000 | I15: 15000 | J15: =H15-I15 -> -7000 | K15: [우편료] | M15: =SUM(M16) -> 8000
K16: ○ 국내·외 관람객 홍보물 등 발송 우편료 : 2,500원*3,200개소 | L16: = | M16: 8000
G17: 15 복리후생비 | H17: =M17 -> 6048 | I17: 0 | J17: =H17-I17 -> 6048 | K17: [급량비] | M17: =SUM(M18) -> 6048
K18: ○ 기본업무수행 급량비 : 9,000원*7명*8일*12월 | L18: = | M18: 6048
F19: 202 여비 | H19: =H20+H23 -> 36600 | I19: 37000 | J19: =H19-I19 -> -400
G20: 01 국내여비 | H20: =M20 -> 12600 | I20: 11000 | J20: =H20-I20 -> 1600 | K20: [국내여비] | M20: =SUM(M21:M22) -> 12600
K21: ○ 유치협력 기본업무 수행 관내여비 : 20,000원*7명*2일*12월 | L21: = | M21: 3360 | AC21: 9
K22: ○ 유치협력 기본업무 수행 관외여비 : 110,000원*7명*12월 | L22: = | M22: 9240
G23: 03 국외업무여비 | H23: =M23 -> 24000 | I23: 26000 | J23: =H23-I23 -> -2000 | K23: [국외업무여비] | M23: =SUM(M24:M25) -> 24000
K24: ○ 자매도시 등 국제교류 및 각종 국제행사 참가 : 3,000,000원*2명*4회 | L24: = | M24: 24000 | AC24: 9
F25: 203 업무추진비 | H25: =H26 -> 4000 | I25: 3000 | J25: =H25-I25 -> 1000
G26: 07 사업업무추진비 | H26: =M26 -> 4000 | I26: 3000 | J26: =H26-I26 -> 1000 | K26: [사업업무추진비] | M26: =SUM(M27:M28) -> 4000
K27: ○ 유치협력부 업무추진 : 2,000,000원*1식 | L27: = | M27: 2000
K28: ○ 협력관 업무추진 : 2,000,000원*1식 | L28: = | M28: 2000
F29: 217 관서업무비 | H29: =H30 -> 2100 | I29: 0 | J29: =H29-I29 -> 2100
G30: 02 부서업무비 | H30: =M30 -> 2100 | I30: 0 | J30: =H30-I30 -> 2100 | K30: [부서업무비] | M30: =M31 -> 2100
K31: ○ 유치협력부 부서운영 총액계상 : 175,000원*12월 | L31: = | M31: 2100

Sheet 운영부
A1: 지출예산(세부사업) - 운영부 | M1: 단위 : 천원
A2: 구 분 | B2: 사업 | E2: 편성목 | H2: 당년도예산액 (A) | I2: 전년도예산액 (B) | J2: 증 감 (A-B) | K2: 산 출 기 초
B3: 정책 | C3: 단위 | D3: 세부 | E3: 그룹 | F3: 목 | G3: 세목
A4: 총계(사업예산 + 자본예산) | H4: =H5 -> 358632 | I4: 104400 | J4: =H4-I4 -> 254232
A5: 사업예산 | H5: =H6 -> 358632 | I5: 104400 | J5: =H5-I5 -> 254232
B6: 2026여수세계섬박람회 운영 | H6: =SUM(H7,H18) -> 358632 | I6: 104400 | J6: =H6-I6 -> 254232
C7: 박람회장 운영 | H7: =SUM(H8) -> 306500 | I7: 104400 | J7: =H7-I7 -> 202100
D8: 대행사 선정 | H8: =SUM(H9) -> 306500 | I8: 0 | J8: =H8-I8 -> 306500
E9: 200 물건비 | H9: =H10 -> 306500 | I9: 0 | J9: =H9-I9 -> 306500
F10: 201 일반운영비 | H10: =SUM(M11,M14,M16) -> 306500 | I10: 0 | J10: =H10-I10 -> 306500
G11: 01 사무관리비 | H11: =M11 -> 6000 | I11: 0 | J11: =H11-I11 -> 6000 | K11: [운영수당] | M11: =SUM(M12:M13) -> 6000
K12: ○ 대행사 선정 제안서 평가위원 수당 : 250,000원*10명*2회 | L12: = | M12: 5000
K13: ○ 대행사 선정 평가위원 실비 : 500,000원*2회 | L13: = | M13: 1000
G14: 03 행사운영비 | H14: =M14 -> 300000 | I14: 0 | J14: =H14-I14 -> 300000 | K14: [행사운영비] | M14: 300000
K15: ○ 종합실행계획 수립 및 운영대행 용역비(1차분) : 300,000,000원*1식 | L15: = | M15: 300000
G16: 14 회의비 | H16: =M16 -> 500 | I16: 0 | J16: =H16-I16 -> 500 | K16: [회의비] | M16: =M17 -> 500
K17: ○ 대행사 선정 평가위원회 운영비 : 250,000원*2회 | L17: = | M17: 500
C18: 운영부 사무국운영 | H18: =H19 -> 52132 | I18: 10425 | J18: =H18-I18 -> 41707
D19: 기본경비 | H19: =H20 -> 52132 | I19: 10425 | J19: =H19-I19 -> 41707
E20: 200 물건비 | H20: =SUM(H21,H28,H32,H38) -> 52132 | I20: 10425 | J20: =H20-I20 -> 41707
F21: 201 일반운영비 | H21: =SUM(H22,H26) -> 19912 | I21: 5275 | J21: =H21-I21 -> 14637
G22: 01 사무관리비 | H22: =M22 -> 13000 | I22: 5275 | J22: =H22-I22 -> 7725 | K22: [일반수용비] | M22: =SUM(M23:M25) -> 13000
K23: ○ 사무용품 등 소모품 구입 : 5,000,000원*1식 | L23: = | M23: 5000
K24: ○ 복사기 및 프린터토너 구입 : 3,000,000원*1식 | L24: = | M24: 3000
K25: ○ 사무실 환경정비용품 구입 : 5,000,000원*1식 | L25: = | M25: 5000
G26: 15 복리후생비 | H26: =M27 -> 6912 | I26: 0 | J26: =H26-I26 -> 6912 | K26: [급량비] | M26: =M27 -> 6912
K27: ○ 기본업무수행 급량비 : 9,000원*8명*8일*12월 | L27: = | M27: 6912
F28: 202 여비 | H28: =H29 -> 14400 | I28: 4400 | J28: =H28-I28 -> 10000
G29: 01 국내여비 | H29: =M29 -> 14400 | I29: 4400 | J29: =H29-I29 -> 10000 | K29: [국내여비] | M29: =SUM(M30:M31) -> 14400
K30: ○ 운영부 기본업무 수행 관내여비 : 20,000원*8명*2일*12월 | L30: = | M30: 3840
K31: ○ 운영부 기본업무 수행 관외여비 : 110,000원*8명*12월 | L31: = | M31: 10560
F32: 203 업무추진비 | H32: =H33 -> 13400 | I32: 750 | J32: =H32-I32 -> 12650
G33: 07 사업업무추진비 | H33: =SUM(M33,M35) -> 13400 | I33: 750 | J33: =H33-I33 -> 12650 | K33: [기관운영업무추진비] | M33: =SUM(M34:M34) -> 6600
K34: ○ 4급보조기관장(운영본부장) : 6,600,000원*1식 | L34: = | M34: 6600
K35: [시책추진업무추진비] | M35: =SUM(M36:M37) -> 6800
K36: ○ 박람회 운영 및 조성 업무추진(4급) : 4,800,000원*1식 | L36: = | M36: 4800
K37: ○ 운영부 업무추진 : 2,000,000원*1식 | L37: = | M37: 2000
F38: 217 관서업무비 | H38: =SUM(M39,M41) -> 4420 | I38: 0 | J38: =H38-I38 -> 4420
G39: 01 정원가산업무비 | H39: =M39 -> 2320 | I39: 0 | J39: =H39-I39 -> 2320 | K39: [정원가산업무비] | M39: =M40 -> 2320
K40: ○ 운영본부 정원가산총액계상 : 80,000원*29명 | L40: = | M40: 2320
...

Sheet 행사부
A1: 지출예산(세부사업) - 행사부 | M1: 단위 : 천원
A2: 구 분 | B2: 사업 | E2: 편성목 | H2: 당년도예산액 (A) | I2: 전년도예산액 (B) | J2: 증 감 (A-B) | K2: 산 출 기 초
B3: 정책 | C3: 단위 | D3: 세부 | E3: 그룹 | F3: 목 | G3: 세목
A4: 총계(사업예산 + 자본예산) | H4: =H5 -> 25268 | I4: 0 | J4: =H4-I4 -> 25268
A5: 사업예산 | H5: =H6 -> 25268 | I5: 0 | J5: =H5-I5 -> 25268
B6: 2026여수세계섬박람회 행사 | H6: =H7 -> 25268 | I6: 0 | J6: =H6-I6 -> 25268
C7: 행사부 부서운영 | H7: =H8 -> 25268 | I7: 0 | J7: =H7-I7 -> 25268
D8: 기본경비 | H8: =H9 -> 25268 | I8: 0 | J8: =H8-I8 -> 25268
E9: 200 물건비 | H9: =SUM(H10,H15,H19,H22) -> 25268 | I9: 0 | J9: =H9-I9 -> 25268
F10: 201 일반운영비 | H10: =SUM(H11,H13) -> 8568 | I10: 0 | J10: =H10-I10 -> 8568
G11: 01 사무관리비 | H11: =M11 -> 2520 | I11: 0 | J11: =H11-I11 -> 2520 | K11: [일반수용비] | M11: =SUM(M12:M12) -> 2520
K12: ○ 부서운영을 위한 소모품 구입 : 210,000원*12월 | L12: = | M12: 2520
G13: 15 복리후생비 | H13: =M13 -> 6048 | I13: 0 | J13: =H13-I13 -> 6048 | K13: [급량비] | M13: =SUM(M14) -> 6048
K14: ○ 기본업무수행 급량비 : 9,000원*7명*8일*12월 | L14: = | M14: 6048
F15: 202 여비 | H15: =H16 -> 12600 | I15: 0 | J15: =H15-I15 -> 12600
G16: 01 국내여비 | H16: =M16 -> 12600 | I16: 0 | J16: =H16-I16 -> 12600 | K16: [국내여비] | M16: =SUM(M17:M18) -> 12600
K17: ○ 행사부 기본업무 수행 관내여비 : 20,000원*7명*2일*12월 | L17: = | M17: 3360
K18: ○ 행사부 기본업무 수행 관외여비 : 110,000원*7명*12월 | L18: = | M18: 9240
F19: 203 업무추진비 | H19: =H20 -> 2000 | I19: 0 | J19: =H19-I19 -> 2000
G20: 07 사업업무추진비 | H20: =M20 -> 2000 | I20: 0 | J20: =H20-I20 -> 2000 | K20: [사업업무추진비] | M20: =SUM(M21) -> 2000
K21: ○ 행사부 업무추진 : 2,000,000원*1식 | L21: = | M21: 2000
F22: 217 관서업무비 | H22: =H23 -> 2100 | I22: 0 | J22: =H22-I22 -> 2100
G23: 02 부서업무비 | H23: =M23 -> 2100 | I23: 0 | J23: =H23-I23 -> 2100 | K23: [부서업무비] | M23: =M24 -> 2100
K24: ○ 행사부 부서운영 총액계상 : 175,000원*12월 | L24: = | M24: 2100

Sheet 시설조성부
A1: 지출예산(세부사업) - 시설조성부 | M1: 단위 : 천원
A2: 구 분 | B2: 사업 | E2: 편성목 | H2: 당년도예산액 (A) | I2: 전년도예산액 (B) | J2: 증 감 (A-B) | K2: 산 출 기 초
B3: 정책 | C3: 단위 | D3: 세부 | E3: 그룹 | F3: 목 | G3: 세목
A4: 총계(사업예산 + 자본예산) | H4: =H5 -> 25268 | I4: 47200 | J4: =H4-I4 -> -21932
A5: 사업예산 | H5: =H6 -> 25268 | I5: 47200 | J5: =H5-I5 -> -21932
B6: 2026여수세계섬박람회 시설조성 | H6: =H7 -> 25268 | I6: 47200 | J6: =H6-I6 -> -21932
C7: 시설조성부 부서운영 | H7: =H8 -> 25268 | I7: 47200 | J7: =H7-I7 -> -21932
D8: 기본경비 | H8: =H9 -> 25268 | I8: 47200 | J8: =H8-I8 -> -21932
E9: 200 물건비 | H9: =SUM(H10,H15,H19,H22) -> 25268 | I9: 47200 | J9: =H9-I9 -> -21932
F10: 201 일반운영비 | H10: =SUM(H11,H13) -> 8568 | I10: 21100 | J10: =H10-I10 -> -12532
G11: 01 사무관리비 | H11: =M11 -> 2520 | I11: 21100 | J11: =H11-I11 -> -18580 | K11: [일반수용비] | M11: =SUM(M12:M12) -> 2520
K12: ○ 부서운영을 위한 소모품 구입 : 210,000원*12월 | L12: = | M12: 2520
G13: 15 복리후생비 | H13: =M13 -> 6048 | I13: 0 | J13: =H13-I13 -> 6048 | K13: [급량비] | M13: =M14 -> 6048
K14: ○ 기본업무수행 급량비 : 9,000원*7명*8일*12월 | L14: = | M14: 6048
F15: 202 여비 | H15: =H16 -> 12600 | I15: 23100 | J15: =H15-I15 -> -10500
G16: 01 국내여비 | H16: =M16 -> 12600 | I16: 23100 | J16: =H16-I16 -> -10500 | K16: [국내여비] | M16: =SUM(M17:M18) -> 12600
K17: ○ 시설조성부 기본업무 수행 관내여비 : 20,000원*7명*2일*12월 | L17: = | M17: 3360
K18: ○ 시설조성부 기본업무 수행 관외여비 : 110,000원*7명*12월 | L18: = | M18: 9240
F19: 203 업무추진비 | H19: =H20 -> 2000 | I19: 3000 | J19: =H19-I19 -> -1000
G20: 07 사업업무추진비 | H20: =M20 -> 2000 | I20: 3000 | J20: =H20-I20 -> -1000 | K20: [사업업무추진비] | M20: =SUM(M21) -> 2000
K21: ○ 시설조성부 업무추진 : 2,000,000원*1식 | L21: = | M21: 2000
F22: 217 관서업무비 | H22: =H23 -> 2100 | I22: 0 | J22: =H22-I22 -> 2100
G23: 02 부서업무비 | H23: =M23 -> 2100 | I23: 0 | J23: =H23-I23 -> 2100 | K23: [부서업무비] | M23: =M24 -> 2100
K24: ○ 시설조성부 부서운영 총액계상 : 175,000원*12월 | L24: = | M24: 2100

Sheet 전시연출부
A1: 지출예산(세부사업) - 전시연출부 | M1: 단위 : 천원
A2: 구 분 | B2: 사업 | E2: 편성목 | H2: 당년도예산액 (A) | I2: 전년도예산액 (B) | J2: 증 감 (A-B) | K2: 산 출 기 초
B3: 정책 | C3: 단위 | D3: 세부 | E3: 그룹 | F3: 목 | G3: 세목
A4: 총계(사업예산 + 자본예산) | H4: =H5 -> 25268 | I4: 104400 | J4: =H4-I4 -> -79132
A5: 사업예산 | H5: =H6 -> 25268 | I5: 104000 | J5: =H5-I5 -> -78732
B6: 2026여수세계섬박람회 전시연출 | H6: =H7 -> 25268 | I6: 104000 | J6: =H6-I6 -> -78732
C7: 전시연출부 부서운영 | H7: =H8 -> 25268 | I7: 10425 | J7: =H7-I7 -> 14843
D8: 기본경비 | H8: =H9 -> 25268 | I8: 10425 | J8: =H8-I8 -> 14843
E9: 200 물건비 | H9: =SUM(H10,H15,H19,H22) -> 25268 | I9: 10425 | J9: =H9-I9 -> 14843
F10: 201 일반운영비 | H10: =SUM(H11,H13) -> 8568 | I10: 5275 | J10: =H10-I10 -> 3293
G11: 01 사무관리비 | H11: =M11 -> 2520 | I11: 5275 | J11: =H11-I11 -> -2755 | K11: [일반수용비] | M11: =SUM(M12:M12) -> 2520
K12: ○ 부서운영을 위한 소모품 구입 : 210,000원*12월 | L12: = | M12: 2520
G13: 15 복리후생비 | H13: =M13 -> 6048 | I13: 0 | J13: =H13-I13 -> 6048 | K13: [급량비] | M13: =SUM(M14) -> 6048
K14: ○ 기본업무수행 급량비 : 9,000원*7명*8일*12월 | L14: = | M14: 6048
F15: 202 여비 | H15: =H16 -> 12600 | I15: 4400 | J15: =H15-I15 -> 8200
G16: 01 국내여비 | H16: =M16 -> 12600 | I16: 4400 | J16: =H16-I16 -> 8200 | K16: [국내여비] | M16: =SUM(M17:M18) -> 12600
K17: ○ 전시연출부 기본업무 수행 관내여비 : 20,000원*7명*2일*12월 | L17: = | M17: 3360
K18: ○ 전시연출부 기본업무 수행 관외여비 : 110,000원*7명*12월 | L18: = | M18: 9240
F19: 203 업무추진비 | H19: =H20 -> 2000 | I19: 750 | J19: =H19-I19 -> 1250
G20: 07 사업업무추진비 | H20: =M20 -> 2000 | I20: 750 | J20: =H20-I20 -> 1250 | K20: [사업업무추진비] | M20: =SUM(M21) -> 2000
K21: ○ 전시연출부 업무추진 : 2,000,000원*1식 | L21: = | M21: 2000
F22: 217 관서업무비 | H22: =H23 -> 2100 | I22: 0 | J22: =H22-I22 -> 2100
G23: 02 부서업무비 | H23: =M23 -> 2100 | I23: 0 | J23: =H23-I23 -> 2100 | K23: [부서업무비] | M23: =M24 -> 2100
K24: ○ 전시연출부 부서운영 총액계상 : 175,000원*12월 | L24: = | M24: 2100

Sheet 예비비
A1: 지출예산(세부사업) - 예비비 | M1: 단위 : 천원
A2: 구 분 | B2: 사업 | E2: 편성목 | H2: 예산액 | I2: 기정액 | J2: 비교증감 | K2: 산 출 기 초
B3: 정책 | C3: 단위 | D3: 세부 | E3: 그룹 | F3: 목 | G3: 세목
A4: 총계(사업예산 + 자본예산) | H4: =H5+H13 -> 316640 | I4: 724280 | J4: =H4-I4 -> -407640
A5: 사업예산 | H5: =H6 -> 316640 | I5: 724280 | J5: =H5-I5 -> -407640
B6: 예비비 | H6: =H7 -> 316640 | I6: 724280 | J6: =H6-I6 -> -407640
C7: 예비비 | H7: =H8 -> 316640 | I7: 724280 | J7: =H7-I7 -> -407640
D8: 예비비 | H8: =H9 -> 316640 | I8: 724280 | J8: =H8-I8 -> -407640
E9: 800 예비비 | H9: =H10 -> 316640 | I9: 724280 | J9: =H9-I9 -> -407640
F10: 801 예비비 | H10: =H11 -> 316640 | I10: 724280 | J10: =H10-I10 -> -407640
G11: 01 일반예비비 | H11: =M11 -> 316640 | I11: 724280 | J11: =H11-I11 -> -407640 | K11: [일반예비비] | M11: =M12 -> 316640
K12: ○ 예비비 : 316,640,000원*1식 | M12: 316640
A13: 자본예산 | H13: =SUM(H14,H27) -> 0 | I13: 0 | J13: =H13-I13 -> 0
B14: 예비비(자본) | H14: =SUM(H15,H55) -> 0 | I14: 0 | J14: =H14-I14 -> 0
C15: 예비비(자본) | H15: =H16 -> 0 | I15: 0 | J15: =H15-I15 -> 0
D16: 예비비(자본) | H16: =H17 -> 0 | I16: 0 | J16: =H16-I16 -> 0
E17: 800 예비비 | H17: =H18 -> 0 | I17: 0 | J17: =H17-I17 -> 0
F18: 801 예비비 | H18: =H19 -> 0 | I18: 0 | J18: =H18-I18 -> 0
G19: 01 일반예비비 | H19: =M19 -> 0 | I19: 0 | J19: =H19-I19 -> 0 | K19: [일반예비비] | M19: =M20 -> 0
K20: ○ 예비비(자본) : 0원 | L20: = | M20: 0

Sheet 지출예산(위탁)
A1: 지출예산(위탁) - 본예산
I2: (단위 : 천 원)
A3: 과 목 | G3: 예산액 | H3: 기정액 | I3: 비교증감
A4: 구분 | B4: 정책사업 | C4: 단위사업 | D4: 세부사업 | E4: 목 | F4: 세목
A5: 총계(사업예산+자본예산) | G5: =G6+G43 -> 22550000 | H5: 0 | I5: =G5-H5 -> 22550000
A6: 사업예산 | G6: =SUM(G7,G16,G30,G38) -> 5450000 | H6: 0 | I6: =G6-H6 -> 5450000
B7: 2026여수세계섬박람회 기획홍보(위탁) | G7: ='기획본부(위탁)'!H6 -> 2000000 | H7: 0 | I7: =G7-H7 -> 2000000
C8: 2026여수세계섬박람회 홍보 | G8: ='기획본부(위탁)'!H7 -> 2000000 | H8: 0 | I8: =G8-H8 -> 2000000
D9: 박람회 홍보 | G9: ='기획본부(위탁)'!H8 -> 2000000 | H9: 0 | I9: =G9-H9 -> 2000000
E10: 일반운영비 | G10: ='기획본부(위탁)'!H10 -> 1974000 | H10: 0 | I10: =G10-H10 -> 1974000
F11: 사무관리비 | G11: ='기획본부(위탁)'!H11 -> 1419000 | H11: 0 | I11: =G11-H11 -> 1419000
F12: 행사운영비 | G12: ='기획본부(위탁)'!H19 -> 55000 | H12: 0 | I12: =G12-H12 -> 55000
F13: 광고선전비 | G13: ='기획본부(위탁)'!H23 -> 500000 | H13: 0 | I13: =G13-H13 -> 500000
E14: 일반보상금 | G14: ='기획본부(위탁)'!H26 -> 26000 | H14: 0 | I14: =G14-H14 -> 26000
F15: 기타보상금 | G15: ='기획본부(위탁)'!H27 -> 26000 | H15: 0 | I15: =G15-H15 -> 26000
B16: 2026여수세계섬박람회 유치협력(위탁) | G16: =G17 -> 950000 | H16: 0 | I16: =G16-H16 -> 950000
C17: 2026여수세계섬박람회 유치 | G17: ='기획본부(위탁)'!H31 -> 950000 | H17: 0 | I17: =G17-H17 -> 950000
D18: 관람객 유치 | G18: ='기획본부(위탁)'!H32 -> 660000 | H18: 0 | I18: =G18-H18 -> 660000
E19: 일반운영비 | G19: ='기획본부(위탁)'!H34 -> 498000 | H19: 0 | I19: =G19-H19 -> 498000
F20: 사무관리비 | G20: ='기획본부(위탁)'!H35 -> 450000 | H20: 0 | I20: =G20-H20 -> 450000
F21: 행사운영비 | G21: ='기획본부(위탁)'!H43 -> 48000 | H21: 0 | I21: =G21-H21 -> 48000
E22: 일반보상금 | G22: ='기획본부(위탁)'!H46 -> 162000 | H22: 0 | I22: =G22-H22 -> 162000
F23: 외빈초청여비 | G23: ='기획본부(위탁)'!H47 -> 132000 | H23: 0 | I23: =G23-H23 -> 132000
F24: 기타보상금 | G24: ='기획본부(위탁)'!H50 -> 30000 | H24: 0 | I24: =G24-H24 -> 30000
D25: 학술회의 유치 | G25: ='기획본부(위탁)'!H52 -> 290000 | H25: 0 | I25: =G25-H25 -> 290000
E26: 일반운영비 | G26: ='기획본부(위탁)'!H54 -> 120000 | H26: 0 | I26: =G26-H26 -> 120000
F27: 행사운영비 | G27: ='기획본부(위탁)'!H55 -> 120000 | H27: 0 | I27: =G27-H27 -> 120000
E28: 일반보상금 | G28: ='기획본부(위탁)'!H58 -> 170000 | H28: 0 | I28: =G28-H28 -> 170000
F29: 외빈초청여비 | G29: ='기획본부(위탁)'!H59 -> 170000 | H29: 0 | I29: =G29-H29 -> 170000
B30: 2026여수세계섬박람회 행사(위탁) | G30: =G31 -> 1000000 | H30: 0 | I30: =G30-H30 -> 1000000
C31: 2026여수세계섬박람회 행사 | G31: ='운영본부(위탁)'!H7 -> 1000000 | H31: 0 | I31: =G31-H31 -> 1000000
D32: 사전행사 개최 | G32: ='운영본부(위탁)'!H8 -> 400000 | H32: 0 | I32: =G32-H32 -> 400000
E33: 일반운영비 | G33: ='운영본부(위탁)'!H10 -> 400000 | H33: 0 | I33: =G33-H33 -> 400000
F34: 행사운영비 | G34: ='운영본부(위탁)'!H11 -> 400000 | H34: 0 | I34: =G34-H34 -> 400000
D35: 문화행사 추진 | G35: ='운영본부(위탁)'!H14 -> 600000 | H35: 0 | I35: =G35-H35 -> 600000
E36: 일반운영비 | G36: ='운영본부(위탁)'!H16 -> 600000 | H36: 0 | I36: =G36-H36 -> 600000
F37: 행사운영비 | G37: ='운영본부(위탁)'!H17 -> 600000 | H37: 0 | I37: =G37-H37 -> 600000
B38: 2026여수세계섬박람회 전시연출(위탁) | G38: =G39 -> 1500000 | H38: 0 | I38: =G38-H38 -> 1500000
C39: 2026여수세계섬박람회 전시연출 | G39: ='운영본부(위탁)'!H20 -> 1500000 | H39: 0 | I39: =G39-H39 -> 1500000
D40: 박람회 연출 | G40: ='운영본부(위탁)'!H21 -> 1500000 | H40: 0 | I40: =G40-H40 -> 1500000
...

Sheet 기획본부(위탁)
A1: 지출예산 - 기획본부(위탁) | M1: 단위 : 천 원
A2: 구 분 | B2: 사업 | E2: 편성목 | H2: 예산액 | I2: 기정액 | J2: 비교증감 | K2: 산 출 기 초
B3: 정책 | C3: 단위 | D3: 세부 | E3: 그룹 | F3: 목 | G3: 세목
A4: 총계(사업예산 + 자본예산) | H4: =H5 -> 2950000 | I4: 0 | J4: =H4-I4 -> 2950000
A5: 사업예산 | H5: =H6+H30 -> 2950000 | I5: 0 | J5: =H5-I5 -> 2950000
B6: 2026여수세계섬박람회 기획홍보(위탁) | H6: =H7 -> 2000000 | I6: 0 | J6: =H6-I6 -> 2000000
C7: 2026여수세계섬박람회 홍보 | H7: =H8 -> 2000000 | I7: 0 | J7: =H7-I7 -> 2000000
D8: 박람회 홍보 | H8: =H9+H25 -> 2000000 | I8: 0 | J8: =H8-I8 -> 2000000
E9: 200 물건비 | H9: =H10 -> 1974000 | I9: 0 | J9: =H9-I9 -> 1974000
F10: 201 일반운영비 | H10: =SUM(H11,H19,H23) -> 1974000 | I10: 0 | J10: =H10-I10 -> 1974000
G11: 01 사무관리비 | H11: =M11 -> 1419000 | I11: 0 | J11: =H11-I11 -> 1419000 | K11: [사무관리비] | M11: =SUM(M12:M18) -> 1419000
K12: ○ 홍보물품 등 제작 : 140,000,000원*1식 | L12: = | M12: 140000
K13: ○ 홍보부스 참가 : 5,000,000원*4회 | L13: = | M13: 20000
K14: ○ 제안서, 공모전 평가위원 수당 : 7,000,000원*1식 | L14: = | M14: 7000
K15: ○ 제안서, 공모전 평가위원 교통비 등 기타 실비 : 2,000,000원*1식 | L15: = | M15: 2000
K16: ○ 종합홍보 대행 용역(1차분) : 1,000,000,000원*1식 | L16: = | M16: 1000000
K17: ○ 온라인 홍보 대행 용역 : 150,000,000원*1식 | L17: = | M17: 150000
K18: ○ 홍보영상 제작 용역 : 100,000,000원*1식 | L18: = | M18: 100000
G19: 03 행사운영비 | H19: =M19 -> 55000 | I19: 0 | J19: =H19-I19 -> 55000 | K19: [행사운영비] | M19: =SUM(M20:M22) -> 55000
K20: ○ 사전 홍보 이벤트 : 30,000,000원*1식 | L20: = | M20: 30000
K21: ○ 홍보부스 운영 : 5,000,000원*1식 | L21: = | M21: 5000
K22: ○ 홍보대사, 서포터즈 운영 : 20,000,000원*1식 | L22: = | M22: 20000
G23: 16 광고선전비 | H23: =M23 -> 500000 | I23: 0 | J23: =H23-I23 -> 500000 | K23: [광고료] | M23: =SUM(M24) -> 500000
K24: ○ 섬박람회 광고 홍보료 : 500,000,000원*1식 | L24: = | M24: 500000
E25: 300 경상이전 | H25: =H26 -> 26000 | I25: 0 | J25: =H25-I25 -> 26000
F26: 301 일반보상금 | H26: =H27 -> 26000 | I26: 0 | J26: =H26-I26 -> 26000
G27: 14 기타보상금 | H27: =M27 -> 26000 | I27: 0 | J27: =H27-I27 -> 26000 | K27: [기타보상금] | M27: =SUM(M28:M29) -> 26000
K28: ○ 공모전 시상금 : 7,000,000원*3회 | L28: = | M28: 21000
K29: ○ 각종 이벤트 경품 : 5,000,000원*1식 | L29: = | M29: 5000
B30: 2026여수세계섬박람회 유치협력(위탁) | H30: =H31 -> 950000 | I30: 0 | J30: =H30-I30 -> 950000
C31: 2026여수세계섬박람회 유치 | H31: =H32+H52 -> 950000 | I31: 0 | J31: =H31-I31 -> 950000
D32: 관람객 유치 | H32: =H33+H45 -> 660000 | I32: 0 | J32: =H32-I32 -> 660000
E33: 200 물건비 | H33: =H34 -> 498000 | I33: 0 | J33: =H33-I33 -> 498000
F34: 201 일반운영비 | H34: =SUM(H35,H43) -> 498000 | I34: 0 | J34: =H34-I34 -> 498000
G35: 01 사무관리비 | H35: =M35 -> 450000 | I35: 0 | J35: =H35-I35 -> 450000 | K35: [사무관리비] | M35: =SUM(M36:M42) -> 450000
K36: ○ 유치활동 추진을 위한 소책자, 협약서 등 제작(다국어) : 40,000,000원*1식 | L36: = | M36: 40000
K37: ○ 유치활동 PPT, 영상 제작(다국어) : 16,000,000원*1식 | L37: = | M37: 16000
K38: ○ 유치활동 추진을 위한 통번역 수수료 : 600,000원*40회 | L38: = | M38: 24000
K39: ○ 유치활동 추진을 위한 유치홍보물 제작 : 20,000원*5,000개 | L39: = | M39: 100000
K40: ○ 전국 단위 축제·행사 홍보부스 참가비 : 5,000,000원*6회 | L40: = | M40: 30000
...

Sheet 운영본부(위탁)
A1: 지출예산 - 운영본부(위탁) | M1: 단위 : 천 원
A2: 구 분 | B2: 사업 | E2: 편성목 | H2: 예산액 | I2: 기정액 | J2: 비교증감 | K2: 산 출 기 초
B3: 정책 | C3: 단위 | D3: 세부 | E3: 그룹 | F3: 목 | G3: 세목
A4: 총계(사업예산 + 자본예산) | H4: =H5+H26 -> 19600000 | I4: 0 | J4: =H4-I4 -> 19600000
A5: 사업예산 | H5: =H6+H19 -> 2500000 | I5: 0 | J5: =H5-I5 -> 2500000
B6: 2026여수세계섬박람회 행사(위탁) | H6: =H7 -> 1000000 | I6: 0 | J6: =H6-I6 -> 1000000
C7: 2026여수세계섬박람회 행사 | H7: =H8+H14 -> 1000000 | I7: 0 | J7: =H7-I7 -> 1000000
D8: 사전행사 개최 | H8: =H9 -> 400000 | I8: 0 | J8: =H8-I8 -> 400000
E9: 200 물건비 | H9: =H10 -> 400000 | I9: 0 | J9: =H9-I9 -> 400000
F10: 201 일반운영비 | H10: =H11 -> 400000 | I10: 0 | J10: =H10-I10 -> 400000
G11: 03 행사운영비 | H11: =M11 -> 400000 | I11: 0 | J11: =H11-I11 -> 400000 | K11: [행사운영비] | M11: =SUM(M12:M13) -> 400000
K12: ○ D-365 기념행사 : 280,000,000원*1식 | L12: = | M12: 280000
K13: ○ '너와 나의 섬이야기' 성공개최 이벤트 : 120,000,000원*1식 | L13: = | M13: 120000
D14: 문화행사 추진 | H14: =H15 -> 600000 | I14: 0 | J14: =H14-I14 -> 600000
E15: 200 물건비 | H15: =H16 -> 600000 | I15: 0 | J15: =H15-I15 -> 600000
F16: 201 일반운영비 | H16: =H17 -> 600000 | I16: 0 | J16: =H16-I16 -> 600000
G17: 03 행사운영비 | H17: =M17 -> 600000 | I17: 0 | J17: =H17-I17 -> 600000 | K17: [행사운영비] | M17: =M18 -> 600000
K18: ○ 섬박람회 문화행사 기획 및 프로그램 개발 : 600,000,000원*1식 | L18: = | M18: 600000
B19: 2026여수세계섬박람회 전시연출(위탁) | H19: =H20 -> 1500000 | I19: 0 | J19: =H19-I19 -> 1500000
C20: 2026여수세계섬박람회 전시연출 | H20: =H21 -> 1500000 | I20: 0 | J20: =H20-I20 -> 1500000
D21: 박람회 연출 | H21: =H22 -> 1500000 | I21: 0 | J21: =H21-I21 -> 1500000
E22: 200 물건비 | H22: =H23 -> 1500000 | I22: 0 | J22: =H22-I22 -> 1500000
F23: 201 일반운영비 | H23: =H24 -> 1500000 | I23: 0 | J23: =H23-I23 -> 1500000
G24: 03 행사운영비 | H24: =M24 -> 1500000 | I24: 0 | J24: =H24-I24 -> 1500000 | K24: [행사운영비] | M24: =SUM(M25:M25) -> 1500000
K25: ○ 전시연출 콘텐츠 개발 : 1,500,000,000원*1식 | L25: = | M25: 1500000
A26: 자본예산 | H26: =H27+H57 -> 17100000 | I26: 0 | J26: =H26-I26 -> 17100000
B27: 2026여수세계섬박람회 시설조성(위탁) | H27: =H28 -> 10300000 | I27: 0 | J27: =H27-I27 -> 10300000
C28: 2026여수세계섬박람회 시설조성 | H28: =SUM(H29,H36,H43,H50) -> 10300000 | I28: 0 | J28: =H28-I28 -> 10300000
D29: 섬박람회 랜드마크 조성사업 | H29: =H30 -> 5000000 | I29: 0 | J29: =H29-I29 -> 5000000
E30: 400 자본지출 | H30: =H31 -> 5000000 | I30: 0 | J30: =H30-I30 -> 5000000
F31: 401 시설비및부대비 | H31: =SUM(H32,H34) -> 5000000 | I31: 0 | J31: =H31-I31 -> 5000000
G32: 01 시설비 | H32: =M32 -> 4986500 | I32: 0 | J32: =H32-I32 -> 4986500 | K32: [시설비] | M32: =SUM(M33:M33) -> 4986500
K33: ○ 섬박람회 랜드마크 조성 시설비 : 5,000,000,000원*1식*99.73/100 | L33: = | M33: 4986500
G34: 03 시설부대비 | H34: =M34 -> 13500 | I34: 0 | J34: =H34-I34 -> 13500 | K34: [시설부대비] | M34: =SUM(M35) -> 13500
K35: ○ 섬박람회 랜드마크 조성 시설부대비 : 5,000,000,000원*1식*0.27/100 | L35: = | M35: 13500
D36: 섬박람회장 안전시설물 설치사업 | H36: =H37 -> 3000000 | I36: 0 | J36: =H36-I36 -> 3000000
E37: 400 자본지출 | H37: =H38 -> 3000000 | I37: 0 | J37: =H37-I37 -> 3000000
F38: 401 시설비및부대비 | H38: =SUM(H39,H41) -> 3000000 | I38: 0 | J38: =H38-I38 -> 3000000
G39: 01 시설비 | H39: =M39 -> 2989200 | I39: 0 | J39: =H39-I39 -> 2989200 | K39: [시설비] | M39: =M40 -> 2989200
K40: ○ 섬박람회장 안전시설물 설치 시설비 : 3,000,000,000원*1식*99.64/100 | L40: = | M40: 2989200
...
