Workbook
Name ㄹㄹㄹ: #REF!
Name ㄹㄹㄹ: #REF!
Name ㄹㄹㄹ: #REF!
Name ㅁ1: #REF!
Name ㅁ1: #REF!
Name ㅁ1: #REF!
Name ㅁ1: #REF!
Name ㅇㅇ: #REF!
Name ㅇㅇ: #REF!
Name ㅇㅇㅇ: #REF!
Name ㅇㅇㅇ: #REF!

Sheet 표지
M3: 2025. 3.
A13: 섬박람회 조직위원회 2025년도 제1회 추경예산서
D22: (재)2026여수세계섬박람회 조직위

Sheet 수입예산 총괄표
A1: 수입예산 총괄표(출연금+위탁사업비)
H2: (단위 : 천 원)
A3: 과 목 | F3: 예산액 (제1회추경) | G3: 기정액 (본예산) | H3: 비교증감
A4: 구분 | B4: 관 | C4: 항 | D4: 세항 | E4: 목
A5: 총계(사업예산+자본예산) | F5: =F6 -> 24729000 | G5: 24529000 | H5: =F5-G5 -> 200000
A6: 자체수입금 | F6: =SUM(F7,F20) -> 24729000 | G6: 24529000 | H6: =F6-G6 -> 200000
B7: 600 사업수익 | F7: =SUM(F8,F17) -> 24729000 | G7: 24529000 | H7: =F7-G7 -> 200000
C8: 610 영업수익 | F8: =SUM(F9,F11,F13,F15) -> 24711000 | G8: 24511000 | H8: =F8-G8 -> 200000
D9: 623 대행사업수익 | F9: =F10 -> 22550000 | G9: 22550000 | H9: =F9-G9 -> 0
E10: 01 직접관리비수익 | F10: 22550000 | G10: 22550000 | H10: =F10-G10 -> 0
D11: 647 기부금수익 | F11: =F12 -> 200000 | G11: 0 | H11: =F11-G11 -> 200000
E12: 01 기부금수익 | F12: 200000 | G12: 0 | H12: =F12-G12 -> 200000
D13: 648 출연금 수익 | F13: =F14 -> 1861000 | G13: 1861000 | H13: =F13-G13 -> 0
E14: 02 자치단체출연금수익 | F14: 1861000 | G14: 1861000 | H14: =F14-G14 -> 0
D15: 649 후원금 수익 | F15: =F16 -> 100000 | G15: 100000 | H15: =F15-G15 -> 0
E16: 01 지정후원금수익 | F16: 100000 | G16: 100000 | H16: =F16-G16 -> 0
C17: 670 영업외수익 | F17: =F18 -> 18000 | G17: 18000 | H17: =F17-G17 -> 0
D18: 671 이자수익 | F18: =F19 -> 18000 | G18: 18000 | H18: =F18-G18 -> 0
E19: 01 예금이자수익 | F19: 18000 | G19: 18000 | H19: =F19-G19 -> 0
B20: 100 자본적수입 | F20: =F21 -> 0 | G20: 0 | H20: =F20-G20 -> 0
C21: 170 자본잉여금수입 | F21: =F22 -> 0 | G21: 0 | H21: =F21-G21 -> 0
D22: 177 출연금 수입 | F22: =F23 -> 0 | G22: 0 | H22: =F22-G22 -> 0
E23: 01 정부출연금 | F23: 0 | G23: 0 | H23: =F23-G23 -> 0

Sheet 지출예산 총괄표
A1: 지출예산 총괄표(출연금+위탁사업비)
G2: 1979000 | I2: (단위 : 천 원)
A3: 과 목 | G3: 예산액 (제1회추경) | H3: 기정액 (본예산) | I3: 비교증감
A4: 구분 | B4: 정책사업
A5: 총계(출연금+위탁사업비) | G5: =G6+G19 -> 24729000 | H5: 24529000 | I5: =G5-H5 -> 200000
A6: 출연금(사업예산+자본예산) | G6: =SUM(G7,G17) -> 2179000 | H6: 1979000 | I6: =G6-H6 -> 200000
A7: 사업예산 | G7: =SUM(G8:G16) -> 2179000 | H7: 1979000 | I7: =G7-H7 -> 200000
B8: 2026여수세계섬박람회 행정관리 | G8: =행정관리부!H5 -> 937348 | H8: 927348 | I8: =G8-H8 -> 10000
B9: 2026여수세계섬박람회 기획홍보 | G9: =기획홍보부!H5 -> 261892 | H9: 151892 | I9: =G9-H9 -> 110000
B10: 2026여수세계섬박람회 수익사업 | G10: =수익사업부!H5 -> 91166 | H10: 86166 | I10: =G10-H10 -> 5000
B11: 2026여수세계섬박람회 유치협력 | G11: =유치협력부!H5 -> 62518 | H11: 62518 | I11: =G11-H11 -> 0
B12: 2026여수세계섬박람회 운영 | G12: =운영부!H5 -> 360632 | H12: 358632 | I12: =G12-H12 -> 2000
B13: 2026여수세계섬박람회 행사 | G13: =행사부!H5 -> 25268 | H13: 25268 | I13: =G13-H13 -> 0
B14: 2026여수세계섬박람회 시설조성 | G14: =시설조성부!H5 -> 25268 | H14: 25268 | I14: =G14-H14 -> 0
B15: 2026여수세계섬박람회 전시연출 | G15: =전시연출부!H5 -> 34668 | H15: 25268 | I15: =G15-H15 -> 9400
B16: 예비비 | G16: =예비비!H6 -> 380240 | H16: 316640 | I16: =G16-H16 -> 63600
A17: 자본예산 | G17: =G18 -> 0 | H17: 0 | I17: =G17-H17 -> 0
B18: 예비비(자본) | G18: =예비비!H15 -> 0 | H18: 0 | I18: =G18-H18 -> 0
A19: 위탁사업비(사업예산+자본예산) | G19: =G20+G25 -> 22550000 | H19: 22550000 | I19: =G19-H19 -> 0
A20: 사업예산 | G20: =SUM(G21:G24) -> 5450000 | H20: 5450000 | I20: =G20-H20 -> 0
B21: 2026여수세계섬박람회 기획홍보(위탁) | G21: ='기획본부(위탁)'!H6 -> 2000000 | H21: 2000000 | I21: =G21-H21 -> 0
B22: 2026여수세계섬박람회 유치협력(위탁) | G22: ='기획본부(위탁)'!H30 -> 950000 | H22: 950000 | I22: =G22-H22 -> 0
B23: 2026여수세계섬박람회 행사(위탁) | G23: ='운영본부(위탁)'!H6 -> 1000000 | H23: 1000000 | I23: =G23-H23 -> 0
B24: 2026여수세계섬박람회 전시연출(위탁) | G24: ='운영본부(위탁)'!H19 -> 1500000 | H24: 1500000 | I24: =G24-H24 -> 0
A25: 자본예산 | G25: =SUM(G26:G27) -> 17100000 | H25: 17100000 | I25: =G25-H25 -> 0
B26: 2026여수세계섬박람회 시설조성(위탁) | G26: ='운영본부(위탁)'!H27 -> 10300000 | H26: 10300000 | I26: =G26-H26 -> 0
B27: 2026여수세계섬박람회 전시연출(위탁) | G27: ='운영본부(위탁)'!H57 -> 6800000 | H27: 6800000 | I27: =G27-H27 -> 0

Sheet 행정관리부
A1: 지출예산(세부사업) - 행정관리부 | M1: 단위 : 천원
A2: 구 분 | B2: 사업 | E2: 편성목 | H2: 예산액 (A) | I2: 기정액(본예산) (B) | J2: 비교증감 (A-B) | K2: 산 출 기 초
B3: 정책 | C3: 단위 | D3: 세부 | E3: 그룹 | F3: 목 | G3: 세목
A4: 총계(사업예산 + 자본예산) | H4: =H5 -> 937348 | I4: 927348 | J4: =H4-I4 -> 10000
A5: 사업예산 | H5: =H6 -> 937348 | I5: 927348 | J5: =H5-I5 -> 10000
B6: 2026여수세계섬박람회 행정관리 | H6: =SUM(H7,H30) -> 937348 | I6: 927348 | J6: =H6-I6 -> 10000
C7: 2026여수세계섬박람회 행정 업무추진 | H7: =SUM(H8,H14) -> 80420 | I7: 80420 | J7: =H7-I7 -> 0
D8: 직원역랑강화 워크숍 | H8: =H9 -> 32960 | I8: 32960 | J8: =H8-I8 -> 0
E9: 200 물건비 | H9: =H10 -> 32960 | I9: 32960 | J9: =H9-I9 -> 0
F10: 213 교육훈련비 | H10: =H11 -> 32960 | I10: 32960 | J10: =H10-I10 -> 0
G11: 교육훈련경비 | H11: =M11 -> 32960 | I11: 32960 | J11: =H11-I11 -> 0 | K11: [교육훈련경비] | M11: =SUM(M12:M13) -> 32960
K12: ○ 직원역량강화 교육 강사수당 : 370,000원*2명*4회 | L12: = | M12: 2960
K13: ○ 현장체험 등 워크숍 운영 경비 : 15,000,000원*2회 | L13: = | M13: 30000
D14: 이사회 및 각종 위원회 운영 | H14: =H15 -> 47460 | I14: 47460 | J14: =H14-I14 -> 0
E15: 200 물건비 | H15: =H16 -> 47460 | I15: 47460 | J15: =H15-I15 -> 0
F16: 201 일반운영비 | H16: =SUM(H17,H28) -> 47460 | I16: 47460 | J16: =H16-I16 -> 0
G17: 01 사무관리비 | H17: =SUM(M17,M20,M26) -> 45060 | I17: 45060 | J17: =H17-I17 -> 0 | K17: [일반수용비] | M17: =SUM(M18:M19) -> 2560
K18: ○ 이사회 책자 제작 및 소모품 구입 : 20,000원*13명*6회 | L18: = | M18: 1560
K19: ○ 이사회 변경등기 및 법무사 수수료 : 1,000,000원*1식 | L19: = | M19: 1000
K20: [운영수당] | M20: =SUM(M21:M25) -> 30500
K21: ○ 이사회 참석수당 : 150,000원*13명*6회 | L21: = | M21: 11700
K22: ○ 이사회 참석자 실비보상 : 110,000원*13명*6회 | L22: = | M22: 8580
K23: ○ 인사위원회 참석수당 : 100,000원*3명*5회 | L23: = | M23: 1500
K24: ○ 명예위원장, 부위원장, 특별위원회 위원 등 행사 참석 실비 : 110,000원*13명*4회 | L24: = | M24: 5720
K25: ○ 계약심의위원회 수당 등 지급 : 100,000원*6명*5회 | L25: = | M25: 3000
K26: [임차료] | M26: =M27 -> 12000
K27: ○ 이사회 개최를 위한 회의실 임차료 : 300,000원*4회 | L27: = | M27: 12000
G28: 14 회의비 | H28: =M28 -> 2400 | I28: 2400 | J28: =H28-I28 -> 0 | K28: [회의비] | M28: =M29 -> 2400
K29: ○ 이사회 등 회의 운영비 : 400,000원*6회 | L29: = | M29: 2400
C30: 사무국운영 | H30: =H31 -> 856928 | I30: 846928 | J30: =H30-I30 -> 10000
D31: 기본경비 | H31: =SUM(H32,H51,H109) -> 856928 | I31: 846928 | J31: =H31-I31 -> 10000
E32: 100 인건비 | H32: =SUM(H33,H48) -> 619831 | I32: 619831 | J32: =H32-I32 -> 0
F33: 101 인건비 | H33: =SUM(H34,H39,H44) -> 609331 | I33: 609331 | J33: =H33-I33 -> 0
G34: 01 보수 | H34: =SUM(M34,M37) -> 392400 | I34: 392400 | J34: =H34-I34 -> 0 | K34: [직원파견수당] | M34: =SUM(M35:M36) -> 302400
K35: ○ 4급이상 : 600,000원*2명*12월 | L35: = | M35: 14400
K36: ○ 5급이하 : 400,000원*60명*12월 | L36: = | M36: 288000
K37: [주거지원비] | M37: =M38 -> 90000
K38: ○ 타시군(도) 주거지원비 : 500,000원*15명*12월 | L38: = | M38: 90000
G39: 02 기타직 보수 | H39: =SUM(M39,M42) -> 186102 | I39: 186102 | J39: =H39-I39 -> 0 | K39: [사무총장] | M39: =SUM(M40:M41) -> 102102
K40: ○ 연봉 : 8,468,460원*12월 | L40: = | M40: 101622
...

Sheet 기획홍보부
A1: 지출예산(세부사업) - 기획홍보부 | M1: 단위 : 천원
A2: 구 분 | B2: 사업 | E2: 편성목 | H2: 예산액 (A) | I2: 기정액(본예산) (B) | J2: 비교증감 (A-B) | K2: 산 출 기 초
B3: 정책 | C3: 단위 | D3: 세부 | E3: 그룹 | F3: 목 | G3: 세목
A4: 총계(사업예산 + 자본예산) | H4: =H5 -> 261892 | I4: 151892 | J4: =H4-I4 -> 110000
A5: 사업예산 | H5: =H6 -> 261892 | I5: 151892 | J5: =H5-I5 -> 110000
B6: 2026여수세계섬박람회 기획홍보 | H6: =SUM(H7,H25,H31,H49) -> 261892 | I6: 151892 | J6: =H6-I6 -> 110000
C7: 2026여수세계섬박람회 기획 | H7: =H8+H14 -> 38600 | I7: 28600 | J7: =H7-I7 -> 10000
D8: 박람회 기획 | H8: =SUM(H9) -> 10000 | I8: 0 | J8: =H8-I8 -> 10000
E9: 300 경상이전 | H9: =SUM(H10) -> 10000 | I9: 0 | J9: =H9-I9 -> 10000
F10: 303 포상금 | H10: =H11 -> 10000 | I10: 0 | J10: =H10-I10 -> 10000
G11: 01 포상금 | H11: =M11 -> 10000 | I11: 0 | J11: =H11-I11 -> 10000 | K11: [포상금] | M11: =M13 -> 10000
K12: 추경1회
K13: ○ 2024년 직원 아이디어 경진대회 포상금 : 10,000,000원*1식 | L13: = | M13: 10000
D14: 자문위원회 운영 | H14: =H15 -> 28600 | I14: 28600 | J14: =H14-I14 -> 0
E15: 200 물건비 | H15: =SUM(H16) -> 28600 | I15: 28600 | J15: =H15-I15 -> 0
F16: 201 일반운영비 | H16: =SUM(H17,H21,H23) -> 28600 | I16: 28600 | J16: =H16-I16 -> 0
G17: 01 사무관리비 | H17: =M17 -> 28000 | I17: 28000 | J17: =H17-I17 -> 0 | K17: [운영수당] | M17: =SUM(M18:M20) -> 28000
K18: ○ 자문위원회 자문수당(대면) : 150,000원*3회*32명 | L18: = | M18: 14400
K19: ○ 자문위원회 자문수당(서면) : 100,000원*3회*32명 | L19: = | M19: 9600
K20: ○ 자문위원회 참석자 실비 보상 : 4,000,000원*1식 | L20: = | M20: 4000
G21: 03 행사운영비 | H21: =M21 -> 300 | I21: 300 | J21: =H21-I21 -> 0 | K21: [행사운영비] | M21: =M22 -> 300
K22: ○ 자문위원회 운영 행사운영비 : 100,000원*3회 | L22: = | M22: 300
G23: 14 회의비 | H23: =M23 -> 300 | I23: 300 | J23: =H23-I23 -> 0 | K23: [회의비] | M23: =M24 -> 300
K24: ○ 자문위원회 회의 운영비 : 50,000원*6회 | L24: = | M24: 300
C25: 2026여수세계섬박람회 홍보 | H25: =H26 -> 50000 | I25: 50000 | J25: =H25-I25 -> 0
D26: 홈페이지 유지관리 | H26: =H27 -> 50000 | I26: 50000 | J26: =H26-I26 -> 0
E27: 200 물건비 | H27: =H28 -> 50000 | I27: 50000 | J27: =H27-I27 -> 0
F28: 214 수선유지교체비 | H28: =H29 -> 50000 | I28: 50000 | J28: =H28-I28 -> 0
G29: 05 수선유지비 | H29: =M29 -> 50000 | I29: 50000 | J29: =H29-I29 -> 0 | K29: [수선유지비] | M29: =SUM(M30:M30) -> 50000
K30: ○ 누리집 유지관리 용역 : 50,000,000원*1식 | L30: = | M30: 50000
C31: 기획홍보부 부서운영 | H31: =H32 -> 28292 | I31: 28292 | J31: =H31-I31 -> 0
D32: 기본경비 | H32: =H33 -> 28292 | I32: 28292 | J32: =H32-I32 -> 0
E33: 200 물건비 | H33: =SUM(H34,H39,H43,H46) -> 28292 | I33: 28292 | J33: =H33-I33 -> 0
F34: 201 일반운영비 | H34: =H35+H37 -> 9792 | I34: 9792 | J34: =H34-I34 -> 0
G35: 01 사무관리비 | H35: =M35 -> 2880 | I35: 2880 | J35: =H35-I35 -> 0 | K35: [일반수용비] | M35: =SUM(M36:M36) -> 2880
K36: ○ 부서 운영을 위한 소모품 구입 : 240,000원*12월 | L36: = | M36: 2880
G37: 15 복리후생비 | H37: =M37 -> 6912 | I37: 6912 | J37: =H37-I37 -> 0 | K37: [급량비] | M37: =SUM(M38:M38) -> 6912
K38: ○ 기본업무수행 급량비 : 9,000원*8명*8일*12월 | L38: = | M38: 6912
F39: 202 여비 | H39: =H40 -> 14400 | I39: 14400 | J39: =H39-I39 -> 0
G40: 01 국내여비 | H40: =M40 -> 14400 | I40: 14400 | J40: =H40-I40 -> 0 | K40: [국내여비] | M40: =SUM(M41:M42) -> 14400
...

Sheet 수익사업부
A1: 지출예산(세부사업) - 수익사업부 | M1: 단위 : 천원
A2: 구 분 | B2: 사업 | E2: 편성목 | H2: 예산액 (A) | I2: 기정액(본예산) (B) | J2: 비교증감 (A-B) | K2: 산 출 기 초
B3: 정책 | C3: 단위 | D3: 세부 | E3: 그룹 | F3: 목 | G3: 세목
A4: 총계(사업예산 + 자본예산) | H4: =H5 -> 91166 | I4: 86166 | J4: =H4-I4 -> 5000
A5: 사업예산 | H5: =H6 -> 91166 | I5: 86166 | J5: =H5-I5 -> 5000
B6: 2026여수세계섬박람회 수익사업 | H6: =SUM(H7,H40) -> 91166 | I6: 86166 | J6: =H6-I6 -> 5000
C7: 2026여수세계섬박람회 수익사업 | H7: =SUM(H8,H18,H24,H34) -> 58850 | I7: 53850 | J7: =H7-I7 -> 5000
D8: 박람회 휘장업무 추진 | H8: =H9 -> 14450 | I8: 14450 | J8: =H8-I8 -> 0
E9: 200 물건비 | H9: =H10 -> 14450 | I9: 14450 | J9: =H9-I9 -> 0
F10: 201 일반운영비 | H10: =H11+H16 -> 14450 | I10: 14450 | J10: =H10-I10 -> 0
G11: 01 사무관리비 | H11: =M11 -> 10450 | I11: 10450 | J11: =H11-I11 -> 0 | K11: [일반수용비] | M11: =SUM(M12:M15) -> 10450
K12: ○ 후원·기부 유치를 위한 홍보물 제작 : 5,000,000원*1식 | L12: = | M12: 5000
K13: ○ 공식상품화권자 선정 심사수당 : 250,000원*7명*1회 | L13: = | M13: 1750
K14: ○ 공식상품화권자 선정 심사위원 교통비 등 기타실비 : 700,000원*1식 | L14: = | M14: 700
K15: ○ 박람회 인정상품 엠블럼 제작 : 3,000,000원*1식 | L15: = | M15: 3000 | N15: ○ 직원 병가 및 휴직 등 공백발생 시 채용(인건비 23년 기준)
G16: 03 행사운영비 | H16: =M16 -> 4000 | I16: 4000 | J16: =H16-I16 -> 0 | K16: [행사운영비] | M16: =SUM(M17:M17) -> 4000
K17: ○ 후원 협약식 개최 : 800,000원*5회 | L17: = | M17: 4000
D18: 박람회 기부금품 관리 | H18: =SUM(H19) -> 7000 | I18: 7000 | J18: =H18-I18 -> 0
E19: 200 물건비 | H19: =H20 -> 7000 | I19: 7000 | J19: =H19-I19 -> 0
F20: 201 일반운영비 | H20: =H21 -> 7000 | I20: 7000 | J20: =H20-I20 -> 0
G21: 01 사무관리비 | H21: =M21 -> 7000 | I21: 7000 | J21: =H21-I21 -> 0 | K21: [일반수용비] | M21: =SUM(M22:M23) -> 7000
K22: ○ 기부금품 전달식 개최 : 300,000원*10회 | L22: = | M22: 3000
K23: ○ 기부자 예우 물품 제작 : 20,000원*200개 | L23: = | M23: 4000
D24: 박람회 입장권 사업 | H24: =SUM(H25,H30) -> 32400 | I24: 32400 | J24: =H24-I24 -> 0
E25: 200 물건비 | H25: =H26 -> 22400 | I25: 22400 | J25: =H25-I25 -> 0
F26: 201 일반운영비 | H26: =H27 -> 22400 | I26: 22400 | J26: =H26-I26 -> 0
G27: 01 사무관리비 | H27: =M27 -> 22400 | I27: 22400 | J27: =H27-I27 -> 0 | K27: [일반수용비] | M27: =SUM(M28:M29) -> 22400
K28: ○ 입장권 판촉 홍보물 제작 : 20,000,000원*1식 | L28: = | M28: 20000
K29: ○ 입장권 사업 추진 사무용품 구입 : 200,000원*12월 | L29: = | M29: 2400
E30: 300 경상이전 | H30: =H31 -> 10000 | I30: 10000 | J30: =H30-I30 -> 0
F31: 301 일반보상금 | H31: =H32 -> 10000 | I31: 10000 | J31: =H31-I31 -> 0
G32: 14 기타보상금 | H32: =M32 -> 10000 | I32: 10000 | J32: =H32-I32 -> 0 | K32: [기타보상금] | M32: =M33 -> 10000
K33: ○ 입장권 구매보상금 지급 : 10,000,000원*1식 | L33: = | M33: 10000
D34: 박람회 임대사업 | H34: =SUM(H35) -> 5000 | I34: 0 | J34: =H34-I34 -> 5000
E35: 200 물건비 | H35: =H36 -> 5000 | I35: 0 | J35: =H35-I35 -> 5000
F36: 201 일반운영비 | H36: =H37 -> 5000 | I36: 0 | J36: =H36-I36 -> 5000
G37: 01 사무관리비 | H37: =M37 -> 5000 | I37: 0 | J37: =H37-I37 -> 5000 | K37: [일반수용비] | M37: =SUM(M38:M39) -> 5000
K38: 추경1회
K39: ○ 감정평가수수료 2,500,000원*2개소 | L39: = | M39: 5000
C40: 수익사업부 부서운영 | H40: =H41 -> 32316 | I40: 32316 | J40: =H40-I40 -> 0
...

Sheet 유치협력부
A1: 지출예산(세부사업) - 유치협력부 | M1: 단위 : 천원
A2: 구 분 | B2: 사업 | E2: 편성목 | H2: 예산액 (A) | I2: 기정액(본예산) (B) | J2: 비교증감 (A-B) | K2: 산 출 기 초
B3: 정책 | C3: 단위 | D3: 세부 | E3: 그룹 | F3: 목 | G3: 세목
A4: 총계(사업예산 + 자본예산) | H4: =H5 -> 62518 | I4: 62518 | J4: =H4-I4 -> 0
A5: 사업예산 | H5: =H6 -> 62518 | I5: 62518 | J5: =H5-I5 -> 0
B6: 2026여수세계섬박람회 유치협력 | H6: =H7 -> 62518 | I6: 62518 | J6: =H6-I6 -> 0
C7: 유치협력부 부서운영 | H7: =H8 -> 62518 | I7: 62518 | J7: =H7-I7 -> 0
D8: 기본경비 | H8: =H9 -> 62518 | I8: 62518 | J8: =H8-I8 -> 0
E9: 200 물건비 | H9: =SUM(H10,H19,H25,H29) -> 62518 | I9: 62518 | J9: =H9-I9 -> 0
F10: 201 일반운영비 | H10: =SUM(H11,H15,H17) -> 19818 | I10: 19818 | J10: =H10-I10 -> 0
G11: 01 사무관리비 | H11: =M11 -> 5770 | I11: 5770 | J11: =H11-I11 -> 0 | K11: [일반수용비] | M11: =SUM(M12:M14) -> 5770
K12: ○ 부서 운영을 위한 소모품 구입 : 210,000원*12월 | L12: = | M12: 2520
K13: ○ 국내외 유치마케팅 대행사 선정 심사수당 : 250,000원*9명*1회 | L13: = | M13: 2250
K14: ○ 국내외 유치마케팅 대행사 선정 심사위원 교통비 등 기타실비 : 1,000,000원*1식 | L14: = | M14: 1000
G15: 02 공공운영비 | H15: =M15 -> 8000 | I15: 8000 | J15: =H15-I15 -> 0 | K15: [우편료] | M15: =SUM(M16) -> 8000
K16: ○ 국내·외 관람객 홍보물 등 발송 우편료 : 2,500원*3,200개소 | L16: = | M16: 8000
G17: 15 복리후생비 | H17: =M17 -> 6048 | I17: 6048 | J17: =H17-I17 -> 0 | K17: [급량비] | M17: =SUM(M18) -> 6048
K18: ○ 기본업무수행 급량비 : 9,000원*7명*8일*12월 | L18: = | M18: 6048
F19: 202 여비 | H19: =H20+H23 -> 36600 | I19: 36600 | J19: =H19-I19 -> 0
G20: 01 국내여비 | H20: =M20 -> 12600 | I20: 12600 | J20: =H20-I20 -> 0 | K20: [국내여비] | M20: =SUM(M21:M22) -> 12600
K21: ○ 유치협력 기본업무 수행 관내여비 : 20,000원*7명*2일*12월 | L21: = | M21: 3360 | AC21: 9
K22: ○ 유치협력 기본업무 수행 관외여비 : 110,000원*7명*12월 | L22: = | M22: 9240
G23: 03 국외업무여비 | H23: =M23 -> 24000 | I23: 24000 | J23: =H23-I23 -> 0 | K23: [국외업무여비] | M23: =SUM(M24:M25) -> 24000
K24: ○ 자매도시 등 국제교류 및 각종 국제행사 참가 : 3,000,000원*2명*4회 | L24: = | M24: 24000 | AC24: 9
F25: 203 업무추진비 | H25: =H26 -> 4000 | I25: 4000 | J25: =H25-I25 -> 0
G26: 07 사업업무추진비 | H26: =M26 -> 4000 | I26: 4000 | J26: =H26-I26 -> 0 | K26: [사업업무추진비] | M26: =SUM(M27:M28) -> 4000
K27: ○ 유치협력부 업무추진 : 2,000,000원*1식 | L27: = | M27: 2000
K28: ○ 협력관 업무추진 : 2,000,000원*1식 | L28: = | M28: 2000
F29: 217 관서업무비 | H29: =H30 -> 2100 | I29: 2100 | J29: =H29-I29 -> 0
G30: 02 부서업무비 | H30: =M30 -> 2100 | I30: 2100 | J30: =H30-I30 -> 0 | K30: [부서업무비] | M30: =M31 -> 2100
K31: ○ 유치협력부 부서운영 총액계상 : 175,000원*12월 | L31: = | M31: 2100

Sheet 운영부
A1: 지출예산(세부사업) - 운영부 | M1: 단위 : 천원
A2: 구 분 | B2: 사업 | E2: 편성목 | H2: 예산액 (A) | I2: 기정액(본예산) (B) | J2: 비교증감 (A-B) | K2: 산 출 기 초
B3: 정책 | C3: 단위 | D3: 세부 | E3: 그룹 | F3: 목 | G3: 세목
A4: 총계(사업예산 + 자본예산) | H4: =H5 -> 360632 | I4: 358632 | J4: =H4-I4 -> 2000
A5: 사업예산 | H5: =H6 -> 360632 | I5: 358632 | J5: =H5-I5 -> 2000
B6: 2026여수세계섬박람회 운영 | H6: =SUM(H7,H21) -> 360632 | I6: 358632 | J6: =H6-I6 -> 2000
C7: 박람회장 운영 | H7: =SUM(H8) -> 308500 | I7: 306500 | J7: =H7-I7 -> 2000
D8: 대행사 선정 | H8: =SUM(H9) -> 308500 | I8: 306500 | J8: =H8-I8 -> 2000
E9: 200 물건비 | H9: =H10 -> 308500 | I9: 306500 | J9: =H9-I9 -> 2000
F10: 201 일반운영비 | H10: =SUM(M11,M14,M17,M19) -> 308500 | I10: 306500 | J10: =H10-I10 -> 2000
G11: 01 사무관리비 | H11: =M11+M14 -> 8000 | I11: 6000 | J11: =H11-I11 -> 2000 | K11: [일반수용비] | M11: =SUM(M12:M13) -> 2000
K12: 추경1회
K13: ○ 회의실 임차료 : 400,000원*5회 | L13: = | M13: 2000
K14: [운영수당] | M14: =SUM(M15:M16) -> 6000
K15: ○ 대행사 선정 제안서 평가위원 수당 : 250,000원*10명*2회 | L15: = | M15: 5000
K16: ○ 대행사 선정 평가위원 실비 : 500,000원*2회 | L16: = | M16: 1000
G17: 03 행사운영비 | H17: =M17 -> 300000 | I17: 300000 | J17: =H17-I17 -> 0 | K17: [행사운영비] | M17: 300000
K18: ○ 종합실행계획 수립 및 운영대행 용역비(1차분) : 300,000,000원*1식 | L18: = | M18: 300000
G19: 14 회의비 | H19: =M19 -> 500 | I19: 500 | J19: =H19-I19 -> 0 | K19: [회의비] | M19: =M20 -> 500
K20: ○ 대행사 선정 평가위원회 운영비 : 250,000원*2회 | L20: = | M20: 500
C21: 운영부 사무국운영 | H21: =H22 -> 52132 | I21: 52132 | J21: =H21-I21 -> 0
D22: 기본경비 | H22: =H23 -> 52132 | I22: 52132 | J22: =H22-I22 -> 0
E23: 200 물건비 | H23: =SUM(H24,H31,H35,H41) -> 52132 | I23: 52132 | J23: =H23-I23 -> 0
F24: 201 일반운영비 | H24: =SUM(H25,H29) -> 19912 | I24: 19912 | J24: =H24-I24 -> 0
G25: 01 사무관리비 | H25: =M25 -> 13000 | I25: 13000 | J25: =H25-I25 -> 0 | K25: [일반수용비] | M25: =SUM(M26:M28) -> 13000
K26: ○ 사무용품 등 소모품 구입 : 5,000,000원*1식 | L26: = | M26: 5000
K27: ○ 복사기 및 프린터토너 구입 : 3,000,000원*1식 | L27: = | M27: 3000
K28: ○ 사무실 환경정비용품 구입 : 5,000,000원*1식 | L28: = | M28: 5000
G29: 15 복리후생비 | H29: =M30 -> 6912 | I29: 6912 | J29: =H29-I29 -> 0 | K29: [급량비] | M29: =M30 -> 6912
K30: ○ 기본업무수행 급량비 : 9,000원*8명*8일*12월 | L30: = | M30: 6912
F31: 202 여비 | H31: =H32 -> 14400 | I31: 14400 | J31: =H31-I31 -> 0
G32: 01 국내여비 | H32: =M32 -> 14400 | I32: 14400 | J32: =H32-I32 -> 0 | K32: [국내여비] | M32: =SUM(M33:M34) -> 14400
K33: ○ 운영부 기본업무 수행 관내여비 : 20,000원*8명*2일*12월 | L33: = | M33: 3840
K34: ○ 운영부 기본업무 수행 관외여비 : 110,000원*8명*12월 | L34: = | M34: 10560
F35: 203 업무추진비 | H35: =H36 -> 13400 | I35: 13400 | J35: =H35-I35 -> 0
G36: 07 사업업무추진비 | H36: =SUM(M36,M38) -> 13400 | I36: 13400 | J36: =H36-I36 -> 0 | K36: [기관운영업무추진비] | M36: =SUM(M37:M37) -> 6600
K37: ○ 4급보조기관장(운영본부장) : 6,600,000원*1식 | L37: = | M37: 6600
K38: [시책추진업무추진비] | M38: =SUM(M39:M40) -> 6800
K39: ○ 박람회 운영 및 조성 업무추진(4급) : 4,800,000원*1식 | L39: = | M39: 4800
K40: ○ 운영부 업무추진 : 2,000,000원*1식 | L40: = | M40: 2000
...

Sheet 행사부
A1: 지출예산(세부사업) - 행사부 | M1: 단위 : 천원
A2: 구 분 | B2: 사업 | E2: 편성목 | H2: 예산액 (A) | I2: 기정액(본예산) (B) | J2: 비교증감 (A-B) | K2: 산 출 기 초
B3: 정책 | C3: 단위 | D3: 세부 | E3: 그룹 | F3: 목 | G3: 세목
A4: 총계(사업예산 + 자본예산) | H4: =H5 -> 25268 | I4: 25268 | J4: =H4-I4 -> 0
A5: 사업예산 | H5: =H6 -> 25268 | I5: 25268 | J5: =H5-I5 -> 0
B6: 2026여수세계섬박람회 행사 | H6: =H7 -> 25268 | I6: 25268 | J6: =H6-I6 -> 0
C7: 행사부 부서운영 | H7: =H8 -> 25268 | I7: 25268 | J7: =H7-I7 -> 0
D8: 기본경비 | H8: =H9 -> 25268 | I8: 25268 | J8: =H8-I8 -> 0
E9: 200 물건비 | H9: =SUM(H10,H15,H19,H22) -> 25268 | I9: 25268 | J9: =H9-I9 -> 0
F10: 201 일반운영비 | H10: =SUM(H11,H13) -> 8568 | I10: 8568 | J10: =H10-I10 -> 0
G11: 01 사무관리비 | H11: =M11 -> 2520 | I11: 2520 | J11: =H11-I11 -> 0 | K11: [일반수용비] | M11: =SUM(M12:M12) -> 2520
K12: ○ 부서운영을 위한 소모품 구입 : 210,000원*12월 | L12: = | M12: 2520
G13: 15 복리후생비 | H13: =M13 -> 6048 | I13: 6048 | J13: =H13-I13 -> 0 | K13: [급량비] | M13: =SUM(M14) -> 6048
K14: ○ 기본업무수행 급량비 : 9,000원*7명*8일*12월 | L14: = | M14: 6048
F15: 202 여비 | H15: =H16 -> 12600 | I15: 12600 | J15: =H15-I15 -> 0
G16: 01 국내여비 | H16: =M16 -> 12600 | I16: 12600 | J16: =H16-I16 -> 0 | K16: [국내여비] | M16: =SUM(M17:M18) -> 12600
K17: ○ 행사부 기본업무 수행 관내여비 : 20,000원*7명*2일*12월 | L17: = | M17: 3360
K18: ○ 행사부 기본업무 수행 관외여비 : 110,000원*7명*12월 | L18: = | M18: 9240
F19: 203 업무추진비 | H19: =H20 -> 2000 | I19: 2000 | J19: =H19-I19 -> 0
G20: 07 사업업무추진비 | H20: =M20 -> 2000 | I20: 2000 | J20: =H20-I20 -> 0 | K20: [사업업무추진비] | M20: =SUM(M21) -> 2000
K21: ○ 행사부 업무추진 : 2,000,000원*1식 | L21: = | M21: 2000
F22: 217 관서업무비 | H22: =H23 -> 2100 | I22: 2100 | J22: =H22-I22 -> 0
G23: 02 부서업무비 | H23: =M23 -> 2100 | I23: 2100 | J23: =H23-I23 -> 0 | K23: [부서업무비] | M23: =M24 -> 2100
K24: ○ 행사부 부서운영 총액계상 : 175,000원*12월 | L24: = | M24: 2100

Sheet 시설조성부
A1: 지출예산(세부사업) - 시설조성부 | M1: 단위 : 천원
A2: 구 분 | B2: 사업 | E2: 편성목 | H2: 예산액 (A) | I2: 기정액(본예산) (B) | J2: 비교증감 (A-B) | K2: 산 출 기 초
B3: 정책 | C3: 단위 | D3: 세부 | E3: 그룹 | F3: 목 | G3: 세목
A4: 총계(사업예산 + 자본예산) | H4: =H5 -> 25268 | I4: 25268 | J4: =H4-I4 -> 0
A5: 사업예산 | H5: =H6 -> 25268 | I5: 25268 | J5: =H5-I5 -> 0
B6: 2026여수세계섬박람회 시설조성 | H6: =H7 -> 25268 | I6: 25268 | J6: =H6-I6 -> 0
C7: 시설조성부 부서운영 | H7: =H8 -> 25268 | I7: 25268 | J7: =H7-I7 -> 0
D8: 기본경비 | H8: =H9 -> 25268 | I8: 25268 | J8: =H8-I8 -> 0
E9: 200 물건비 | H9: =SUM(H10,H15,H19,H22) -> 25268 | I9: 25268 | J9: =H9-I9 -> 0
F10: 201 일반운영비 | H10: =SUM(H11,H13) -> 8568 | I10: 8568 | J10: =H10-I10 -> 0
G11: 01 사무관리비 | H11: =M11 -> 2520 | I11: 2520 | J11: =H11-I11 -> 0 | K11: [일반수용비] | M11: =SUM(M12:M12) -> 2520
K12: ○ 부서운영을 위한 소모품 구입 : 210,000원*12월 | L12: = | M12: 2520
G13: 15 복리후생비 | H13: =M13 -> 6048 | I13: 6048 | J13: =H13-I13 -> 0 | K13: [급량비] | M13: =M14 -> 6048
K14: ○ 기본업무수행 급량비 : 9,000원*7명*8일*12월 | L14: = | M14: 6048
F15: 202 여비 | H15: =H16 -> 12600 | I15: 12600 | J15: =H15-I15 -> 0
G16: 01 국내여비 | H16: =M16 -> 12600 | I16: 12600 | J16: =H16-I16 -> 0 | K16: [국내여비] | M16: =SUM(M17:M18) -> 12600
K17: ○ 시설조성부 기본업무 수행 관내여비 : 20,000원*7명*2일*12월 | L17: = | M17: 3360
K18: ○ 시설조성부 기본업무 수행 관외여비 : 110,000원*7명*12월 | L18: = | M18: 9240
F19: 203 업무추진비 | H19: =H20 -> 2000 | I19: 2000 | J19: =H19-I19 -> 0
G20: 07 사업업무추진비 | H20: =M20 -> 2000 | I20: 2000 | J20: =H20-I20 -> 0 | K20: [사업업무추진비] | M20: =SUM(M21) -> 2000
K21: ○ 시설조성부 업무추진 : 2,000,000원*1식 | L21: = | M21: 2000
F22: 217 관서업무비 | H22: =H23 -> 2100 | I22: 2100 | J22: =H22-I22 -> 0
G23: 02 부서업무비 | H23: =M23 -> 2100 | I23: 2100 | J23: =H23-I23 -> 0 | K23: [부서업무비] | M23: =M24 -> 2100
K24: ○ 시설조성부 부서운영 총액계상 : 175,000원*12월 | L24: = | M24: 2100

Sheet 전시연출부
A1: 지출예산(세부사업) - 전시연출부 | M1: 단위 : 천원
A2: 구 분 | B2: 사업 | E2: 편성목 | H2: 예산액 (A) | I2: 기정액(본예산) (B) | J2: 비교증감 (A-B) | K2: 산 출 기 초
B3: 정책 | C3: 단위 | D3: 세부 | E3: 그룹 | F3: 목 | G3: 세목
A4: 총계(사업예산 + 자본예산) | H4: =H5 -> 34668 | I4: 25268 | J4: =H4-I4 -> 9400
A5: 사업예산 | H5: =H6 -> 34668 | I5: 25268 | J5: =H5-I5 -> 9400
B6: 2026여수세계섬박람회 전시연출 | H6: =SUM(H7,H18,H28) -> 34668 | I6: 25268 | J6: =H6-I6 -> 9400
C7: 2026여수세계섬박람회 전시연출 | H7: =H8 -> 4700 | I7: 0 | J7: =H7-I7 -> 4700
D8: 섬 테마존 조성 업무 추진 | H8: =H9 -> 4700 | I8: 0 | J8: =H8-I8 -> 4700
E9: 200 물건비 | H9: =H10 -> 4700 | I9: 0 | J9: =H9-I9 -> 4700
F10: 201 일반운영비 | H10: =SUM(H11,H15) -> 4700 | I10: 0 | J10: =H10-I10 -> 4700
G11: 01 사무관리비 | H11: =M11 -> 3500 | I11: 0 | J11: =H11-I11 -> 3500 | K11: [운영수당] | M11: =SUM(M13:M14) -> 3500
K12: 추경1회
K13: ○ 제안서 평가위원 심사수당 : 250,000원*10명 | L13: = | M13: 2500
K14: ○ 제안서 평가위원 실비 : 1,000,000원*1식 | L14: = | M14: 1000
H15: =M15 -> 1200 | I15: 0 | J15: =H15-I15 -> 1200 | K15: [임차료] | M15: =SUM(M17) -> 1200
K16: 추경1회
K17: ○ 회의실 임차료 : 400,000원*3회 | L17: = | M17: 1200
D18: 섬박람회 상징 아트포토존 조성 업무 추진 | H18: =H19 -> 4700 | I18: 0 | J18: =H18-I18 -> 4700
E19: 200 물건비 | H19: =H20 -> 4700 | I19: 0 | J19: =H19-I19 -> 4700
F20: 201 일반운영비 | H20: =SUM(H21,H25) -> 4700 | I20: 0 | J20: =H20-I20 -> 4700
G21: 01 사무관리비 | H21: =M21 -> 3500 | I21: 0 | J21: =H21-I21 -> 3500 | K21: [운영수당] | M21: =SUM(M23:M24) -> 3500
K22: 추경1회
K23: ○ 제안서 평가위원 심사수당 : 250,000원*10명 | L23: = | M23: 2500
K24: ○ 제안서 평가위원 실비 : 1,000,000원*1식 | L24: = | M24: 1000
H25: =M25 -> 1200 | I25: 0 | J25: =H25-I25 -> 1200 | K25: [임차료] | M25: =SUM(M27) -> 1200
K26: 추경1회
K27: ○ 회의실 임차료 : 400,000원*3회 | L27: = | M27: 1200
C28: 전시연출부 부서운영 | H28: =H29 -> 25268 | I28: 25268 | J28: =H28-I28 -> 0
D29: 기본경비 | H29: =H30 -> 25268 | I29: 25268 | J29: =H29-I29 -> 0
E30: 200 물건비 | H30: =SUM(H31,H36,H40,H43) -> 25268 | I30: 25268 | J30: =H30-I30 -> 0
F31: 201 일반운영비 | H31: =SUM(H32,H34) -> 8568 | I31: 8568 | J31: =H31-I31 -> 0
G32: 01 사무관리비 | H32: =M32 -> 2520 | I32: 2520 | J32: =H32-I32 -> 0 | K32: [일반수용비] | M32: =SUM(M33:M33) -> 2520
K33: ○ 부서운영을 위한 소모품 구입 : 210,000원*12월 | L33: = | M33: 2520
G34: 15 복리후생비 | H34: =M34 -> 6048 | I34: 6048 | J34: =H34-I34 -> 0 | K34: [급량비] | M34: =SUM(M35) -> 6048
K35: ○ 기본업무수행 급량비 : 9,000원*7명*8일*12월 | L35: = | M35: 6048
F36: 202 여비 | H36: =H37 -> 12600 | I36: 12600 | J36: =H36-I36 -> 0
G37: 01 국내여비 | H37: =M37 -> 12600 | I37: 12600 | J37: =H37-I37 -> 0 | K37: [국내여비] | M37: =SUM(M38:M39) -> 12600
K38: ○ 전시연출부 기본업무 수행 관내여비 : 20,000원*7명*2일*12월 | L38: = | M38: 3360
K39: ○ 전시연출부 기본업무 수행 관외여비 : 110,000원*7명*12월 | L39: = | M39: 9240
F40: 203 업무추진비 | H40: =H41 -> 2000 | I40: 2000 | J40: =H40-I40 -> 0
...

Sheet 예비비
A1: 지출예산(세부사업) - 예비비 | M1: 단위 : 천원
A2: 구 분 | B2: 사업 | E2: 편성목 | H2: 예산액 (A) | I2: 기정액(본예산) (B) | J2: 비교증감 (A-B) | K2: 산 출 기 초
B3: 정책 | C3: 단위 | D3: 세부 | E3: 그룹 | F3: 목 | G3: 세목
A4: 총계(사업예산 + 자본예산) | H4: =H5+H15 -> 380240 | I4: 316640 | J4: =H4-I4 -> 63600
A5: 사업예산 | H5: =H6 -> 380240 | I5: 316640 | J5: =H5-I5 -> 63600
B6: 예비비 | H6: =H7 -> 380240 | I6: 316640 | J6: =H6-I6 -> 63600
C7: 예비비 | H7: =H8 -> 380240 | I7: 316640 | J7: =H7-I7 -> 63600
D8: 예비비 | H8: =H9 -> 380240 | I8: 316640 | J8: =H8-I8 -> 63600
E9: 800 예비비 | H9: =H10 -> 380240 | I9: 316640 | J9: =H9-I9 -> 63600
F10: 801 예비비 | H10: =H11 -> 380240 | I10: 316640 | J10: =H10-I10 -> 63600
G11: 01 일반예비비 | H11: =M11 -> 380240 | I11: 316640 | J11: =H11-I11 -> 63600 | K11: [일반예비비] | M11: =M14 -> 380240
K12: ○ 예비비 : 316,640,000원*1식 | L12: = | M12: 316640
K13: 추경1회
K14: ○ 예비비 : 경정 380,240,000원 | L14: = | M14: 380240
A15: 자본예산 | H15: =SUM(H16,H29) -> 0 | I15: 0 | J15: =H15-I15 -> 0
B16: 예비비(자본) | H16: =SUM(H17,H57) -> 0 | I16: 0 | J16: =H16-I16 -> 0
C17: 예비비(자본) | H17: =H18 -> 0 | I17: 0 | J17: =H17-I17 -> 0
D18: 예비비(자본) | H18: =H19 -> 0 | I18: 0 | J18: =H18-I18 -> 0
E19: 800 예비비 | H19: =H20 -> 0 | I19: 0 | J19: =H19-I19 -> 0
F20: 801 예비비 | H20: =H21 -> 0 | I20: 0 | J20: =H20-I20 -> 0
G21: 01 일반예비비 | H21: =M21 -> 0 | I21: 0 | J21: =H21-I21 -> 0 | K21: [일반예비비] | M21: =M22 -> 0
K22: ○ 예비비(자본) : 0원 | L22: = | M22: 0

Sheet 기획본부(위탁)
A1: 지출예산 - 기획본부(위탁) | M1: 단위 : 천 원
A2: 구 분 | B2: 사업 | E2: 편성목 | H2: 예산액 (A) | I2: 기정액(본예산) (B) | J2: 비교증감 (A-B) | K2: 산 출 기 초
B3: 정책 | C3: 단위 | D3: 세부 | E3: 그룹 | F3: 목 | G3: 세목
A4: 총계(사업예산 + 자본예산) | H4: =H5 -> 2950000 | I4: 2950000 | J4: =H4-I4 -> 0
A5: 사업예산 | H5: =H6+H30 -> 2950000 | I5: 2950000 | J5: =H5-I5 -> 0
B6: 2026여수세계섬박람회 기획홍보(위탁) | H6: =H7 -> 2000000 | I6: 2000000 | J6: =H6-I6 -> 0
C7: 2026여수세계섬박람회 홍보 | H7: =H8 -> 2000000 | I7: 2000000 | J7: =H7-I7 -> 0
D8: 박람회 홍보 | H8: =H9+H25 -> 2000000 | I8: 2000000 | J8: =H8-I8 -> 0
E9: 200 물건비 | H9: =H10 -> 1974000 | I9: 1974000 | J9: =H9-I9 -> 0
F10: 201 일반운영비 | H10: =SUM(H11,H19,H23) -> 1974000 | I10: 1974000 | J10: =H10-I10 -> 0
G11: 01 사무관리비 | H11: =M11 -> 1419000 | I11: 1419000 | J11: =H11-I11 -> 0 | K11: [사무관리비] | M11: =SUM(M12:M18) -> 1419000
K12: ○ 홍보물품 등 제작 : 140,000,000원*1식 | L12: = | M12: 140000
K13: ○ 홍보부스 참가 : 5,000,000원*4회 | L13: = | M13: 20000
K14: ○ 제안서, 공모전 평가위원 수당 : 7,000,000원*1식 | L14: = | M14: 7000
K15: ○ 제안서, 공모전 평가위원 교통비 등 기타 실비 : 2,000,000원*1식 | L15: = | M15: 2000
K16: ○ 종합홍보 대행 용역(1차분) : 1,000,000,000원*1식 | L16: = | M16: 1000000
K17: ○ 온라인 홍보 대행 용역 : 150,000,000원*1식 | L17: = | M17: 150000
K18: ○ 홍보영상 제작 용역 : 100,000,000원*1식 | L18: = | M18: 100000
G19: 03 행사운영비 | H19: =M19 -> 55000 | I19: 55000 | J19: =H19-I19 -> 0 | K19: [행사운영비] | M19: =SUM(M20:M22) -> 55000
K20: ○ 사전 홍보 이벤트 : 30,000,000원*1식 | L20: = | M20: 30000
K21: ○ 홍보부스 운영 : 5,000,000원*1식 | L21: = | M21: 5000
K22: ○ 홍보대사, 서포터즈 운영 : 20,000,000원*1식 | L22: = | M22: 20000
G23: 16 광고선전비 | H23: =M23 -> 500000 | I23: 500000 | J23: =H23-I23 -> 0 | K23: [광고료] | M23: =SUM(M24) -> 500000
K24: ○ 섬박람회 광고 홍보료 : 500,000,000원*1식 | L24: = | M24: 500000
E25: 300 경상이전 | H25: =H26 -> 26000 | I25: 26000 | J25: =H25-I25 -> 0
F26: 301 일반보상금 | H26: =H27 -> 26000 | I26: 26000 | J26: =H26-I26 -> 0
G27: 14 기타보상금 | H27: =M27 -> 26000 | I27: 26000 | J27: =H27-I27 -> 0 | K27: [기타보상금] | M27: =SUM(M28:M29) -> 26000
K28: ○ 공모전 시상금 : 7,000,000원*3회 | L28: = | M28: 21000
K29: ○ 각종 이벤트 경품 : 5,000,000원*1식 | L29: = | M29: 5000
B30: 2026여수세계섬박람회 유치협력(위탁) | H30: =H31 -> 950000 | I30: 950000 | J30: =H30-I30 -> 0
C31: 2026여수세계섬박람회 유치 | H31: =H32+H56 -> 950000 | I31: 950000 | J31: =H31-I31 -> 0
D32: 관람객 유치 | H32: =H33+H49 -> 660000 | I32: 660000 | J32: =H32-I32 -> 0
E33: 200 물건비 | H33: =H34 -> 498000 | I33: 498000 | J33: =H33-I33 -> 0
F34: 201 일반운영비 | H34: =SUM(H35,H45) -> 498000 | I34: 498000 | J34: =H34-I34 -> 0
G35: 01 사무관리비 | H35: =M35 -> 250000 | I35: 450000 | J35: =H35-I35 -> -200000 | K35: [사무관리비] | M35: =SUM(M36:M41,M44) -> 250000
K36: ○ 유치활동 추진을 위한 소책자, 협약서 등 제작(다국어) : 40,000,000원*1식 | L36: = | M36: 40000
K37: ○ 유치활동 PPT, 영상 제작(다국어) : 16,000,000원*1식 | L37: = | M37: 16000
K38: ○ 유치활동 추진을 위한 통번역 수수료 : 600,000원*40회 | L38: = | M38: 24000
K39: ○ 유치활동 추진을 위한 유치홍보물 제작 : 20,000원*5,000개 | L39: = | M39: 100000
K40: ○ 전국 단위 축제·행사 홍보부스 참가비 : 5,000,000원*6회 | L40: = | M40: 30000
...

Sheet 운영본부(위탁)
A1: 지출예산 - 운영본부(위탁) | M1: 단위 : 천 원
A2: 구 분 | B2: 사업 | E2: 편성목 | H2: 예산액 (A) | I2: 기정액(본예산) (B) | J2: 비교증감 (A-B) | K2: 산 출 기 초
B3: 정책 | C3: 단위 | D3: 세부 | E3: 그룹 | F3: 목 | G3: 세목
A4: 총계(사업예산 + 자본예산) | H4: =H5+H26 -> 19600000 | I4: 19600000 | J4: =H4-I4 -> 0
A5: 사업예산 | H5: =H6+H19 -> 2500000 | I5: 2500000 | J5: =H5-I5 -> 0
B6: 2026여수세계섬박람회 행사(위탁) | H6: =H7 -> 1000000 | I6: 1000000 | J6: =H6-I6 -> 0
C7: 2026여수세계섬박람회 행사 | H7: =H8+H14 -> 1000000 | I7: 1000000 | J7: =H7-I7 -> 0
D8: 사전행사 개최 | H8: =H9 -> 400000 | I8: 400000 | J8: =H8-I8 -> 0
E9: 200 물건비 | H9: =H10 -> 400000 | I9: 400000 | J9: =H9-I9 -> 0
F10: 201 일반운영비 | H10: =H11 -> 400000 | I10: 400000 | J10: =H10-I10 -> 0
G11: 03 행사운영비 | H11: =M11 -> 400000 | I11: 400000 | J11: =H11-I11 -> 0 | K11: [행사운영비] | M11: =SUM(M12:M13) -> 400000
K12: ○ D-365 기념행사 : 280,000,000원*1식 | L12: = | M12: 280000
K13: ○ '너와 나의 섬이야기' 성공개최 이벤트 : 120,000,000원*1식 | L13: = | M13: 120000
D14: 문화행사 추진 | H14: =H15 -> 600000 | I14: 600000 | J14: =H14-I14 -> 0
E15: 200 물건비 | H15: =H16 -> 600000 | I15: 600000 | J15: =H15-I15 -> 0
F16: 201 일반운영비 | H16: =H17 -> 600000 | I16: 600000 | J16: =H16-I16 -> 0
G17: 03 행사운영비 | H17: =M17 -> 600000 | I17: 600000 | J17: =H17-I17 -> 0 | K17: [행사운영비] | M17: =M18 -> 600000
K18: ○ 섬박람회 문화행사 기획 및 프로그램 개발 : 600,000,000원*1식 | L18: = | M18: 600000
B19: 2026여수세계섬박람회 전시연출(위탁) | H19: =H20 -> 1500000 | I19: 1500000 | J19: =H19-I19 -> 0
C20: 2026여수세계섬박람회 전시연출 | H20: =H21 -> 1500000 | I20: 1500000 | J20: =H20-I20 -> 0
D21: 박람회 연출 | H21: =H22 -> 1500000 | I21: 1500000 | J21: =H21-I21 -> 0
E22: 200 물건비 | H22: =H23 -> 1500000 | I22: 1500000 | J22: =H22-I22 -> 0
F23: 201 일반운영비 | H23: =H24 -> 1500000 | I23: 1500000 | J23: =H23-I23 -> 0
G24: 03 행사운영비 | H24: =M24 -> 1500000 | I24: 1500000 | J24: =H24-I24 -> 0 | K24: [행사운영비] | M24: =SUM(M25:M25) -> 1500000
K25: ○ 전시연출 콘텐츠 개발 : 1,500,000,000원*1식 | L25: = | M25: 1500000
A26: 자본예산 | H26: =H27+H57 -> 17100000 | I26: 17100000 | J26: =H26-I26 -> 0
B27: 2026여수세계섬박람회 시설조성(위탁) | H27: =H28 -> 10300000 | I27: 10300000 | J27: =H27-I27 -> 0
C28: 2026여수세계섬박람회 시설조성 | H28: =SUM(H29,H36,H43,H50) -> 10300000 | I28: 10300000 | J28: =H28-I28 -> 0
D29: 섬박람회 랜드마크 조성사업 | H29: =H30 -> 5000000 | I29: 5000000 | J29: =H29-I29 -> 0
E30: 400 자본지출 | H30: =H31 -> 5000000 | I30: 5000000 | J30: =H30-I30 -> 0
F31: 401 시설비및부대비 | H31: =SUM(H32,H34) -> 5000000 | I31: 5000000 | J31: =H31-I31 -> 0
G32: 01 시설비 | H32: =M32 -> 4986500 | I32: 4986500 | J32: =H32-I32 -> 0 | K32: [시설비] | M32: =SUM(M33:M33) -> 4986500
K33: ○ 섬박람회 랜드마크 조성 시설비 : 5,000,000,000원*1식*99.73/100 | L33: = | M33: 4986500
G34: 03 시설부대비 | H34: =M34 -> 13500 | I34: 13500 | J34: =H34-I34 -> 0 | K34: [시설부대비] | M34: =SUM(M35) -> 13500
K35: ○ 섬박람회 랜드마크 조성 시설부대비 : 5,000,000,000원*1식*0.27/100 | L35: = | M35: 13500
D36: 섬박람회장 안전시설물 설치사업 | H36: =H37 -> 3000000 | I36: 3000000 | J36: =H36-I36 -> 0
E37: 400 자본지출 | H37: =H38 -> 3000000 | I37: 3000000 | J37: =H37-I37 -> 0
F38: 401 시설비및부대비 | H38: =SUM(H39,H41) -> 3000000 | I38: 3000000 | J38: =H38-I38 -> 0
G39: 01 시설비 | H39: =M39 -> 2989200 | I39: 2989200 | J39: =H39-I39 -> 0 | K39: [시설비] | M39: =M40 -> 2989200
K40: ○ 섬박람회장 안전시설물 설치 시설비 : 3,000,000,000원*1식*99.64/100 | L40: = | M40: 2989200
...
