Workbook
Name ㄹㄹㄹ: #REF!
Name ㄹㄹㄹ: #REF!
Name ㄹㄹㄹ: #REF!
Name ㄹㄹㄹ: #REF!
Name ㅁ1: #REF!
Name ㅁ1: #REF!
Name ㅁ1: #REF!
Name ㅁ1: #REF!
Name ㅁ1: #REF!
Name ㅇㅇ: #REF!
Name ㅇㅇ: #REF!
Name ㅇㅇㅇ: #REF!
Name ㅇㅇㅇ: #REF!

Sheet 표지
M3: 2025. 6. 2.
A13: 섬박람회 조직위원회 2025년도 제2회 추경예산서
D22: (재)2026여수세계섬박람회 조직위

Sheet 수입예산 총괄표
A1: 수입예산 총괄표(출연금+위탁사업비)
H2: (단위 : 천 원)
A3: 과 목 | F3: 예산액 (제2회추경) | G3: 기정액 (제1회추경) | H3: 비교증감
A4: 구분 | B4: 관 | C4: 항 | D4: 세항 | E4: 목
A5: 총계(사업예산+자본예산) | F5: =F6 -> 30011081 | G5: =G6 -> 24729000 | H5: =F5-G5 -> 5282081
A6: 자체수입금 | F6: =SUM(F7,F20) -> 30011081 | G6: 24729000 | H6: =F6-G6 -> 5282081
B7: 600 사업수익 | F7: =SUM(F8,F17) -> 26117900 | G7: 24729000 | H7: =F7-G7 -> 1388900
C8: 610 영업수익 | F8: =SUM(F9,F11,F13,F15) -> 26099900 | G8: 24711000 | H8: =F8-G8 -> 1388900
D9: 623 대행사업수익 | F9: =F10 -> 22550000 | G9: 22550000 | H9: =F9-G9 -> 0
E10: 01 직접관리비수익 | F10: 22550000 | G10: 22550000 | H10: =F10-G10 -> 0
D11: 647 기부금수익 | F11: =F12 -> 200000 | G11: 200000 | H11: =F11-G11 -> 0
E12: 01 기부금수익 | F12: 200000 | G12: 200000 | H12: =F12-G12 -> 0
D13: 648 출연금 수익 | F13: =F14 -> 3199900 | G13: 1861000 | H13: =F13-G13 -> 1338900
E14: 02 자치단체출연금수익 | F14: 3199900 | G14: 1861000 | H14: =F14-G14 -> 1338900
D15: 649 후원금 수익 | F15: =F16 -> 150000 | G15: 100000 | H15: =F15-G15 -> 50000
E16: 01 지정후원금수익 | F16: 150000 | G16: 100000 | H16: =F16-G16 -> 50000
C17: 670 영업외수익 | F17: =F18 -> 18000 | G17: 18000 | H17: =F17-G17 -> 0
D18: 671 이자수익 | F18: =F19 -> 18000 | G18: 18000 | H18: =F18-G18 -> 0
E19: 01 예금이자수익 | F19: 18000 | G19: 18000 | H19: =F19-G19 -> 0
B20: 100 자본적수입 | F20: =F21+F24 -> 3893181 | G20: =G21+G24 -> 0 | H20: =F20-G20 -> 3893181
C21: 170 자본잉여금수입 | F21: =F22 -> 2270000 | G21: 0 | H21: =F21-G21 -> 2270000
D22: 177 출연금 수입 | F22: =F23 -> 2270000 | G22: 0 | H22: =F22-G22 -> 2270000
E23: 01 정부출연금 | F23: 2270000 | G23: 0 | H23: =F23-G23 -> 2270000
C24: 180 유보자금 | F24: =F25 -> 1623181 | G24: =G25 -> 0 | H24: =F24-G24 -> 1623181
D25: 181 순세계잉여금 | F25: =F26+F27 -> 1623181 | G25: =G26+G27 -> 0 | H25: =F25-G25 -> 1623181
E26: 01 순세계잉여금 | F26: 1621558 | G26: 0 | H26: =F26-G26 -> 1621558
E27: 03 대행사업비 사용잔액 | F27: 1623 | G27: 0 | H27: =F27-G27 -> 1623

Sheet 지출예산 총괄표
A1: 지출예산 총괄표(출연금+위탁사업비)
I2: (단위 : 천 원)
A3: 과 목 | G3: 예산액 (제2회추경) | H3: 기정액 (제1회추경) | I3: 비교증감
A4: 구분 | B4: 정책사업
A5: 총계(출연금+위탁사업비) | G5: =G6+G20 -> 30011081 | H5: 24729000 | I5: =G5-H5 -> 5282081
A6: 출연금(사업예산+자본예산) | G6: =SUM(G7,G17) -> 7461081 | H6: 2179000 | I6: =G6-H6 -> 5282081
A7: 사업예산 | G7: =SUM(G8:G16) -> 4681081 | H7: 2179000 | I7: =G7-H7 -> 2502081
B8: 2026여수세계섬박람회 행정관리 | G8: =행정관리부!H5 -> 1097148 | H8: 937348 | I8: =G8-H8 -> 159800
B9: 2026여수세계섬박람회 기획홍보 | G9: =기획홍보부!H5 -> 263538 | H9: 261892 | I9: =G9-H9 -> 1646
B10: 2026여수세계섬박람회 수익사업 | G10: =수익사업부!H5 -> 119956 | H10: 91166 | I10: =G10-H10 -> 28790
B11: 2026여수세계섬박람회 유치협력 | G11: =유치협력부!H5 -> 62518 | H11: 62518 | I11: =G11-H11 -> 0
B12: 2026여수세계섬박람회 운영 | G12: =운영부!H5 -> 360632 | H12: 360632 | I12: =G12-H12 -> 0
B13: 2026여수세계섬박람회 행사 | G13: =행사부!H5 -> 25268 | H13: 25268 | I13: =G13-H13 -> 0
B14: 2026여수세계섬박람회 시설조성 | G14: =시설조성부!H5 -> 25268 | H14: 25268 | I14: =G14-H14 -> 0
B15: 2026여수세계섬박람회 전시연출 | G15: =전시연출부!H5 -> 34668 | H15: 34668 | I15: =G15-H15 -> 0
B16: 예비비 | G16: =예비비!H6 -> 2692085 | H16: 380240 | I16: =G16-H16 -> 2311845
A17: 자본예산 | G17: =SUM(G18:G19) -> 2780000 | H17: 0 | I17: =G17-H17 -> 2780000
B18: 2026여수세계섬박람회 조성연출 | G18: =시설조성부!H26 -> 2780000 | H18: 0 | I18: =G18-H18 -> 2780000
B19: 예비비(자본) | G19: =예비비!H17 -> 0 | H19: 0 | I19: =G19-H19 -> 0
A20: 위탁사업비(사업예산+자본예산) | G20: =G21+G26 -> 22550000 | H20: 22550000 | I20: =G20-H20 -> 0
A21: 사업예산 | G21: =SUM(G22:G25) -> 5450000 | H21: 5450000 | I21: =G21-H21 -> 0
B22: 2026여수세계섬박람회 기획홍보(위탁) | G22: ='기획본부(위탁)'!H6 -> 2000000 | H22: 2000000 | I22: =G22-H22 -> 0
B23: 2026여수세계섬박람회 유치협력(위탁) | G23: ='기획본부(위탁)'!H43 -> 950000 | H23: 950000 | I23: =G23-H23 -> 0
B24: 2026여수세계섬박람회 행사(위탁) | G24: ='운영본부(위탁)'!H6 -> 1000000 | H24: 1000000 | I24: =G24-H24 -> 0
B25: 2026여수세계섬박람회 전시연출(위탁) | G25: ='운영본부(위탁)'!H19 -> 1500000 | H25: 1500000 | I25: =G25-H25 -> 0
A26: 자본예산 | G26: =SUM(G27:G28) -> 17100000 | H26: 17100000 | I26: =G26-H26 -> 0
B27: 2026여수세계섬박람회 시설조성(위탁) | G27: ='운영본부(위탁)'!H27 -> 10300000 | H27: 10300000 | I27: =G27-H27 -> 0
B28: 2026여수세계섬박람회 전시연출(위탁) | G28: ='운영본부(위탁)'!H71 -> 6800000 | H28: 6800000 | I28: =G28-H28 -> 0

Sheet 지출예산
A1: 지출예산 총괄표
I2: (단위 : 천 원)
A3: 과 목 | G3: 예산액 (A) | H3: 기정액(제1회추경) (B) | I3: 비교증감 (A-B)
A4: 구분 | B4: 정책사업 | C4: 단위사업 | D4: 세부사업 | E4: 목 | F4: 세목
A5: 총계 | G5: =G6+G198 -> 7461081 | H5: =SUM(H6,H198) -> 2179000 | I5: =G5-H5 -> 5282081
A6: 사업예산 | G6: =SUM(G7+G45+G84+G118+G131+G150+G162+G174+G193) -> 4681081 | H6: =SUM(H7,H45,H84,H118,H131,H150,H162,H174,H193) -> 2179000 | I6: =G6-H6 -> 2502081
B7: 2026여수세계섬박람회 행정관리 | G7: =SUM(G8,G18) -> 1097148 | H7: 937348 | I7: =G7-H7 -> 159800
C8: 2026여수세계섬박람회 행정 업무추진 | G8: =SUM(G9,G12) -> 133220 | H8: 80420 | I8: =G8-H8 -> 52800
D9: 직원역량강화 워크숍 | G9: =G10 -> 32960 | H9: 32960 | I9: =G9-H9 -> 0
E10: 교육훈련비 | G10: =행정관리부!H10 -> 32960 | H10: 32960 | I10: =G10-H10 -> 0
F11: 교육훈련경비 | G11: =행정관리부!H11 -> 32960 | H11: 32960 | I11: =G11-H11 -> 0
D12: 이사회 및 각종 위원회 운영 | G12: =G13+G16 -> 100260 | H12: 47460 | I12: =G12-H12 -> 52800
E13: 일반운영비 | G13: =행정관리부!H16 -> 47460 | H13: 47460 | I13: =G13-H13 -> 0
F14: 사무관리비 | G14: =행정관리부!H17 -> 45060 | H14: 45060 | I14: =G14-H14 -> 0
F15: 회의비 | G15: =행정관리부!H28 -> 2400 | H15: 2400 | I15: =G15-H15 -> 0
E16: 여비 | G16: =행정관리부!H30 -> 52800 | H16: 0 | I16: =G16-H16 -> 52800
F17: 국외업무여비 | G17: =행정관리부!H31 -> 52800 | H17: 0 | I17: =G17-H17 -> 52800
C18: 사무국운영 | G18: =G19 -> 963928 | H18: 856928 | I18: =G18-H18 -> 107000
D19: 기본경비 | G19: =SUM(G20,G24,G26,G31,G33,G35,G38,G40,G43) -> 963928 | H19: 856928 | I19: =G19-H19 -> 107000
E20: 인건비 | G20: =행정관리부!H37 -> 623731 | H20: 609331 | I20: =G20-H20 -> 14400
F21: 보수 | G21: =행정관리부!H38 -> 406800 | H21: 392400 | I21: =G21-H21 -> 14400
F22: 기타직보수 | G22: =행정관리부!H45 -> 186102 | H22: 186102 | I22: =G22-H22 -> 0
F23: 기간제근로자등보수 | G23: =행정관리부!H50 -> 30829 | H23: 30829 | I23: =G23-H23 -> 0
E24: 퇴직급여 | G24: =행정관리부!H54 -> 10500 | H24: 10500 | I24: =G24-H24 -> 0
F25: 퇴직급여충당금 | G25: =행정관리부!H55 -> 10500 | H25: 10500 | I25: =G25-H25 -> 0
E26: 일반운영비 | G26: =행정관리부!H58 -> 217440 | H26: 125440 | I26: =G26-H26 -> 92000
F27: 사무관리비 | G27: =행정관리부!H59 -> 82560 | H27: 82560 | I27: =G27-H27 -> 0
F28: 공공운영비 | G28: =행정관리부!H76 -> 33760 | H28: 21760 | I28: =G28-H28 -> 12000
F29: 행사운영비 | G29: =행정관리부!H85 -> 80000 | H29: 0 | I29: =G29-H29 -> 80000
F30: 복리후생비 | G30: =행정관리부!H88 -> 21120 | H30: 21120 | I30: =G30-H30 -> 0
E31: 여비 | G31: =행정관리부!H94 -> 18000 | H31: 18000 | I31: =G31-H31 -> 0
F32: 국내여비 | G32: =행정관리부!H95 -> 18000 | H32: 18000 | I32: =G32-H32 -> 0
E33: 업무추진비 | G33: =행정관리부!H98 -> 38400 | H33: 38400 | I33: =G33-H33 -> 0
F34: 사업업무추진비 | G34: =행정관리부!H99 -> 38400 | H34: 38400 | I34: =G34-H34 -> 0
E35: 직무수행경비 | G35: =행정관리부!H106 -> 26520 | H35: 25920 | I35: =G35-H35 -> 600
F36: 직급보조비 | G36: =행정관리부!H107 -> 19800 | H36: 19200 | I36: =G36-H36 -> 600
F37: 특정업무경비 | G37: =행정관리부!H112 -> 6720 | H37: 6720 | I37: =G37-H37 -> 0
E38: 수선유지교체비 | G38: =행정관리부!H114 -> 5000 | H38: 5000 | I38: =G38-H38 -> 0
F39: 수선유지비 | G39: =행정관리부!H115 -> 5000 | H39: 5000 | I39: =G39-H39 -> 0
E40: 관서업무비 | G40: =행정관리부!H117 -> 4740 | H40: 4740 | I40: =G40-H40 -> 0
...

Sheet 행정관리부
A1: 지출예산(세부사업) - 행정관리부 | M1: 단위 : 천원
A2: 구 분 | B2: 사업 | E2: 편성목 | H2: 예산액 (A) | I2: 기정액(제1회추경) (B) | J2: 비교증감 (A-B) | K2: 산 출 기 초
B3: 정책 | C3: 단위 | D3: 세부 | E3: 그룹 | F3: 목 | G3: 세목
A4: 총계(사업예산 + 자본예산) | H4: =H5 -> 1097148 | I4: 937348 | J4: =H4-I4 -> 159800
A5: 사업예산 | H5: =H6 -> 1097148 | I5: 937348 | J5: =H5-I5 -> 159800
B6: 2026여수세계섬박람회 행정관리 | H6: =SUM(H7,H34) -> 1097148 | I6: 937348 | J6: =H6-I6 -> 159800
C7: 2026여수세계섬박람회 행정 업무추진 | H7: =SUM(H8,H14) -> 133220 | I7: 80420 | J7: =H7-I7 -> 52800
D8: 직원역랑강화 워크숍 | H8: =H9 -> 32960 | I8: 32960 | J8: =H8-I8 -> 0
E9: 200 물건비 | H9: =H10 -> 32960 | I9: 32960 | J9: =H9-I9 -> 0
F10: 213 교육훈련비 | H10: =H11 -> 32960 | I10: 32960 | J10: =H10-I10 -> 0
G11: 교육훈련경비 | H11: =M11 -> 32960 | I11: 32960 | J11: =H11-I11 -> 0 | K11: [교육훈련경비] | M11: =SUM(M12:M13) -> 32960
K12: ○ 직원역량강화 교육 강사수당 : 370,000원*2명*4회 | L12: = | M12: 2960
K13: ○ 현장체험 등 워크숍 운영 경비 : 15,000,000원*2회 | L13: = | M13: 30000
D14: 이사회 및 각종 위원회 운영 | H14: =H15 -> 100260 | I14: 47460 | J14: =H14-I14 -> 52800
E15: 200 물건비 | H15: =H16+H30 -> 100260 | I15: 47460 | J15: =H15-I15 -> 52800
F16: 201 일반운영비 | H16: =SUM(H17,H28) -> 47460 | I16: 47460 | J16: =H16-I16 -> 0
G17: 01 사무관리비 | H17: =SUM(M17,M20,M26) -> 45060 | I17: 45060 | J17: =H17-I17 -> 0 | K17: [일반수용비] | M17: =SUM(M18:M19) -> 2560
K18: ○ 이사회 책자 제작 및 소모품 구입 : 20,000원*13명*6회 | L18: = | M18: 1560
K19: ○ 이사회 변경등기 및 법무사 수수료 : 1,000,000원*1식 | L19: = | M19: 1000
K20: [운영수당] | M20: =SUM(M21:M25) -> 30500
K21: ○ 이사회 참석수당 : 150,000원*13명*6회 | L21: = | M21: 11700
K22: ○ 이사회 참석자 실비보상 : 110,000원*13명*6회 | L22: = | M22: 8580
K23: ○ 인사위원회 참석수당 : 100,000원*3명*5회 | L23: = | M23: 1500
K24: ○ 명예위원장, 부위원장, 특별위원회 위원 등 행사 참석 실비 : 110,000원*13명*4회 | L24: = | M24: 5720
K25: ○ 계약심의위원회 수당 등 지급 : 100,000원*6명*5회 | L25: = | M25: 3000
K26: [임차료] | M26: =M27 -> 12000
K27: ○ 이사회 개최를 위한 회의실 임차료 : 300,000원*4회 | L27: = | M27: 12000
G28: 14 회의비 | H28: =M28 -> 2400 | I28: 2400 | J28: =H28-I28 -> 0 | K28: [회의비] | M28: =M29 -> 2400
K29: ○ 이사회 등 회의 운영비 : 400,000원*6회 | L29: = | M29: 2400
F30: 202 여비 | H30: =SUM(H31) -> 52800 | I30: 0 | J30: =H30-I30 -> 52800
G31: 03 국외업무여비 | H31: =M31 -> 52800 | I31: 0 | J31: =H31-I31 -> 52800 | K31: [국외업무여비] | M31: =SUM(M33:M34) -> 52800
K32: 추경2회
K33: ○ 조직위원회 임원진 선진지 견학 : 2,200,000원 * 24명 * 1회 | L33: = | M33: 52800
C34: 사무국운영 | H34: =H35 -> 963928 | I34: 856928 | J34: =H34-I34 -> 107000
D35: 기본경비 | H35: =SUM(H36,H57,H122) -> 963928 | I35: 856928 | J35: =H35-I35 -> 107000
E36: 100 인건비 | H36: =SUM(H37,H54) -> 634231 | I36: 619831 | J36: =H36-I36 -> 14400
F37: 101 인건비 | H37: =SUM(H38,H45,H50) -> 623731 | I37: 609331 | J37: =H37-I37 -> 14400
G38: 01 보수 | H38: =SUM(M38,M43) -> 406800 | I38: 392400 | J38: =H38-I38 -> 14400 | K38: [직원파견수당] | M38: =SUM(M39,M42) -> 316800
K39: ○ 4급이상 : 600,000원*2명*12월 | L39: = | M39: 14400
K40: ○ 5급이하 : 400,000원*60명*12월 | L40: = | M40: 288000
...

Sheet 기획홍보부
A1: 지출예산(세부사업) - 기획홍보부 | M1: 단위 : 천원
A2: 구 분 | B2: 사업 | E2: 편성목 | H2: 예산액 (A) | I2: 기정액(제1회추경) (B) | J2: 비교증감 (A-B) | K2: 산 출 기 초
B3: 정책 | C3: 단위 | D3: 세부 | E3: 그룹 | F3: 목 | G3: 세목
A4: 총계(사업예산 + 자본예산) | H4: =H5 -> 263538 | I4: 261892 | J4: =H4-I4 -> 1646
A5: 사업예산 | H5: =H6 -> 263538 | I5: 261892 | J5: =H5-I5 -> 1646
B6: 2026여수세계섬박람회 기획홍보 | H6: =SUM(H7,H25,H31,H38,H56) -> 263538 | I6: 261892 | J6: =H6-I6 -> 1646
C7: 2026여수세계섬박람회 기획 | H7: =H8+H14 -> 38600 | I7: 38600 | J7: =H7-I7 -> 0
D8: 박람회 기획 | H8: =SUM(H9) -> 10000 | I8: 10000 | J8: =H8-I8 -> 0
E9: 300 경상이전 | H9: =SUM(H10) -> 10000 | I9: 10000 | J9: =H9-I9 -> 0
F10: 303 포상금 | H10: =H11 -> 10000 | I10: 10000 | J10: =H10-I10 -> 0
G11: 01 포상금 | H11: =M11 -> 10000 | I11: 10000 | J11: =H11-I11 -> 0 | K11: [포상금] | M11: =M13 -> 10000
K12: 추경1회
K13: ○ 2024년 직원 아이디어 경진대회 포상금 : 10,000,000원*1식 | L13: = | M13: 10000
D14: 자문위원회 운영 | H14: =H15 -> 28600 | I14: 28600 | J14: =H14-I14 -> 0
E15: 200 물건비 | H15: =SUM(H16) -> 28600 | I15: 28600 | J15: =H15-I15 -> 0
F16: 201 일반운영비 | H16: =SUM(H17,H21,H23) -> 28600 | I16: 28600 | J16: =H16-I16 -> 0
G17: 01 사무관리비 | H17: =M17 -> 28000 | I17: 28000 | J17: =H17-I17 -> 0 | K17: [운영수당] | M17: =SUM(M18:M20) -> 28000
K18: ○ 자문위원회 자문수당(대면) : 150,000원*3회*32명 | L18: = | M18: 14400
K19: ○ 자문위원회 자문수당(서면) : 100,000원*3회*32명 | L19: = | M19: 9600
K20: ○ 자문위원회 참석자 실비 보상 : 4,000,000원*1식 | L20: = | M20: 4000
G21: 03 행사운영비 | H21: =M21 -> 300 | I21: 300 | J21: =H21-I21 -> 0 | K21: [행사운영비] | M21: =M22 -> 300
K22: ○ 자문위원회 운영 행사운영비 : 100,000원*3회 | L22: = | M22: 300
G23: 14 회의비 | H23: =M23 -> 300 | I23: 300 | J23: =H23-I23 -> 0 | K23: [회의비] | M23: =M24 -> 300
K24: ○ 자문위원회 회의 운영비 : 50,000원*6회 | L24: = | M24: 300
C25: 2026여수세계섬박람회 홍보 | H25: =H26 -> 50000 | I25: 50000 | J25: =H25-I25 -> 0
D26: 홈페이지 유지관리 | H26: =H27 -> 50000 | I26: 50000 | J26: =H26-I26 -> 0
E27: 200 물건비 | H27: =H28 -> 50000 | I27: 50000 | J27: =H27-I27 -> 0
F28: 214 수선유지교체비 | H28: =H29 -> 50000 | I28: 50000 | J28: =H28-I28 -> 0
G29: 05 수선유지비 | H29: =M29 -> 50000 | I29: 50000 | J29: =H29-I29 -> 0 | K29: [수선유지비] | M29: =SUM(M30:M30) -> 50000
K30: ○ 누리집 유지관리 용역 : 50,000,000원*1식 | L30: = | M30: 50000
D31: 박람회 홍보 | H31: =H32 -> 1646 | I31: 0 | J31: =H31-I31 -> 1646
E32: 750 기타 | H32: =H33 -> 1646 | I32: 0 | J32: =H32-I32 -> 1646
F33: 751 반환금 | H33: =H34 -> 1646 | I33: 0 | J33: =H33-I33 -> 1646
G34: 04 대행사업비반환금 | H34: =M34 -> 1646 | I34: 0 | J34: =H34-I34 -> 1646 | K34: [대행사업비반환금] | M34: =SUM(M36:M37) -> 1646
K35: 추경2회
K36: ○ 2026여수세계섬박람회 조직위원회 위탁사업(홍보) 사용잔액 1,622,850원*1식 | L36: = | M36: 1623
K37: ○ 위탁사업(홍보) 발생이자 22,060원*1식 | L37: = | M37: 23
C38: 기획홍보부 부서운영 | H38: =H39 -> 28292 | I38: 28292 | J38: =H38-I38 -> 0
D39: 기본경비 | H39: =H40 -> 28292 | I39: 28292 | J39: =H39-I39 -> 0
E40: 200 물건비 | H40: =SUM(H41,H46,H50,H53) -> 28292 | I40: 28292 | J40: =H40-I40 -> 0
...

Sheet 수익사업부
A1: 지출예산(세부사업) - 수익사업부 | M1: 단위 : 천원
A2: 구 분 | B2: 사업 | E2: 편성목 | H2: 예산액 (A) | I2: 기정액(제1회추경) (B) | J2: 비교증감 (A-B) | K2: 산 출 기 초
B3: 정책 | C3: 단위 | D3: 세부 | E3: 그룹 | F3: 목 | G3: 세목
A4: 총계(사업예산 + 자본예산) | H4: =H5 -> 119956 | I4: 91166 | J4: =H4-I4 -> 28790
A5: 사업예산 | H5: =H6 -> 119956 | I5: 91166 | J5: =H5-I5 -> 28790
B6: 2026여수세계섬박람회 수익사업 | H6: =SUM(H7,H52) -> 119956 | I6: 91166 | J6: =H6-I6 -> 28790
C7: 2026여수세계섬박람회 수익사업 | H7: =SUM(H8,H18,H24,H34,H42) -> 87640 | I7: 58850 | J7: =H7-I7 -> 28790
D8: 박람회 휘장업무 추진 | H8: =H9 -> 14450 | I8: 14450 | J8: =H8-I8 -> 0
E9: 200 물건비 | H9: =H10 -> 14450 | I9: 14450 | J9: =H9-I9 -> 0
F10: 201 일반운영비 | H10: =H11+H16 -> 14450 | I10: 14450 | J10: =H10-I10 -> 0
G11: 01 사무관리비 | H11: =M11 -> 10450 | I11: 10450 | J11: =H11-I11 -> 0 | K11: [일반수용비] | M11: =SUM(M12:M15) -> 10450
K12: ○ 후원·기부 유치를 위한 홍보물 제작 : 5,000,000원*1식 | L12: = | M12: 5000
K13: ○ 공식상품화권자 선정 심사수당 : 250,000원*7명*1회 | L13: = | M13: 1750
K14: ○ 공식상품화권자 선정 심사위원 교통비 등 기타실비 : 700,000원*1식 | L14: = | M14: 700
K15: ○ 박람회 인정상품 엠블럼 제작 : 3,000,000원*1식 | L15: = | M15: 3000 | N15: ○ 직원 병가 및 휴직 등 공백발생 시 채용(인건비 23년 기준)
G16: 03 행사운영비 | H16: =M16 -> 4000 | I16: 4000 | J16: =H16-I16 -> 0 | K16: [행사운영비] | M16: =SUM(M17:M17) -> 4000
K17: ○ 후원 협약식 개최 : 800,000원*5회 | L17: = | M17: 4000
D18: 박람회 기부금품 관리 | H18: =SUM(H19) -> 7000 | I18: 7000 | J18: =H18-I18 -> 0
E19: 200 물건비 | H19: =H20 -> 7000 | I19: 7000 | J19: =H19-I19 -> 0
F20: 201 일반운영비 | H20: =H21 -> 7000 | I20: 7000 | J20: =H20-I20 -> 0
G21: 01 사무관리비 | H21: =M21 -> 7000 | I21: 7000 | J21: =H21-I21 -> 0 | K21: [일반수용비] | M21: =SUM(M22:M23) -> 7000
K22: ○ 기부금품 전달식 개최 : 300,000원*10회 | L22: = | M22: 3000
K23: ○ 기부자 예우 물품 제작 : 20,000원*200개 | L23: = | M23: 4000
D24: 박람회 입장권 사업 | H24: =SUM(H25,H30) -> 32400 | I24: 32400 | J24: =H24-I24 -> 0
E25: 200 물건비 | H25: =H26 -> 22400 | I25: 22400 | J25: =H25-I25 -> 0
F26: 201 일반운영비 | H26: =H27 -> 22400 | I26: 22400 | J26: =H26-I26 -> 0
G27: 01 사무관리비 | H27: =M27 -> 22400 | I27: 22400 | J27: =H27-I27 -> 0 | K27: [일반수용비] | M27: =SUM(M28:M29) -> 22400
K28: ○ 입장권 판촉 홍보물 제작 : 20,000,000원*1식 | L28: = | M28: 20000
K29: ○ 입장권 사업 추진 사무용품 구입 : 200,000원*12월 | L29: = | M29: 2400
E30: 300 경상이전 | H30: =H31 -> 10000 | I30: 10000 | J30: =H30-I30 -> 0
F31: 301 일반보상금 | H31: =H32 -> 10000 | I31: 10000 | J31: =H31-I31 -> 0
G32: 14 기타보상금 | H32: =M32 -> 10000 | I32: 10000 | J32: =H32-I32 -> 0 | K32: [기타보상금] | M32: =M33 -> 10000
K33: ○ 입장권 구매보상금 지급 : 10,000,000원*1식 | L33: = | M33: 10000
D34: 박람회 임대사업 | H34: =SUM(H35) -> 27540 | I34: 5000 | J34: =H34-I34 -> 22540
E35: 200 물건비 | H35: =H36 -> 27540 | I35: 5000 | J35: =H35-I35 -> 22540
F36: 201 일반운영비 | H36: =H37 -> 27540 | I36: 5000 | J36: =H36-I36 -> 22540
G37: 01 사무관리비 | H37: =M37 -> 27540 | I37: 5000 | J37: =H37-I37 -> 22540 | K37: [일반수용비] | M37: =M41 -> 27540
K38: 추경1회
K39: ○ 감정평가수수료 2,500,000원*2개소 | L39: = | M39: 5000
K40: 추경2회
...

Sheet 유치협력부
A1: 지출예산(세부사업) - 유치협력부 | M1: 단위 : 천원
A2: 구 분 | B2: 사업 | E2: 편성목 | H2: 예산액 (A) | I2: 기정액(제1회추경) (B) | J2: 비교증감 (A-B) | K2: 산 출 기 초
B3: 정책 | C3: 단위 | D3: 세부 | E3: 그룹 | F3: 목 | G3: 세목
A4: 총계(사업예산 + 자본예산) | H4: =H5 -> 62518 | I4: 62518 | J4: =H4-I4 -> 0
A5: 사업예산 | H5: =H6 -> 62518 | I5: 62518 | J5: =H5-I5 -> 0
B6: 2026여수세계섬박람회 유치협력 | H6: =H7 -> 62518 | I6: 62518 | J6: =H6-I6 -> 0
C7: 유치협력부 부서운영 | H7: =H8 -> 62518 | I7: 62518 | J7: =H7-I7 -> 0
D8: 기본경비 | H8: =H9 -> 62518 | I8: 62518 | J8: =H8-I8 -> 0
E9: 200 물건비 | H9: =SUM(H10,H19,H25,H29) -> 62518 | I9: 62518 | J9: =H9-I9 -> 0
F10: 201 일반운영비 | H10: =SUM(H11,H15,H17) -> 19818 | I10: 19818 | J10: =H10-I10 -> 0
G11: 01 사무관리비 | H11: =M11 -> 5770 | I11: 5770 | J11: =H11-I11 -> 0 | K11: [일반수용비] | M11: =SUM(M12:M14) -> 5770
K12: ○ 부서 운영을 위한 소모품 구입 : 210,000원*12월 | L12: = | M12: 2520
K13: ○ 국내외 유치마케팅 대행사 선정 심사수당 : 250,000원*9명*1회 | L13: = | M13: 2250
K14: ○ 국내외 유치마케팅 대행사 선정 심사위원 교통비 등 기타실비 : 1,000,000원*1식 | L14: = | M14: 1000
G15: 02 공공운영비 | H15: =M15 -> 8000 | I15: 8000 | J15: =H15-I15 -> 0 | K15: [우편료] | M15: =SUM(M16) -> 8000
K16: ○ 국내·외 관람객 홍보물 등 발송 우편료 : 2,500원*3,200개소 | L16: = | M16: 8000
G17: 15 복리후생비 | H17: =M17 -> 6048 | I17: 6048 | J17: =H17-I17 -> 0 | K17: [급량비] | M17: =SUM(M18) -> 6048
K18: ○ 기본업무수행 급량비 : 9,000원*7명*8일*12월 | L18: = | M18: 6048
F19: 202 여비 | H19: =H20+H23 -> 36600 | I19: 36600 | J19: =H19-I19 -> 0
G20: 01 국내여비 | H20: =M20 -> 12600 | I20: 12600 | J20: =H20-I20 -> 0 | K20: [국내여비] | M20: =SUM(M21:M22) -> 12600
K21: ○ 유치협력 기본업무 수행 관내여비 : 20,000원*7명*2일*12월 | L21: = | M21: 3360 | AC21: 9
K22: ○ 유치협력 기본업무 수행 관외여비 : 110,000원*7명*12월 | L22: = | M22: 9240
G23: 03 국외업무여비 | H23: =M23 -> 24000 | I23: 24000 | J23: =H23-I23 -> 0 | K23: [국외업무여비] | M23: =SUM(M24:M25) -> 24000
K24: ○ 자매도시 등 국제교류 및 각종 국제행사 참가 : 3,000,000원*2명*4회 | L24: = | M24: 24000 | AC24: 9
F25: 203 업무추진비 | H25: =H26 -> 4000 | I25: 4000 | J25: =H25-I25 -> 0
G26: 07 사업업무추진비 | H26: =M26 -> 4000 | I26: 4000 | J26: =H26-I26 -> 0 | K26: [사업업무추진비] | M26: =SUM(M27:M28) -> 4000
K27: ○ 유치협력부 업무추진 : 2,000,000원*1식 | L27: = | M27: 2000
K28: ○ 협력관 업무추진 : 2,000,000원*1식 | L28: = | M28: 2000
F29: 217 관서업무비 | H29: =H30 -> 2100 | I29: 2100 | J29: =H29-I29 -> 0
G30: 02 부서업무비 | H30: =M30 -> 2100 | I30: 2100 | J30: =H30-I30 -> 0 | K30: [부서업무비] | M30: =M31 -> 2100
K31: ○ 유치협력부 부서운영 총액계상 : 175,000원*12월 | L31: = | M31: 2100

Sheet 운영부
A1: 지출예산(세부사업) - 운영부 | M1: 단위 : 천원
A2: 구 분 | B2: 사업 | E2: 편성목 | H2: 예산액 (A) | I2: 기정액(제1회추경) (B) | J2: 비교증감 (A-B) | K2: 산 출 기 초
B3: 정책 | C3: 단위 | D3: 세부 | E3: 그룹 | F3: 목 | G3: 세목
A4: 총계(사업예산 + 자본예산) | H4: =H5 -> 360632 | I4: 360632 | J4: =H4-I4 -> 0
A5: 사업예산 | H5: =H6 -> 360632 | I5: 360632 | J5: =H5-I5 -> 0
B6: 2026여수세계섬박람회 운영 | H6: =SUM(H7,H21) -> 360632 | I6: 360632 | J6: =H6-I6 -> 0
C7: 박람회장 운영 | H7: =SUM(H8) -> 308500 | I7: 308500 | J7: =H7-I7 -> 0
D8: 대행사 선정 | H8: =SUM(H9) -> 308500 | I8: 308500 | J8: =H8-I8 -> 0
E9: 200 물건비 | H9: =H10 -> 308500 | I9: 308500 | J9: =H9-I9 -> 0
F10: 201 일반운영비 | H10: =SUM(M11,M14,M17,M19) -> 308500 | I10: 308500 | J10: =H10-I10 -> 0
G11: 01 사무관리비 | H11: =M11+M14 -> 8000 | I11: 8000 | J11: =H11-I11 -> 0 | K11: [일반수용비] | M11: =SUM(M12:M13) -> 2000
K12: 추경1회
K13: ○ 회의실 임차료 : 400,000원*5회 | L13: = | M13: 2000
K14: [운영수당] | M14: =SUM(M15:M16) -> 6000
K15: ○ 대행사 선정 제안서 평가위원 수당 : 250,000원*10명*2회 | L15: = | M15: 5000
K16: ○ 대행사 선정 평가위원 실비 : 500,000원*2회 | L16: = | M16: 1000
G17: 03 행사운영비 | H17: =M17 -> 300000 | I17: 300000 | J17: =H17-I17 -> 0 | K17: [행사운영비] | M17: 300000
K18: ○ 종합실행계획 수립 및 운영대행 용역비(1차분) : 300,000,000원*1식 | L18: = | M18: 300000
G19: 14 회의비 | H19: =M19 -> 500 | I19: 500 | J19: =H19-I19 -> 0 | K19: [회의비] | M19: =M20 -> 500
K20: ○ 대행사 선정 평가위원회 운영비 : 250,000원*2회 | L20: = | M20: 500
C21: 운영부 사무국운영 | H21: =H22 -> 52132 | I21: 52132 | J21: =H21-I21 -> 0
D22: 기본경비 | H22: =H23 -> 52132 | I22: 52132 | J22: =H22-I22 -> 0
E23: 200 물건비 | H23: =SUM(H24,H31,H35,H41) -> 52132 | I23: 52132 | J23: =H23-I23 -> 0
F24: 201 일반운영비 | H24: =SUM(H25,H29) -> 19912 | I24: 19912 | J24: =H24-I24 -> 0
G25: 01 사무관리비 | H25: =M25 -> 13000 | I25: 13000 | J25: =H25-I25 -> 0 | K25: [일반수용비] | M25: =SUM(M26:M28) -> 13000
K26: ○ 사무용품 등 소모품 구입 : 5,000,000원*1식 | L26: = | M26: 5000
K27: ○ 복사기 및 프린터토너 구입 : 3,000,000원*1식 | L27: = | M27: 3000
K28: ○ 사무실 환경정비용품 구입 : 5,000,000원*1식 | L28: = | M28: 5000
G29: 15 복리후생비 | H29: =M30 -> 6912 | I29: 6912 | J29: =H29-I29 -> 0 | K29: [급량비] | M29: =M30 -> 6912
K30: ○ 기본업무수행 급량비 : 9,000원*8명*8일*12월 | L30: = | M30: 6912
F31: 202 여비 | H31: =H32 -> 14400 | I31: 14400 | J31: =H31-I31 -> 0
G32: 01 국내여비 | H32: =M32 -> 14400 | I32: 14400 | J32: =H32-I32 -> 0 | K32: [국내여비] | M32: =SUM(M33:M34) -> 14400
K33: ○ 운영부 기본업무 수행 관내여비 : 20,000원*8명*2일*12월 | L33: = | M33: 3840
K34: ○ 운영부 기본업무 수행 관외여비 : 110,000원*8명*12월 | L34: = | M34: 10560
F35: 203 업무추진비 | H35: =H36 -> 13400 | I35: 13400 | J35: =H35-I35 -> 0
G36: 07 사업업무추진비 | H36: =SUM(M36,M38) -> 13400 | I36: 13400 | J36: =H36-I36 -> 0 | K36: [기관운영업무추진비] | M36: =SUM(M37:M37) -> 6600
K37: ○ 4급보조기관장(운영본부장) : 6,600,000원*1식 | L37: = | M37: 6600
K38: [시책추진업무추진비] | M38: =SUM(M39:M40) -> 6800
K39: ○ 박람회 운영 및 조성 업무추진(4급) : 4,800,000원*1식 | L39: = | M39: 4800
K40: ○ 운영부 업무추진 : 2,000,000원*1식 | L40: = | M40: 2000
...

Sheet 행사부
A1: 지출예산(세부사업) - 행사부 | M1: 단위 : 천원
A2: 구 분 | B2: 사업 | E2: 편성목 | H2: 예산액 (A) | I2: 기정액(제1회추경) (B) | J2: 비교증감 (A-B) | K2: 산 출 기 초
B3: 정책 | C3: 단위 | D3: 세부 | E3: 그룹 | F3: 목 | G3: 세목
A4: 총계(사업예산 + 자본예산) | H4: =H5 -> 25268 | I4: 25268 | J4: =H4-I4 -> 0
A5: 사업예산 | H5: =H6 -> 25268 | I5: 25268 | J5: =H5-I5 -> 0
B6: 2026여수세계섬박람회 행사 | H6: =H7 -> 25268 | I6: 25268 | J6: =H6-I6 -> 0
C7: 행사부 부서운영 | H7: =H8 -> 25268 | I7: 25268 | J7: =H7-I7 -> 0
D8: 기본경비 | H8: =H9 -> 25268 | I8: 25268 | J8: =H8-I8 -> 0
E9: 200 물건비 | H9: =SUM(H10,H15,H19,H22) -> 25268 | I9: 25268 | J9: =H9-I9 -> 0
F10: 201 일반운영비 | H10: =SUM(H11,H13) -> 8568 | I10: 8568 | J10: =H10-I10 -> 0
G11: 01 사무관리비 | H11: =M11 -> 2520 | I11: 2520 | J11: =H11-I11 -> 0 | K11: [일반수용비] | M11: =SUM(M12:M12) -> 2520
K12: ○ 부서운영을 위한 소모품 구입 : 210,000원*12월 | L12: = | M12: 2520
G13: 15 복리후생비 | H13: =M13 -> 6048 | I13: 6048 | J13: =H13-I13 -> 0 | K13: [급량비] | M13: =SUM(M14) -> 6048
K14: ○ 기본업무수행 급량비 : 9,000원*7명*8일*12월 | L14: = | M14: 6048
F15: 202 여비 | H15: =H16 -> 12600 | I15: 12600 | J15: =H15-I15 -> 0
G16: 01 국내여비 | H16: =M16 -> 12600 | I16: 12600 | J16: =H16-I16 -> 0 | K16: [국내여비] | M16: =SUM(M17:M18) -> 12600
K17: ○ 행사부 기본업무 수행 관내여비 : 20,000원*7명*2일*12월 | L17: = | M17: 3360
K18: ○ 행사부 기본업무 수행 관외여비 : 110,000원*7명*12월 | L18: = | M18: 9240
F19: 203 업무추진비 | H19: =H20 -> 2000 | I19: 2000 | J19: =H19-I19 -> 0
G20: 07 사업업무추진비 | H20: =M20 -> 2000 | I20: 2000 | J20: =H20-I20 -> 0 | K20: [사업업무추진비] | M20: =SUM(M21) -> 2000
K21: ○ 행사부 업무추진 : 2,000,000원*1식 | L21: = | M21: 2000
F22: 217 관서업무비 | H22: =H23 -> 2100 | I22: 2100 | J22: =H22-I22 -> 0
G23: 02 부서업무비 | H23: =M23 -> 2100 | I23: 2100 | J23: =H23-I23 -> 0 | K23: [부서업무비] | M23: =M24 -> 2100
K24: ○ 행사부 부서운영 총액계상 : 175,000원*12월 | L24: = | M24: 2100

Sheet 시설조성부
A1: 지출예산(세부사업) - 시설조성부 | M1: 단위 : 천원
A2: 구 분 | B2: 사업 | E2: 편성목 | H2: 예산액 (A) | I2: 기정액(제1회추경) (B) | J2: 비교증감 (A-B) | K2: 산 출 기 초
B3: 정책 | C3: 단위 | D3: 세부 | E3: 그룹 | F3: 목 | G3: 세목
A4: 총계(사업예산 + 자본예산) | H4: =H5+H25 -> 2805268 | I4: 25268 | J4: =H4-I4 -> 2780000
A5: 사업예산 | H5: =H6 -> 25268 | I5: 25268 | J5: =H5-I5 -> 0
B6: 2026여수세계섬박람회 시설조성 | H6: =H7 -> 25268 | I6: 25268 | J6: =H6-I6 -> 0
C7: 시설조성부 부서운영 | H7: =H8 -> 25268 | I7: 25268 | J7: =H7-I7 -> 0
D8: 기본경비 | H8: =H9 -> 25268 | I8: 25268 | J8: =H8-I8 -> 0
E9: 200 물건비 | H9: =SUM(H10,H15,H19,H22) -> 25268 | I9: 25268 | J9: =H9-I9 -> 0
F10: 201 일반운영비 | H10: =SUM(H11,H13) -> 8568 | I10: 8568 | J10: =H10-I10 -> 0
G11: 01 사무관리비 | H11: =M11 -> 2520 | I11: 2520 | J11: =H11-I11 -> 0 | K11: [일반수용비] | M11: =SUM(M12:M12) -> 2520
K12: ○ 부서운영을 위한 소모품 구입 : 210,000원*12월 | L12: = | M12: 2520
G13: 15 복리후생비 | H13: =M13 -> 6048 | I13: 6048 | J13: =H13-I13 -> 0 | K13: [급량비] | M13: =M14 -> 6048
K14: ○ 기본업무수행 급량비 : 9,000원*7명*8일*12월 | L14: = | M14: 6048
F15: 202 여비 | H15: =H16 -> 12600 | I15: 12600 | J15: =H15-I15 -> 0
G16: 01 국내여비 | H16: =M16 -> 12600 | I16: 12600 | J16: =H16-I16 -> 0 | K16: [국내여비] | M16: =SUM(M17:M18) -> 12600
K17: ○ 시설조성부 기본업무 수행 관내여비 : 20,000원*7명*2일*12월 | L17: = | M17: 3360
K18: ○ 시설조성부 기본업무 수행 관외여비 : 110,000원*7명*12월 | L18: = | M18: 9240
F19: 203 업무추진비 | H19: =H20 -> 2000 | I19: 2000 | J19: =H19-I19 -> 0
G20: 07 사업업무추진비 | H20: =M20 -> 2000 | I20: 2000 | J20: =H20-I20 -> 0 | K20: [사업업무추진비] | M20: =SUM(M21) -> 2000
K21: ○ 시설조성부 업무추진 : 2,000,000원*1식 | L21: = | M21: 2000
F22: 217 관서업무비 | H22: =H23 -> 2100 | I22: 2100 | J22: =H22-I22 -> 0
G23: 02 부서업무비 | H23: =M23 -> 2100 | I23: 2100 | J23: =H23-I23 -> 0 | K23: [부서업무비] | M23: =M24 -> 2100
K24: ○ 시설조성부 부서운영 총액계상 : 175,000원*12월 | L24: = | M24: 2100
A25: 자본예산 | H25: =H26 -> 2780000 | I25: 0 | J25: =H25-I25 -> 2780000
B26: 2026여수세계섬박람회 조성연출 | H26: =SUM(H27,H37) -> 2780000 | I26: 0 | J26: =H26-I26 -> 2780000
C27: 박람회 조성 | H27: =SUM(H28) -> 2780000 | I27: 0 | J27: =H27-I27 -> 2780000
D28: 박람회 조성 | H28: =H29 -> 2780000 | I28: 0 | J28: =H28-I28 -> 2780000
E29: 400 자본지출 | H29: =H30 -> 2780000 | I29: 0 | J29: =H29-I29 -> 2780000
F30: 401 시설비 및 부대비 | H30: =SUM(H31,H34) -> 2780000 | I30: 0 | J30: =H30-I30 -> 2780000
G31: 01 시설비 | H31: =M31 -> 2769992 | I31: 0 | J31: =H31-I31 -> 2769992 | K31: [시설비] | M31: =M33 -> 2769992
K32: 추경2회
K33: ○ 2026여수세계섬박람회 주행사장 조성사업 : 2,780,000,000원*99.64/100 | L33: = | M33: 2769992
G34: 03 시설부대비 | H34: =M34 -> 10008 | I34: 0 | J34: =H34-I34 -> 10008 | K34: [시설부대비] | M34: =M36 -> 10008
K35: 추경2회
K36: ○ 2026여수세계섬박람회 주행사장 조성사업 : 2,780,000,000원*0.36/100 | L36: = | M36: 10008

Sheet 전시연출부
A1: 지출예산(세부사업) - 전시연출부 | M1: 단위 : 천원
A2: 구 분 | B2: 사업 | E2: 편성목 | H2: 예산액 (A) | I2: 기정액(제1회추경) (B) | J2: 비교증감 (A-B) | K2: 산 출 기 초
B3: 정책 | C3: 단위 | D3: 세부 | E3: 그룹 | F3: 목 | G3: 세목
A4: 총계(사업예산 + 자본예산) | H4: =H5 -> 34668 | I4: 34668 | J4: =H4-I4 -> 0
A5: 사업예산 | H5: =H6 -> 34668 | I5: 34668 | J5: =H5-I5 -> 0
B6: 2026여수세계섬박람회 전시연출 | H6: =SUM(H7,H18,H28) -> 34668 | I6: 34668 | J6: =H6-I6 -> 0
C7: 2026여수세계섬박람회 전시연출 | H7: =H8 -> 4700 | I7: 4700 | J7: =H7-I7 -> 0
D8: 섬 테마존 조성 업무 추진 | H8: =H9 -> 4700 | I8: 4700 | J8: =H8-I8 -> 0
E9: 200 물건비 | H9: =H10 -> 4700 | I9: 4700 | J9: =H9-I9 -> 0
F10: 201 일반운영비 | H10: =SUM(H11,H15) -> 4700 | I10: 4700 | J10: =H10-I10 -> 0
G11: 01 사무관리비 | H11: =M11 -> 3500 | I11: 3500 | J11: =H11-I11 -> 0 | K11: [운영수당] | M11: =SUM(M13:M14) -> 3500
K12: 추경1회
K13: ○ 제안서 평가위원 심사수당 : 250,000원*10명 | L13: = | M13: 2500
K14: ○ 제안서 평가위원 실비 : 1,000,000원*1식 | L14: = | M14: 1000
H15: =M15 -> 1200 | I15: 1200 | J15: =H15-I15 -> 0 | K15: [임차료] | M15: =SUM(M17) -> 1200
K16: 추경1회
K17: ○ 회의실 임차료 : 400,000원*3회 | L17: = | M17: 1200
D18: 섬박람회 상징 아트포토존 조성 업무 추진 | H18: =H19 -> 4700 | I18: 4700 | J18: =H18-I18 -> 0
E19: 200 물건비 | H19: =H20 -> 4700 | I19: 4700 | J19: =H19-I19 -> 0
F20: 201 일반운영비 | H20: =SUM(H21,H25) -> 4700 | I20: 4700 | J20: =H20-I20 -> 0
G21: 01 사무관리비 | H21: =M21 -> 3500 | I21: 3500 | J21: =H21-I21 -> 0 | K21: [운영수당] | M21: =SUM(M23:M24) -> 3500
K22: 추경1회
K23: ○ 제안서 평가위원 심사수당 : 250,000원*10명 | L23: = | M23: 2500
K24: ○ 제안서 평가위원 실비 : 1,000,000원*1식 | L24: = | M24: 1000
H25: =M25 -> 1200 | I25: 1200 | J25: =H25-I25 -> 0 | K25: [임차료] | M25: =SUM(M27) -> 1200
K26: 추경1회
K27: ○ 회의실 임차료 : 400,000원*3회 | L27: = | M27: 1200
C28: 전시연출부 부서운영 | H28: =H29 -> 25268 | I28: 25268 | J28: =H28-I28 -> 0
D29: 기본경비 | H29: =H30 -> 25268 | I29: 25268 | J29: =H29-I29 -> 0
E30: 200 물건비 | H30: =SUM(H31,H36,H40,H43) -> 25268 | I30: 25268 | J30: =H30-I30 -> 0
F31: 201 일반운영비 | H31: =SUM(H32,H34) -> 8568 | I31: 8568 | J31: =H31-I31 -> 0
G32: 01 사무관리비 | H32: =M32 -> 2520 | I32: 2520 | J32: =H32-I32 -> 0 | K32: [일반수용비] | M32: =SUM(M33:M33) -> 2520
K33: ○ 부서운영을 위한 소모품 구입 : 210,000원*12월 | L33: = | M33: 2520
G34: 15 복리후생비 | H34: =M34 -> 6048 | I34: 6048 | J34: =H34-I34 -> 0 | K34: [급량비] | M34: =SUM(M35) -> 6048
K35: ○ 기본업무수행 급량비 : 9,000원*7명*8일*12월 | L35: = | M35: 6048
F36: 202 여비 | H36: =H37 -> 12600 | I36: 12600 | J36: =H36-I36 -> 0
G37: 01 국내여비 | H37: =M37 -> 12600 | I37: 12600 | J37: =H37-I37 -> 0 | K37: [국내여비] | M37: =SUM(M38:M39) -> 12600
K38: ○ 전시연출부 기본업무 수행 관내여비 : 20,000원*7명*2일*12월 | L38: = | M38: 3360
K39: ○ 전시연출부 기본업무 수행 관외여비 : 110,000원*7명*12월 | L39: = | M39: 9240
F40: 203 업무추진비 | H40: =H41 -> 2000 | I40: 2000 | J40: =H40-I40 -> 0
...

Sheet 예비비
A1: 지출예산(세부사업) - 예비비 | M1: 단위 : 천원
A2: 구 분 | B2: 사업 | E2: 편성목 | H2: 예산액 (A) | I2: 기정액(제1회추경) (B) | J2: 비교증감 (A-B) | K2: 산 출 기 초
B3: 정책 | C3: 단위 | D3: 세부 | E3: 그룹 | F3: 목 | G3: 세목
A4: 총계(사업예산 + 자본예산) | H4: =H5+H17 -> 2692085 | I4: 380240 | J4: =H4-I4 -> 2311845
A5: 사업예산 | H5: =H6 -> 2692085 | I5: 380240 | J5: =H5-I5 -> 2311845
B6: 예비비 | H6: =H7 -> 2692085 | I6: 380240 | J6: =H6-I6 -> 2311845
C7: 예비비 | H7: =H8 -> 2692085 | I7: 380240 | J7: =H7-I7 -> 2311845
D8: 예비비 | H8: =H9 -> 2692085 | I8: 380240 | J8: =H8-I8 -> 2311845
E9: 800 예비비 | H9: =H10 -> 2692085 | I9: 380240 | J9: =H9-I9 -> 2311845
F10: 801 예비비 | H10: =H11 -> 2692085 | I10: 380240 | J10: =H10-I10 -> 2311845
G11: 01 일반예비비 | H11: =M11 -> 2692085 | I11: 380240 | J11: =H11-I11 -> 2311845 | K11: [일반예비비] | M11: =M16 -> 2692085
K12: ○ 예비비 : 316,640,000원*1식 | L12: = | M12: 316640
K13: 추경1회
K14: ○ 예비비 : 경정 380,240,000원 | L14: = | M14: 380240
K15: 추경2회
K16: ○ 예비비 : 경정 2,692,085,000원 | L16: = | M16: 2692085
A17: 자본예산 | H17: =SUM(H18,H31) -> 0 | I17: 0 | J17: =H17-I17 -> 0
B18: 예비비(자본) | H18: =SUM(H19,H59) -> 0 | I18: 0 | J18: =H18-I18 -> 0
C19: 예비비(자본) | H19: =H20 -> 0 | I19: 0 | J19: =H19-I19 -> 0
D20: 예비비(자본) | H20: =H21 -> 0 | I20: 0 | J20: =H20-I20 -> 0
E21: 800 예비비 | H21: =H22 -> 0 | I21: 0 | J21: =H21-I21 -> 0
F22: 801 예비비 | H22: =H23 -> 0 | I22: 0 | J22: =H22-I22 -> 0
G23: 01 일반예비비 | H23: =M23 -> 0 | I23: 0 | J23: =H23-I23 -> 0 | K23: [일반예비비] | M23: =M24 -> 0
K24: ○ 예비비(자본) : 0원 | L24: = | M24: 0

Sheet 지출예산(위탁)
A1: 지출예산(위탁) - 본예산
I2: (단위 : 천 원)
A3: 과 목 | G3: 예산액 (A) | H3: 기정액(제1회추경) (B) | I3: 비교증감 (A-B)
A4: 구분 | B4: 정책사업 | C4: 단위사업 | D4: 세부사업 | E4: 목 | F4: 세목
A5: 총계(사업예산+자본예산) | G5: =G6+G45 -> 22550000 | H5: 22550000 | I5: =G5-H5 -> 0
A6: 사업예산 | G6: =SUM(G7,G18,G32,G40) -> 5450000 | H6: 5450000 | I6: =G6-H6 -> 0
B7: 2026여수세계섬박람회 기획홍보(위탁) | G7: ='기획본부(위탁)'!H6 -> 2000000 | H7: 2000000 | I7: =G7-H7 -> 0
C8: 2026여수세계섬박람회 홍보 | G8: ='기획본부(위탁)'!H7 -> 2000000 | H8: 2000000 | I8: =G8-H8 -> 0
D9: 박람회 홍보 | G9: ='기획본부(위탁)'!H8 -> 2000000 | H9: 2000000 | I9: =G9-H9 -> 0
E10: 일반운영비 | G10: ='기획본부(위탁)'!H10 -> 1945000 | H10: 1974000 | I10: =G10-H10 -> -29000
F11: 사무관리비 | G11: ='기획본부(위탁)'!H11 -> 1379000 | H11: 1419000 | I11: =G11-H11 -> -40000
F12: 공공운영비 | G12: ='기획본부(위탁)'!H22 -> 1000 | H12: 0 | I12: =G12-H12 -> 1000
F13: 행사운영비 | G13: ='기획본부(위탁)'!H25 -> 65000 | H13: 55000 | I13: =G13-H13 -> 10000
F14: 광고선전비 | G14: ='기획본부(위탁)'!H31 -> 500000 | H14: 500000 | I14: =G14-H14 -> 0
E15: 일반보상금 | G15: ='기획본부(위탁)'!H34 -> 55000 | H15: 26000 | I15: =G15-H15 -> 29000
F16: 행사실비보상금 | G16: ='기획본부(위탁)'!H35 -> 5000 | H16: 0 | I16: =G16-H16 -> 5000
F17: 기타보상금 | G17: ='기획본부(위탁)'!H38 -> 50000 | H17: 26000 | I17: =G17-H17 -> 24000
B18: 2026여수세계섬박람회 유치협력(위탁) | G18: =G19 -> 950000 | H18: 950000 | I18: =G18-H18 -> 0
C19: 2026여수세계섬박람회 유치 | G19: ='기획본부(위탁)'!H44 -> 950000 | H19: 950000 | I19: =G19-H19 -> 0
D20: 관람객 유치 | G20: ='기획본부(위탁)'!H45 -> 660000 | H20: 660000 | I20: =G20-H20 -> 0
E21: 일반운영비 | G21: ='기획본부(위탁)'!H47 -> 498000 | H21: 498000 | I21: =G21-H21 -> 0
F22: 사무관리비 | G22: ='기획본부(위탁)'!H48 -> 250000 | H22: 250000 | I22: =G22-H22 -> 0
F23: 행사운영비 | G23: ='기획본부(위탁)'!H58 -> 248000 | H23: 248000 | I23: =G23-H23 -> 0
E24: 일반보상금 | G24: ='기획본부(위탁)'!H63 -> 162000 | H24: 162000 | I24: =G24-H24 -> 0
F25: 외빈초청여비 | G25: ='기획본부(위탁)'!H64 -> 132000 | H25: 132000 | I25: =G25-H25 -> 0
F26: 기타보상금 | G26: ='기획본부(위탁)'!H67 -> 30000 | H26: 30000 | I26: =G26-H26 -> 0
D27: 학술회의 유치 | G27: ='기획본부(위탁)'!H69 -> 290000 | H27: 290000 | I27: =G27-H27 -> 0
E28: 일반운영비 | G28: ='기획본부(위탁)'!H71 -> 173250 | H28: 173250 | I28: =G28-H28 -> 0
F29: 행사운영비 | G29: ='기획본부(위탁)'!H76 -> 170000 | H29: 170000 | I29: =G29-H29 -> 0
E30: 일반보상금 | G30: ='기획본부(위탁)'!H81 -> 116750 | H30: 116750 | I30: =G30-H30 -> 0
F31: 외빈초청여비 | G31: ='기획본부(위탁)'!H82 -> 116750 | H31: 116750 | I31: =G31-H31 -> 0
B32: 2026여수세계섬박람회 행사(위탁) | G32: =G33 -> 1000000 | H32: 1000000 | I32: =G32-H32 -> 0
C33: 2026여수세계섬박람회 행사 | G33: ='운영본부(위탁)'!H7 -> 1000000 | H33: 1000000 | I33: =G33-H33 -> 0
D34: 사전행사 개최 | G34: ='운영본부(위탁)'!H8 -> 400000 | H34: 400000 | I34: =G34-H34 -> 0
E35: 일반운영비 | G35: ='운영본부(위탁)'!H10 -> 400000 | H35: 400000 | I35: =G35-H35 -> 0
F36: 행사운영비 | G36: ='운영본부(위탁)'!H11 -> 400000 | H36: 400000 | I36: =G36-H36 -> 0
D37: 문화행사 추진 | G37: ='운영본부(위탁)'!H14 -> 600000 | H37: 600000 | I37: =G37-H37 -> 0
E38: 일반운영비 | G38: ='운영본부(위탁)'!H16 -> 600000 | H38: 600000 | I38: =G38-H38 -> 0
F39: 행사운영비 | G39: ='운영본부(위탁)'!H17 -> 600000 | H39: 600000 | I39: =G39-H39 -> 0
B40: 2026여수세계섬박람회 전시연출(위탁) | G40: =G41 -> 1500000 | H40: 1500000 | I40: =G40-H40 -> 0
...

Sheet 기획본부(위탁)
A1: 지출예산 - 기획본부(위탁) | M1: 단위 : 천 원
A2: 구 분 | B2: 사업 | E2: 편성목 | H2: 예산액 (A) | I2: 기정액(제1회추경) (B) | J2: 비교증감 (A-B) | K2: 산 출 기 초
B3: 정책 | C3: 단위 | D3: 세부 | E3: 그룹 | F3: 목 | G3: 세목
A4: 총계(사업예산 + 자본예산) | H4: =H5 -> 2950000 | I4: 2950000 | J4: =H4-I4 -> 0
A5: 사업예산 | H5: =H6+H43 -> 2950000 | I5: 2950000 | J5: =H5-I5 -> 0
B6: 2026여수세계섬박람회 기획홍보(위탁) | H6: =H7 -> 2000000 | I6: 2000000 | J6: =H6-I6 -> 0
C7: 2026여수세계섬박람회 홍보 | H7: =H8 -> 2000000 | I7: 2000000 | J7: =H7-I7 -> 0
D8: 박람회 홍보 | H8: =H9+H33 -> 2000000 | I8: 2000000 | J8: =H8-I8 -> 0
E9: 200 물건비 | H9: =H10 -> 1945000 | I9: 1974000 | J9: =H9-I9 -> -29000
F10: 201 일반운영비 | H10: =SUM(H11,H22,H25,H31) -> 1945000 | I10: 1974000 | J10: =H10-I10 -> -29000
G11: 01 사무관리비 | H11: =M11 -> 1379000 | I11: 1419000 | J11: =H11-I11 -> -40000 | K11: [사무관리비] | M11: =SUM(M12:M16,M20:M21) -> 1379000
K12: ○ 홍보물품 등 제작 : 140,000,000원*1식 | L12: = | M12: 140000
K13: ○ 홍보부스 참가 : 5,000,000원*4회 | L13: = | M13: 20000
K14: ○ 제안서, 공모전 평가위원 수당 : 7,000,000원*1식 | L14: = | M14: 7000
K15: ○ 제안서, 공모전 평가위원 교통비 등 기타 실비 : 2,000,000원*1식 | L15: = | M15: 2000
K16: ○ 종합홍보 대행 용역(1차분) : 1,000,000,000원*1식 | L16: = | M16: 1000000
K17: ○ 온라인 홍보 대행 용역 : 150,000,000원*1식 | L17: = | M17: 150000
K18: ○ 홍보영상 제작 용역 : 100,000,000원*1식 | L18: = | M18: 100000
K19: 추경2회
K20: ○ 온라인 홍보 대행 용역 : 경정 140,000,000원 | L20: = | M20: 140000
K21: ○ 홍보영상 제작 용역 : 경정 70,000,000원 | L21: = | M21: 70000
G22: 02 공공운영비 | H22: =M22 -> 1000 | I22: 0 | J22: =H22-I22 -> 1000 | K22: [공공요금 및 제세] | M22: =M24 -> 1000
K23: 추경2회
K24: ○ 서포터즈 보험료 1,000,000원*1식 | L24: = | M24: 1000
G25: 03 행사운영비 | H25: =M25 -> 65000 | I25: 55000 | J25: =H25-I25 -> 10000 | K25: [행사운영비] | M25: =SUM(M26,M28,M30) -> 65000
K26: ○ 사전 홍보 이벤트 : 30,000,000원*1식 | L26: = | M26: 30000
K27: ○ 홍보부스 운영 : 5,000,000원*1식 | L27: = | M27: 5000
K28: ○ 홍보대사, 서포터즈 운영 : 20,000,000원*1식 | L28: = | M28: 20000
K29: 추경2회
K30: ○ 홍보부스 운영 : 경정 15,000,000원 | M30: 15000
G31: 16 광고선전비 | H31: =M31 -> 500000 | I31: 500000 | J31: =H31-I31 -> 0 | K31: [광고료] | M31: =SUM(M32) -> 500000
K32: ○ 섬박람회 광고 홍보료 : 500,000,000원*1식 | L32: = | M32: 500000
E33: 300 경상이전 | H33: =H34 -> 55000 | I33: 26000 | J33: =H33-I33 -> 29000
F34: 301 일반보상금 | H34: =SUM(H35,H38) -> 55000 | I34: 26000 | J34: =H34-I34 -> 29000
G35: 10 행사실비보상금 | H35: =M35 -> 5000 | I35: 0 | J35: =H35-I35 -> 5000 | K35: [행사실비보상금] | M35: =SUM(M36:M37) -> 5000
K36: 추경2회
K37: ○ 홍보대사 및 서포터즈 실비 20,000원*42명*6개월(20천원 절사) | L37: = | M37: 5000
G38: 14 기타보상금 | H38: =M38 -> 50000 | I38: 26000 | J38: =H38-I38 -> 24000 | K38: [기타보상금] | M38: =SUM(M39:M40,M42) -> 50000
K39: ○ 공모전 시상금 : 7,000,000원*3회 | L39: = | M39: 21000
K40: ○ 각종 이벤트 경품 : 5,000,000원*1식 | L40: = | M40: 5000
...

Sheet 운영본부(위탁)
A1: 지출예산 - 운영본부(위탁) | M1: 단위 : 천 원
A2: 구 분 | B2: 사업 | E2: 편성목 | H2: 예산액 (A) | I2: 기정액(본예산) (B) | J2: 비교증감 (A-B) | K2: 산 출 기 초
B3: 정책 | C3: 단위 | D3: 세부 | E3: 그룹 | F3: 목 | G3: 세목
A4: 총계(사업예산 + 자본예산) | H4: =H5+H26 -> 19600000 | I4: 19600000 | J4: =H4-I4 -> 0
A5: 사업예산 | H5: =H6+H19 -> 2500000 | I5: 2500000 | J5: =H5-I5 -> 0
B6: 2026여수세계섬박람회 행사(위탁) | H6: =H7 -> 1000000 | I6: 1000000 | J6: =H6-I6 -> 0
C7: 2026여수세계섬박람회 행사 | H7: =H8+H14 -> 1000000 | I7: 1000000 | J7: =H7-I7 -> 0
D8: 사전행사 개최 | H8: =H9 -> 400000 | I8: 400000 | J8: =H8-I8 -> 0
E9: 200 물건비 | H9: =H10 -> 400000 | I9: 400000 | J9: =H9-I9 -> 0
F10: 201 일반운영비 | H10: =H11 -> 400000 | I10: 400000 | J10: =H10-I10 -> 0
G11: 03 행사운영비 | H11: =M11 -> 400000 | I11: 400000 | J11: =H11-I11 -> 0 | K11: [행사운영비] | M11: =SUM(M12:M13) -> 400000
K12: ○ D-365 기념행사 : 280,000,000원*1식 | L12: = | M12: 280000
K13: ○ '너와 나의 섬이야기' 성공개최 이벤트 : 120,000,000원*1식 | L13: = | M13: 120000
D14: 문화행사 추진 | H14: =H15 -> 600000 | I14: 600000 | J14: =H14-I14 -> 0
E15: 200 물건비 | H15: =H16 -> 600000 | I15: 600000 | J15: =H15-I15 -> 0
F16: 201 일반운영비 | H16: =H17 -> 600000 | I16: 600000 | J16: =H16-I16 -> 0
G17: 03 행사운영비 | H17: =M17 -> 600000 | I17: 600000 | J17: =H17-I17 -> 0 | K17: [행사운영비] | M17: =M18 -> 600000
K18: ○ 섬박람회 문화행사 기획 및 프로그램 개발 : 600,000,000원*1식 | L18: = | M18: 600000
B19: 2026여수세계섬박람회 전시연출(위탁) | H19: =H20 -> 1500000 | I19: 1500000 | J19: =H19-I19 -> 0
C20: 2026여수세계섬박람회 전시연출 | H20: =H21 -> 1500000 | I20: 1500000 | J20: =H20-I20 -> 0
D21: 박람회 연출 | H21: =H22 -> 1500000 | I21: 1500000 | J21: =H21-I21 -> 0
E22: 200 물건비 | H22: =H23 -> 1500000 | I22: 1500000 | J22: =H22-I22 -> 0
F23: 201 일반운영비 | H23: =H24 -> 1500000 | I23: 1500000 | J23: =H23-I23 -> 0
G24: 03 행사운영비 | H24: =M24 -> 1500000 | I24: 1500000 | J24: =H24-I24 -> 0 | K24: [행사운영비] | M24: =SUM(M25:M25) -> 1500000
K25: ○ 전시연출 콘텐츠 개발 : 1,500,000,000원*1식 | L25: = | M25: 1500000
A26: 자본예산 | H26: =H27+H71 -> 17100000 | I26: 17100000 | J26: =H26-I26 -> 0
B27: 2026여수세계섬박람회 시설조성(위탁) | H27: =H28 -> 10300000 | I27: 10300000 | J27: =H27-I27 -> 0
C28: 2026여수세계섬박람회 시설조성 | H28: =SUM(H29,H43,H57,H64) -> 10300000 | I28: 10300000 | J28: =H28-I28 -> 0
D29: 섬박람회 랜드마크 조성사업 | H29: =H30 -> 5000000 | I29: 5000000 | J29: =H29-I29 -> 0
E30: 400 자본지출 | H30: =H31 -> 5000000 | I30: 5000000 | J30: =H30-I30 -> 0
F31: 401 시설비및부대비 | H31: =SUM(H32,H36,H39) -> 5000000 | I31: 5000000 | J31: =H31-I31 -> 0
G32: 01 시설비 | H32: =M32 -> 4737175 | I32: 4986500 | J32: =H32-I32 -> -249325 | K32: [시설비] | M32: =M35 -> 4737175
K33: ○ 섬박람회 랜드마크 조성 시설비 : 5,000,000,000원*1식*99.73/100 | L33: = | M33: 4986500
K34: 추경2회
K35: ○ 섬박람회 랜드마크 조성 시설비 경정 4,737,175,000원 | L35: = | M35: 4737175
G36: 02 감리비 | H36: =M36 -> 250000 | I36: 0 | J36: =H36-I36 -> 250000 | K36: [감리비] | M36: =M38 -> 250000
K37: 추경2회
K38: ○ 섬박람회 랜드마크 조성 감리비 5,000,000,000원*1식*5/100 | L38: = | M38: 250000
G39: 03 시설부대비 | H39: =M39 -> 12825 | I39: 13500 | J39: =H39-I39 -> -675 | K39: [시설부대비] | M39: =M42 -> 12825
K40: ○ 섬박람회 랜드마크 조성 시설부대비 : 5,000,000,000원*1식*0.27/100 | L40: = | M40: 13500
...
