Workbook
Name ㄹㄹㄹ: #REF!
Name ㄹㄹㄹ: #REF!
Name ㄹㄹㄹ: #REF!
Name ㄹㄹㄹ: #REF!
Name ㄹㄹㄹ: #REF!
Name ㅁ1: #REF!
Name ㅁ1: #REF!
Name ㅁ1: #REF!
Name ㅁ1: #REF!
Name ㅁ1: #REF!
Name ㅁ1: #REF!
Name ㅇㅇ: #REF!
Name ㅇㅇ: #REF!
Name ㅇㅇ: #REF!
Name ㅇㅇㅇ: #REF!
Name ㅇㅇㅇ: #REF!
Name ㅇㅇㅇ: #REF!

Sheet 표지
A13: 섬박람회 조직위원회 2026년 본예산서
D22: (재)2026여수세계섬박람회 조직위

Sheet 수입예산 총괄표
A1: 수입예산 총괄표(출연금+위탁사업비)
H2: (단위 : 천 원)
A3: 과 목 | F3: 예산액 (A) | G3: 전년도본예산액 (B) | H3: 비교증감
A4: 구분 | B4: 관 | C4: 항 | D4: 세항 | E4: 목
A5: 총계(사업예산+자본예산) | F5: =F6 -> 30150147 | G5: 24529000 | H5: =F5-G5 -> 5621147
A6: 자체수입금 | F6: =SUM(F7,F26) -> 30150147 | G6: 24529000 | H6: =F6-G6 -> 5621147
B7: 600 사업수익 | F7: =SUM(F8,F23) -> 24012100 | G7: 24529000 | H7: =F7-G7 -> -516900
C8: 610 영업수익 | F8: =SUM(F9,F11,F13,F15,F17,F19,F21) -> 24012100 | G8: 24511000 | H8: =F8-G8 -> -498900
D9: 621 상품등판매수익 | F9: =F10 -> 120000 | G9: 0 | H9: =F9-G9 -> 120000
E10: 01 상품판매수익 | F10: 120000 | G10: 0 | H10: =F10-G10 -> 120000
D11: 623 대행사업수익 | F11: =F12 -> 14320000 | G11: 22550000 | H11: =F11-G11 -> -8230000
E12: 01 직접관리비수익 | F12: =1000000+3380000+600000+270000+5500000+1200000+300000+90000+390000+1200000+390000 -> 14320000 | G12: 22550000 | H12: =F12-G12 -> -8230000
D13: 624 입장료수익 | F13: =F14 -> 6600000 | G13: 0 | H13: =F13-G13 -> 6600000
E14: 01 입장료수익 | F14: 6600000 | G14: 0 | H14: =F14-G14 -> 6600000
D15: 647 기부금수익 | F15: =F16 -> 689000 | G15: 0 | H15: =F15-G15 -> 689000
E16: 01 기부금수익 | F16: 689000 | G16: 0 | H16: =F16-G16 -> 689000
D17: 648 출연금 수익 | F17: =F18 -> 1245100 | G17: 1861000 | H17: =F17-G17 -> -615900
E18: 02 자치단체출연금수익 | F18: 1245100 | G18: 1861000 | H18: =F18-G18 -> -615900
D19: 649 후원금 수익 | F19: =F20 -> 410000 | G19: 100000 | H19: =F19-G19 -> 310000
E20: 01 지정후원금수익 | F20: 410000 | G20: 100000 | H20: =F20-G20 -> 310000
D21: 661 기타영업수익 | F21: =F22 -> 628000 | G21: 0 | H21: =F21-G21 -> 628000
E22: 05 부대시설임대수익 | F22: 628000 | G22: 0 | H22: =F22-G22 -> 628000
C23: 670 영업외수익 | F23: =F24 -> 0 | G23: 18000 | H23: =F23-G23 -> -18000
D24: 671 이자수익 | F24: =F25 -> 0 | G24: 18000 | H24: =F24-G24 -> -18000
E25: 01 예금이자수익 | F25: 0 | G25: 18000 | H25: =F25-G25 -> -18000
B26: 100 자본적수입 | F26: =F27+F30 -> 6138047 | G26: 0 | H26: =F26-G26 -> 6138047
C27: 170 자본잉여금수입 | F27: =F28 -> 3233000 | G27: 0 | H27: =F27-G27 -> 3233000
D28: 177 출연금 수입 | F28: =F29 -> 3233000 | G28: 0 | H28: =F28-G28 -> 3233000
E29: 01 정부출연금 | F29: 3233000 | G29: 0 | H29: =F29-G29 -> 3233000
C30: 180 유보자금 | F30: =F31 -> 2905047 | G30: 0 | H30: =F30-G30 -> 2905047
D31: 181 순세계잉여금 | F31: =F32+F33 -> 2905047 | G31: 0 | H31: =F31-G31 -> 2905047
E32: 01 순세계잉여금 | F32: 2905047 | G32: 0 | H32: =F32-G32 -> 2905047
E33: 03 대행사업비 사용잔액 | F33: 0 | G33: 0 | H33: =F33-G33 -> 0

Sheet 지출예산 총괄표
A1: 지출예산 총괄표(출연금+위탁사업비)
I2: (단위 : 천 원)
A3: 과 목 | G3: 예산액 (A) | H3: 전년도본예산액 (B) | I3: 비교증감
A4: 구분 | B4: 정책사업
A5: 총계(출연금+위탁사업비) | G5: =G6+G23 -> 30150147 | H5: 24529000 | I5: =G5-H5 -> 5621147
A6: 직접사업비(사업예산+자본예산) | G6: =SUM(G7,G18) -> 15830147 | H6: 1979000 | I6: =G6-H6 -> 13851147
A7: 사업예산 | G7: =SUM(G8:G17) -> 9597147 | H7: 1979000 | I7: =G7-H7 -> 7618147
B8: 2026여수세계섬박람회 행정관리 | G8: =행정관리부!H5 -> 974983 | H8: 927348 | I8: =G8-H8 -> 47635
B9: 2026여수세계섬박람회 기획홍보 | G9: =기획홍보부!H5 -> 170012 | H9: 151892 | I9: =G9-H9 -> 18120
B10: 2026여수세계섬박람회 수익사업 | G10: =수익사업부!H5 -> 197636 | H10: 86166 | I10: =G10-H10 -> 111470
B11: 2026여수세계섬박람회 유치협력 | G11: =유치협력부!H5 -> 47440 | H11: 62518 | I11: =G11-H11 -> -15078
B12: 2026여수세계섬박람회 운영 | G12: =운영부!H5 -> 3686944 | H12: 358632 | I12: =G12-H12 -> 3328312
B13: 2026여수세계섬박람회 행사 | G13: =행사부!H5 -> 20648 | H13: 25268 | I13: =G13-H13 -> -4620
B14: 2026여수세계섬박람회 시설조성 | G14: =시설조성부!H5 -> 1765648 | H14: 25268 | I14: =G14-H14 -> 1740380
B15: 2026여수세계섬박람회 전시연출 | G15: =전시연출부!H5 -> 2121344 | H15: 25268 | I15: =G15-H15 -> 2096076
B16: 2026여수세계섬박람회 종합상황실 | G16: =종합상황실!H5 -> 16292 | H16: 0 | I16: =G16-H16 -> 16292
B17: 예비비 | G17: =예비비!H5 -> 596200 | H17: 316640 | I17: =G17-H17 -> 279560
A18: 자본예산 | G18: =시설조성부!H31 -> 6233000 | H18: 0 | I18: =G18-H18 -> 6233000
B19: 2026여수세계섬박람회 조성연출 | G19: =시설조성부!H32 -> 3233000 | H19: 0 | I19: =G19-H19 -> 3233000
B20: 섬박람회 랜드마크 조성사업(수익) | G20: =시설조성부!H39 -> 1000000 | H20: 0 | I20: =G20-H20 -> 1000000
B21: 섬박람회 안전시설물 설치사업(수익) | G21: =시설조성부!H46 -> 2000000 | H21: 0 | I21: =G21-H21 -> 2000000
B22: 예비비(자본) | G22: =예비비!H13 -> 0 | H22: 0 | I22: =G22-H22 -> 0
A23: 위탁사업비(사업예산+자본예산) | G23: =G24+G28 -> 14320000 | H23: 22550000 | I23: =G23-H23 -> -8230000
A24: 사업예산 | G24: =SUM(G25:G27) -> 10750000 | H24: 5450000 | I24: =G24-H24 -> 5300000
B25: 2026여수세계섬박람회 기획홍보(위탁) | G25: ='기획본부(위탁)'!H6 -> 1000000 | H25: 2000000 | I25: =G25-H25 -> -1000000
B26: 2026여수세계섬박람회 유치협력(위탁) | G26: ='기획본부(위탁)'!H30 -> 4250000 | H26: 950000 | I26: =G26-H26 -> 3300000
B27: 2026여수세계섬박람회 행사(위탁) | G27: ='운영본부(위탁)'!H6 -> 5500000 | H27: 1000000 | I27: =G27-H27 -> 4500000
A28: 자본예산 | G28: =SUM(G29:G30) -> 3570000 | H28: 17100000 | I28: =G28-H28 -> -13530000
B29: 2026여수세계섬박람회 시설조성(위탁) | G29: ='운영본부(위탁)'!H14 -> 1980000 | H29: 10300000 | I29: =G29-H29 -> -8320000
B30: 2026여수세계섬박람회 전시연출(위탁) | G30: ='운영본부(위탁)'!H36 -> 1590000 | H30: 6800000 | I30: =G30-H30 -> -5210000

Sheet 지출예산(직접)
A1: 지출예산 총괄표
I2: (단위 : 천 원)
A3: 과 목 | G3: 예산액 (A) | H3: 전년도본예산액 (B) | I3: 비교증감 (A-B)
A4: 구분 | B4: 정책사업 | C4: 단위사업 | D4: 세부사업 | E4: 목 | F4: 세목
A5: 총계 | G5: =G6+G209 -> 15830147 | H5: =SUM(H6,H209) -> 1979000 | I5: =G5-H5 -> 13851147
A6: 사업예산 | G6: =SUM(G7,G39,G77,G104,G123,G142,G154,G170,G192,G204) -> 9597147 | H6: 1979000 | I6: =G6-H6 -> 7618147
B7: 2026여수세계섬박람회 행정관리 | G7: =SUM(G8,G13) -> 974983 | H7: 927348 | I7: =G7-H7 -> 47635
C8: 2026여수세계섬박람회 행정 업무추진 | G8: =SUM(,G9) -> 26100 | H8: 80420 | I8: =G8-H8 -> -54320
D9: 이사회 및 각종 위원회 운영 | G9: =G10 -> 26100 | H9: 47460 | I9: =G9-H9 -> -21360
E10: 일반운영비 | G10: =행정관리부!H10 -> 26100 | H10: 47460 | I10: =G10-H10 -> -21360
F11: 사무관리비 | G11: =행정관리부!H11 -> 24900 | H11: 45060 | I11: =G11-H11 -> -20160
F12: 회의비 | G12: =행정관리부!H19 -> 1200 | H12: 2400 | I12: =G12-H12 -> -1200
C13: 사무국운영 | G13: =G14 -> 948883 | H13: 846928 | I13: =G13-H13 -> 101955
D14: 기본경비 | G14: =SUM(G15,G19,G21,G25,G27,G29,G32,G34,G37) -> 948883 | H14: 846928 | I14: =G14-H14 -> 101955
E15: 인건비 | G15: =행정관리부!H24 -> 651710 | H15: 609331 | I15: =G15-H15 -> 42379
F16: 보수 | G16: =행정관리부!H25 -> 402600 | H16: 392400 | I16: =G16-H16 -> 10200
F17: 기타직보수 | G17: =행정관리부!H30 -> 219281 | H17: 186102 | I17: =G17-H17 -> 33179
F18: 기간제근로자등보수 | G18: =행정관리부!H36 -> 29829 | H18: 30829 | I18: =G18-H18 -> -1000
E19: 퇴직급여 | G19: =행정관리부!H40 -> 52200 | H19: 10500 | I19: =G19-H19 -> 41700
F20: 퇴직급여충당금 | G20: =행정관리부!H41 -> 52200 | H20: 10500 | I20: =G20-H20 -> 41700
E21: 일반운영비 | G21: =행정관리부!H46 -> 137760 | H21: 115440 | I21: =G21-H21 -> 22320
F22: 사무관리비 | G22: =행정관리부!H47 -> 82220 | H22: 72560 | I22: =G22-H22 -> 9660
F23: 공공운영비 | G23: =행정관리부!H62 -> 35460 | H23: 21760 | I23: =G23-H23 -> 13700
F24: 복리후생비 | G24: =행정관리부!H69 -> 20080 | H24: 21120 | I24: =G24-H24 -> -1040
E25: 여비 | G25: =행정관리부!H75 -> 11990 | H25: 18000 | I25: =G25-H25 -> -6010
F26: 국내여비 | G26: =행정관리부!H76 -> 11990 | H26: 18000 | I26: =G26-H26 -> -6010
E27: 업무추진비 | G27: =행정관리부!H79 -> 36600 | H27: 38400 | I27: =G27-H27 -> -1800
F28: 사업업무추진비 | G28: =행정관리부!H80 -> 36600 | H28: 38400 | I28: =G28-H28 -> -1800
E29: 직무수행경비 | G29: =행정관리부!H87 -> 27120 | H29: 25920 | I29: =G29-H29 -> 1200
F30: 직급보조비 | G30: =행정관리부!H88 -> 20400 | H30: 19200 | I30: =G30-H30 -> 1200
F31: 특정업무경비 | G31: =행정관리부!H91 -> 6720 | H31: 6720 | I31: =G31-H31 -> 0
E32: 수선유지교체비 | G32: =행정관리부!H93 -> 8000 | H32: 5000 | I32: =G32-H32 -> 3000
F33: 수선유지비 | G33: =행정관리부!H94 -> 8000 | H33: 5000 | I33: =G33-H33 -> 3000
E34: 관서업무비 | G34: =행정관리부!H96 -> 5140 | H34: 4740 | I34: =G34-H34 -> 400
F35: 정원가산업무비 | G35: =행정관리부!H97 -> 3040 | H35: 2640 | I35: =G35-H35 -> 400
F36: 부서업무비 | G36: =행정관리부!H99 -> 2100 | H36: 2100 | I36: =G36-H36 -> 0
E37: 연금부담금 등 | G37: =행정관리부!H102 -> 18363 | H37: 19597 | I37: =G37-H37 -> -1234
F38: 연금부담금 | G38: =행정관리부!H103 -> 18363 | H38: 19597 | I38: =G38-H38 -> -1234
B39: 2026여수세계섬박람회 기획홍보 | G39: =SUM(G40,G48,G55,G66) -> 170012 | H39: 151892 | I39: =G39-H39 -> 18120
C40: 2026여수세계섬박람회 기획 | G40: =기획홍보부!H7 -> 20200 | H40: 28600 | I40: =G40-H40 -> -8400
...

Sheet 행정관리부
A1: 지출예산(세부사업) - 행정관리부 | M1: 단위 : 천원
A2: 구 분 | B2: 사업 | E2: 편성목 | H2: 예산액 (A) | I2: 전년도본예산액 (B) | J2: 비교증감 (A-B) | K2: 산 출 기 초
B3: 정책 | C3: 단위 | D3: 세부 | E3: 그룹 | F3: 목 | G3: 세목
A4: 총계(사업예산 + 자본예산) | H4: =H5 -> 974983 | I4: 927348 | J4: =H4-I4 -> 47635
A5: 사업예산 | H5: =H6 -> 974983 | I5: 927348 | J5: =H5-I5 -> 47635
B6: 2026여수세계섬박람회 행정관리 | H6: =SUM(H7,H21) -> 974983 | I6: 927348 | J6: =H6-I6 -> 47635
C7: 2026여수세계섬박람회 행정 업무추진 | H7: =H8 -> 26100 | I7: 80420 | J7: =H7-I7 -> -54320
D8: 이사회 및 각종 위원회 운영 | H8: =H9 -> 26100 | I8: 47460 | J8: =H8-I8 -> -21360
E9: 200 물건비 | H9: =H10 -> 26100 | I9: 47460 | J9: =H9-I9 -> -21360
F10: 201 일반운영비 | H10: =SUM(H11,H19) -> 26100 | I10: 47460 | J10: =H10-I10 -> -21360
G11: 01 사무관리비 | H11: =SUM(M11,M13,M17) -> 24900 | I11: 45060 | J11: =H11-I11 -> -20160 | K11: [일반수용비] | M11: =SUM(M12:M12) -> 800
K12: ○ 변경등기 수수료 : 200,000원*4회 | L12: = | M12: 800
K13: [운영수당] | M13: =SUM(M14:M16) -> 21300
K14: ○ 이사회 참석수당 : 150,000원*12명*7회 | L14: = | M14: 12600
K15: ○ 이사회 참석자 실비보상 : 100,000원*12명*7회 | L15: = | M15: 8400
K16: ○ 인사위원회 위원 참석수당 : 100,000원*3명*1회 | L16: = | M16: 300
K17: [임차료] | M17: =M18 -> 2800
K18: ○ 회의실 임차료 : 400,000원*7회 | L18: = | M18: 2800
G19: 14 회의비 | H19: =M19 -> 1200 | I19: 2400 | J19: =H19-I19 -> -1200 | K19: [회의비] | M19: =M20 -> 1200
K20: ○ 이사회 등 회의 운영비 : 400,000원*3회 | L20: = | M20: 1200
C21: 사무국운영 | H21: =H22 -> 948883 | I21: 846928 | J21: =H21-I21 -> 101955
D22: 기본경비 | H22: =SUM(H23,H45,H101) -> 948883 | I22: 846928 | J22: =H22-I22 -> 101955
E23: 100 인건비 | H23: =SUM(H24,H40) -> 703910 | I23: 619831 | J23: =H23-I23 -> 84079
F24: 101 인건비 | H24: =SUM(H25,H30,H36) -> 651710 | I24: 609331 | J24: =H24-I24 -> 42379
G25: 01 보수 | H25: =SUM(M25,M28) -> 402600 | I25: 392400 | J25: =H25-I25 -> 10200 | K25: [직원파견수당] | M25: =SUM(M26:M27) -> 303600
K26: ○ 4급이상 : 600,000원*2명*11월 | L26: = | M26: 13200
K27: ○ 5급이하 : 400,000원*66명*11월 | L27: = | M27: 290400
K28: [주거지원비] | M28: =M29 -> 99000
K29: ○ 타시군(도) 주거지원비 : 500,000원*18명*11월 | L29: = | M29: 99000
G30: 02 기타직 보수 | H30: =SUM(M30,M33) -> 219281 | I30: 186102 | J30: =H30-I30 -> 33179 | K30: [사무총장] | M30: =SUM(M31:M32) -> 97281
K31: ○ 연봉 : 8,468,460원*11월 | L31: = | M31: 93154
K32: ○ 연차수당 : 8,468,460원*86%*1/30*17일 | L32: = | M32: 4127
K33: [총감독 급여] | M33: =SUM(M34:M35) -> 122000
K34: ○ 비상임 급여 : 7,000,000원*2월 | L34: = | M34: 14000
K35: ○ 월급여 : 12,000,000원*9월 | L35: = | M35: 108000
G36: 04 기간제근로자등보수 | H36: =M36 -> 29829 | I36: 30829 | J36: =H36-I36 -> -1000 | K36: [본부장실 관리요원] | M36: =SUM(M37:M39) -> 29829
K37: ○ 인부임 : 98,440원*1명*22일*11월 | L37: = | M37: 23823
K38: ○ 주휴수당 : 98,440원*1명*4일*11월 | L38: = | M38: 4332
K39: ○ 연차수당 : 98,440원*1명*17일 | L39: = | M39: 1674
F40: 107 퇴직급여 | H40: =SUM(H41,H48) -> 52200 | I40: 10500 | J40: =H40-I40 -> 41700
...

Sheet 기획홍보부
A1: 지출예산(세부사업) - 기획홍보부 | M1: 단위 : 천원
A2: 구 분 | B2: 사업 | E2: 편성목 | H2: 예산액 (A) | I2: 전년도본예산액 (B) | J2: 비교증감 (A-B) | K2: 산 출 기 초
B3: 정책 | C3: 단위 | D3: 세부 | E3: 그룹 | F3: 목 | G3: 세목
A4: 총계(사업예산 + 자본예산) | H4: =H5 -> 170012 | I4: 151892 | J4: =H4-I4 -> 18120
A5: 사업예산 | H5: =H6 -> 170012 | I5: 151892 | J5: =H5-I5 -> 18120
B6: 2026여수세계섬박람회 기획홍보 | H6: =SUM(H7,H22,H33,H51) -> 170012 | I6: 151892 | J6: =H6-I6 -> 18120
C7: 2026여수세계섬박람회 기획 | H7: =H8+H13 -> 20200 | I7: 28600 | J7: =H7-I7 -> -8400
D8: 박람회 기획 | H8: =SUM(H9) -> 5000 | I8: 0 | J8: =H8-I8 -> 5000
E9: 200 물건비 | H9: =SUM(H10) -> 5000 | I9: 0 | J9: =H9-I9 -> 5000
F10: 201 일반운영비 | H10: =H11 -> 5000 | I10: 0 | J10: =H10-I10 -> 5000
G11: 01 사무관리비 | H11: =M11 -> 5000 | I11: 0 | J11: =H11-I11 -> 5000 | K11: [일반수용비] | M11: =SUM(M12) -> 5000
K12: ○ 추진상황 보고 PPT 제작 2,500,000원*2회 | L12: = | M12: 5000
D13: 자문위원회 운영 | H13: =H14 -> 15200 | I13: 28600 | J13: =H13-I13 -> -13400
E14: 200 물건비 | H14: =SUM(H15) -> 15200 | I14: 28600 | J14: =H14-I14 -> -13400
F15: 201 일반운영비 | H15: =SUM(H16,H20) -> 15200 | I15: 28600 | J15: =H15-I15 -> -13400
G16: 01 사무관리비 | H16: =M16 -> 15000 | I16: 28000 | J16: =H16-I16 -> -13000 | K16: [운영수당] | M16: =SUM(M17:M19) -> 15000
K17: ○ 자문위원회 자문수당(대면) : 150,000원*2회*25명 | L17: = | M17: 7500
K18: ○ 자문위원회 자문수당(서면) : 100,000원*2회*25명 | L18: = | M18: 5000
K19: ○ 자문위원회 참석자 실비 보상 : 2,500,000원*1식 | L19: = | M19: 2500
G20: 14 회의비 | H20: =M20 -> 200 | I20: 300 | J20: =H20-I20 -> -100 | K20: [회의비] | M20: =M21 -> 200
K21: ○ 자문위원회 회의 운영비 : 100,000원*2회 | L21: = | M21: 200
C22: 2026여수세계섬박람회 홍보 | H22: =SUM(H23,H28) -> 53300 | I22: 50000 | J22: =H22-I22 -> 3300
D23: 홈페이지 유지관리 | H23: =H24 -> 50000 | I23: 50000 | J23: =H23-I23 -> 0
E24: 200 물건비 | H24: =H25 -> 50000 | I24: 50000 | J24: =H24-I24 -> 0
F25: 214 수선유지교체비 | H25: =H26 -> 50000 | I25: 50000 | J25: =H25-I25 -> 0
G26: 05 수선유지비 | H26: =M26 -> 50000 | I26: 50000 | J26: =H26-I26 -> 0 | K26: [수선유지비] | M26: =SUM(M27:M27) -> 50000
K27: ○ 누리집 유지관리 용역 : 50,000,000원*1식 | L27: = | M27: 50000
D28: 박람회 홍보 | H28: =H29 -> 3300 | I28: 0 | J28: =H28-I28 -> 3300
E29: 200 물건비 | H29: =H30 -> 3300 | I29: 0 | J29: =H29-I29 -> 3300
F30: 202 여비 | H30: =H31 -> 3300 | I30: 0 | J30: =H30-I30 -> 3300
G31: 01 국내여비 | H31: =M31 -> 3300 | I31: 0 | J31: =H31-I31 -> 3300 | K31: [국내여비] | M31: =SUM(M32:M32) -> 3300
K32: ○ 박람회 홍보 관외여비 110,000원*2명*3일*5월 | L32: = | M32: 3300
C33: 기획홍보부 부서운영 | H33: =H34 -> 21512 | I33: 28292 | J33: =H33-I33 -> -6780
D34: 기본경비 | H34: =H35 -> 21512 | I34: 28292 | J34: =H34-I34 -> -6780
E35: 200 물건비 | H35: =SUM(H36,H41,H45,H48) -> 21512 | I35: 28292 | J35: =H35-I35 -> -6780
F36: 201 일반운영비 | H36: =H37+H39 -> 8912 | I36: 9792 | J36: =H36-I36 -> -880
G37: 01 사무관리비 | H37: =M37 -> 2000 | I37: 2880 | J37: =H37-I37 -> -880 | K37: [일반수용비] | M37: =SUM(M38:M38) -> 2000
K38: ○ 부서 운영을 위한 소모품 구입 : 200,000원*10월 | L38: = | M38: 2000
G39: 15 복리후생비 | H39: =M39 -> 6912 | I39: 6912 | J39: =H39-I39 -> 0 | K39: [급량비] | M39: =SUM(M40:M40) -> 6912
K40: ○ 기본업무수행 급량비 : 9,000원*8명*8일*12월 | L40: = | M40: 6912
...

Sheet 수익사업부
A1: 지출예산(세부사업) - 수익사업부 | M1: 단위 : 천원
A2: 구 분 | B2: 사업 | E2: 편성목 | H2: 예산액 (A) | I2: 전년도본예산액 (B) | J2: 비교증감 (A-B) | K2: 산 출 기 초
B3: 정책 | C3: 단위 | D3: 세부 | E3: 그룹 | F3: 목 | G3: 세목
A4: 총계(사업예산 + 자본예산) | H4: =H5 -> 197636 | I4: 86166 | J4: =H4-I4 -> 111470
A5: 사업예산 | H5: =H6 -> 197636 | I5: 86166 | J5: =H5-I5 -> 111470
B6: 2026여수세계섬박람회 수익사업 | H6: =SUM(H7,H37) -> 197636 | I6: 86166 | J6: =H6-I6 -> 111470
C7: 2026여수세계섬박람회 수익사업 | H7: =SUM(H8,,H18,H32) -> 174760 | I7: 53850 | J7: =H7-I7 -> 120910
D8: 박람회 휘장업무 추진 | H8: =H9 -> 11300 | I8: 14450 | J8: =H8-I8 -> -3150
E9: 200 물건비 | H9: =H10 -> 11300 | I9: 14450 | J9: =H9-I9 -> -3150
F10: 201 일반운영비 | H10: =H11 -> 11300 | I10: 14450 | J10: =H10-I10 -> -3150
G11: 01 사무관리비 | H11: =SUM(M11,M15) -> 11300 | I11: 10450 | J11: =H11-I11 -> 850 | K11: [일반수용비] | M11: =SUM(M12:M14) -> 8100
K12: ○ 후원 유치를 위한 홍보물 등 제작 : 4,000,000원*1식 | L12: = | M12: 4000
K13: ○ 휘장업무 추진 사무용품 등 구입 : 110,000원*10월 | L13: = | M13: 1100 | N13: ○ 직원 병가 및 휴직 등 공백발생 시 채용(인건비 23년 기준)
K14: ○ 후원 관련 협약식 등 소모품 구입 : 500,000원*6회 | L14: = | M14: 3000
K15: [운영수당] | M15: =SUM(M16:M17) -> 3200
K16: ○ 공식공급권자 선정 심사수당 : 250,000원*10명*1회 | L16: = | M16: 2500
K17: ○ 공식공급권자 선정 심사위원 교통비 등 기타실비 : 700,000원*1식 | L17: = | M17: 700
D18: 박람회 입장권 사업 | H18: =SUM(H19,H28) -> 63460 | I18: 32400 | J18: =H18-I18 -> 31060
E19: 200 물건비 | H19: =SUM(H20,H25) -> 23460 | I19: 22400 | J19: =H19-I19 -> 1060
F20: 201 일반운영비 | H20: =H21 -> 20160 | I20: 22400 | J20: =H20-I20 -> -2240
G21: 01 사무관리비 | H21: =M21 -> 20160 | I21: 22400 | J21: =H21-I21 -> -2240 | K21: [일반수용비] | M21: =SUM(M22:M24) -> 20160
K22: ○ 입장권 판촉 홍보물 제작 : 15,000,000원*1식 | L22: = | M22: 15000
K23: ○ 입장권 제휴 할인 홍보물 제작 : 3,000,000원*1식 | L23: = | M23: 3000
K24: ○ 입장권 사업 추진 사무용품 구입 : 216,000원*10월 | L24: = | M24: 2160
F25: 202 여비 | H25: =H26 -> 3300 | I25: 0 | J25: =H25-I25 -> 3300
G26: 01 국내여비 | H26: =M26 -> 3300 | I26: 0 | J26: =H26-I26 -> 3300 | K26: [국내여비] | M26: =SUM(M27:M28) -> 3300
K27: ○ 입장권 판촉활동 등 관외여비 : 110,000원*2명*3일*5월 | L27: = | M27: 3300 | N27: ○ 한글 250천원, ms오피스 420천원 | P27: 670000 | Q27: 1 | R27: 1
E28: 300 경상이전 | H28: =H29 -> 40000 | I28: 10000 | J28: =H28-I28 -> 30000
F29: 301 일반보상금 | H29: =H30 -> 40000 | I29: 10000 | J29: =H29-I29 -> 30000
G30: 14 기타보상금 | H30: =M30 -> 40000 | I30: 10000 | J30: =H30-I30 -> 30000 | K30: [기타보상금] | M30: =M31 -> 40000
K31: ○ 입장권 구매보상금 지급 : 40,000,000원*1식 | L31: = | M31: 40000
D32: 박람회 굿즈 제작 | H32: =SUM(H33) -> 100000 | I32: 0 | J32: =H32-I32 -> 100000
E33: 200 물건비 | H33: =SUM(H34) -> 100000 | I33: 0 | J33: =H33-I33 -> 100000
F34: 201 일반운영비 | H34: =H35 -> 100000 | I34: 0 | J34: =H34-I34 -> 100000
G35: 01 사무관리비 | H35: =M35 -> 100000 | I35: 0 | J35: =H35-I35 -> 100000 | K35: [일반수용비] | M35: =SUM(M36:M36) -> 100000
K36: ○ 박람회 굿즈 제작 100,000,000원*1식 | L36: = | M36: 100000
C37: 수익사업부 부서운영 | H37: =H38 -> 22876 | I37: 32316 | J37: =H37-I37 -> -9440
D38: 기본경비 | H38: =H39 -> 22876 | I38: 32316 | J38: =H38-I38 -> -9440
E39: 200 물건비 | H39: =SUM(H40,H47,H51,H54) -> 22876 | I39: 32316 | J39: =H39-I39 -> -9440
F40: 201 일반운영비 | H40: =SUM(H41,H43,H45) -> 10276 | I40: 12016 | J40: =H40-I40 -> -1740
...

Sheet 유치협력부
A1: 지출예산(세부사업) - 유치협력부 | M1: 단위 : 천원
A2: 구 분 | B2: 사업 | E2: 편성목 | H2: 예산액 (A) | I2: 전년도본예산액 (B) | J2: 비교증감 (A-B) | K2: 산 출 기 초
B3: 정책 | C3: 단위 | D3: 세부 | E3: 그룹 | F3: 목 | G3: 세목
A4: 총계(사업예산 + 자본예산) | H4: =H5 -> 47440 | I4: 62518 | J4: =H4-I4 -> -15078
A5: 사업예산 | H5: =H6 -> 47440 | I5: 62518 | J5: =H5-I5 -> -15078
B6: 2026여수세계섬박람회 유치협력 | H6: =SUM(H7,H18) -> 47440 | I6: 62518 | J6: =H6-I6 -> -15078
C7: 2026여수세계섬박람회 유치 | H7: =H8 -> 26300 | I7: 0 | J7: =H7-I7 -> 26300
D8: 국가기업 등 유치 | H8: =H9 -> 26300 | I8: 0 | J8: =H8-I8 -> 26300
E9: 200 물건비 | H9: =SUM(H10,H13) -> 26300 | I9: 0 | J9: =H9-I9 -> 26300
F10: 201 일반운영비 | H10: =H11 -> 5000 | I10: 0 | J10: =H10-I10 -> 5000
G11: 02 공공운영비 | H11: =M11 -> 5000 | I11: 0 | J11: =H11-I11 -> 5000 | K11: [우편료] | M11: =SUM(M12:M12) -> 5000
K12: ○ 국내·외 관람객 홍보물 등 발송 우편료 : 2,500원*2,000개소 | L12: = | M12: 5000
F13: 202 여비 | H13: =SUM(H14,H16) -> 21300 | I13: 0 | J13: =H13-I13 -> 21300
G14: 01 국내여비 | H14: =M14 -> 3300 | I14: 0 | J14: =H14-I14 -> 3300 | K14: [국내여비] | M14: =M15 -> 3300
K15: ○ 국가·기업 등 유치활동을 위한 관외여비 : 110,000원*2명*3일*5월 | L15: = | M15: 3300 | AC15: 9
G16: 03 국외업무여비 | H16: =M16 -> 18000 | I16: 0 | J16: =H16-I16 -> 18000 | K16: [국외업무여비] | M16: =M17 -> 18000
K17: ○ 국제교류 등 각종 국제행사 참가 : 3,000,000원*2명*3회 | L17: = | M17: 18000 | AC17: 9
C18: 유치협력부 부서운영 | H18: =H19 -> 21140 | I18: 62518 | J18: =H18-I18 -> -41378
D19: 기본경비 | H19: =H20 -> 21140 | I19: 62518 | J19: =H19-I19 -> -41378
E20: 200 물건비 | H20: =SUM(H21,H26,H30,H34) -> 21140 | I20: 62518 | J20: =H20-I20 -> -41378
F21: 201 일반운영비 | H21: =SUM(H22,H24) -> 7040 | I21: 19818 | J21: =H21-I21 -> -12778
G22: 01 사무관리비 | H22: =M22 -> 2000 | I22: 5770 | J22: =H22-I22 -> -3770 | K22: [일반수용비] | M22: =SUM(M23:M23) -> 2000
K23: ○ 부서 운영을 위한 소모품 구입 : 200,000원*10월 | L23: = | M23: 2000
G24: 15 복리후생비 | H24: =M24 -> 5040 | I24: 6048 | J24: =H24-I24 -> -1008 | K24: [급량비] | M24: =SUM(M25) -> 5040
K25: ○ 기본업무수행 급량비 : 9,000원*7명*8일*10월 | L25: = | M25: 5040
F26: 202 여비 | H26: =H27 -> 9000 | I26: 36600 | J26: =H26-I26 -> -27600
G27: 01 국내여비 | H27: =M27 -> 9000 | I27: 12600 | J27: =H27-I27 -> -3600 | K27: [국내여비] | M27: =SUM(M28:M29) -> 9000
K28: ○ 유치협력부 기본업무 수행 관내여비 : 20,000원*6명*2일*10월 | L28: = | M28: 2400 | AC28: 9
K29: ○ 유치협력부 기본업무 수행 관외여비 : 110,000원*6명*10월 | L29: = | M29: 6600
F30: 203 업무추진비 | H30: =H31 -> 3000 | I30: 4000 | J30: =H30-I30 -> -1000
G31: 07 사업업무추진비 | H31: =M31 -> 3000 | I31: 4000 | J31: =H31-I31 -> -1000 | K31: [시책추진업무추진비] | M31: =SUM(M32:M33) -> 3000
K32: ○ 유치협력부 업무추진 : 1,500,000원*1식 | L32: = | M32: 1500
K33: ○ 협력관 업무추진 : 1,500,000원*1식 | L33: = | M33: 1500
F34: 217 관서업무비 | H34: =H35 -> 2100 | I34: 2100 | J34: =H34-I34 -> 0
G35: 02 부서업무비 | H35: =M35 -> 2100 | I35: 2100 | J35: =H35-I35 -> 0 | K35: [부서업무비] | M35: =M36 -> 2100
K36: ○ 유치협력부 부서운영 총액계상 : 175,000원*12월 | L36: = | M36: 2100

Sheet 운영부
A1: 지출예산(세부사업) - 운영부 | M1: 단위 : 천원
A2: 구 분 | B2: 사업 | E2: 편성목 | H2: 예산액 (A) | I2: 전년도본예산액 (B) | J2: 비교증감 (A-B) | K2: 산 출 기 초
B3: 정책 | C3: 단위 | D3: 세부 | E3: 그룹 | F3: 목 | G3: 세목
A4: 총계(사업예산 + 자본예산) | H4: =H5 -> 3686944 | I4: 358632 | J4: =H4-I4 -> 3328312
A5: 사업예산 | H5: =H6 -> 3686944 | I5: 358632 | J5: =H5-I5 -> 3328312
B6: 2026여수세계섬박람회 운영 | H6: =SUM(H7,H19) -> 3686944 | I6: 358632 | J6: =H6-I6 -> 3328312
C7: 박람회장 운영 | H7: =SUM(H8) -> 3635156 | I7: 306500 | J7: =H7-I7 -> 3328656
D8: 대행사 선정 | H8: =SUM(H9) -> 3635156 | I8: 306500 | J8: =H8-I8 -> 3328656
E9: 200 물건비 | H9: =H10 -> 3635156 | I9: 306500 | J9: =H9-I9 -> 3328656
F10: 201 일반운영비 | H10: =SUM(M11,M13,M15,M17) -> 3635156 | I10: 306500 | J10: =H10-I10 -> 3328656
G11: 01 사무관리비 | H11: =M11+M13 -> 5000 | I11: 6000 | J11: =H11-I11 -> -1000 | K11: [운영수당] | M11: =SUM(M12:M12) -> 4000
K12: ○ 세부실행계획 보고회 등 참석수당 : 100,000원*10명*4회 | L12: = | M12: 4000
K13: [임차료] | M13: =SUM(M14:M14) -> 1000
K14: ○ 세부실행계획 보고회 회의실 임차비 : 250,000원*4회 | L14: = | M14: 1000
G15: 03 행사운영비 | H15: =M15 -> 3628156 | I15: 300000 | J15: =H15-I15 -> 3328156 | K15: [행사운영비] | M15: =M16 -> 3628156
K16: ○ 2026여수세계섬박람회 회장운영 대행 용역비(2차분) : 3,628,156,000원*1식 [사업수익 3,628,156] | L16: = | M16: 3628156
G17: 14 회의비 | H17: =M17 -> 2000 | I17: 500 | J17: =H17-I17 -> 1500 | K17: [회의비] | M17: =M18 -> 2000
K18: ○ 세부실행계획 추진상황 보고회 등 운영비 500,000원*4회 | L18: = | M18: 2000
C19: 운영부 사무국운영 | H19: =H20 -> 51788 | I19: 52132 | J19: =H19-I19 -> -344
D20: 기본경비 | H20: =H21 -> 51788 | I20: 52132 | J20: =H20-I20 -> -344
E21: 200 물건비 | H21: =SUM(H22,H29,H33,H39) -> 51788 | I21: 52132 | J21: =H21-I21 -> -344
F22: 201 일반운영비 | H22: =SUM(H23,H27) -> 25128 | I22: 19912 | J22: =H22-I22 -> 5216
G23: 01 사무관리비 | H23: =M23 -> 18000 | I23: 13000 | J23: =H23-I23 -> 5000 | K23: [일반수용비] | M23: =SUM(M24:M26) -> 18000
K24: ○ 운영본부 사무용품 등 구입 : 6,000,000원*1식 | L24: = | M24: 6000
K25: ○ 운영본부 복사용지 및 토너 구입 : 7,000,000원*1식 | L25: = | M25: 7000
K26: ○ 운영본부 환경정비 및 청소용품 구입 : 5,000,000원*1식 | L26: = | M26: 5000
G27: 15 복리후생비 | H27: =M28 -> 7128 | I27: 6912 | J27: =H27-I27 -> 216 | K27: [급량비] | M27: =M28 -> 7128
K28: ○ 기본업무수행 급량비 : 9,000원*9명*8일*11월 | L28: = | M28: 7128
F29: 202 여비 | H29: =H30 -> 10060 | I29: 14400 | J29: =H29-I29 -> -4340
G30: 01 국내여비 | H30: =M30 -> 10060 | I30: 14400 | J30: =H30-I30 -> -4340 | K30: [국내여비] | M30: =SUM(M31:M32) -> 10060
K31: ○ 운영부 기본업무 수행 관내여비 : 20,000원*7명*2일*10월 | L31: = | M31: 2800
K32: ○ 운영부 기본업무 수행 관외여비 : 110,000원*6명*11월 | L32: = | M32: 7260
F33: 203 업무추진비 | H33: =H34 -> 12100 | I33: 13400 | J33: =H33-I33 -> -1300
G34: 07 사업업무추진비 | H34: =SUM(M34,M36) -> 12100 | I34: 13400 | J34: =H34-I34 -> -1300 | K34: [기관운영업무추진비] | M34: =SUM(M35:M35) -> 6600
K35: ○ 4급보조기관장(운영본부장) : 6,600,000원*1식 | L35: = | M35: 6600
K36: [시책추진업무추진비] | M36: =SUM(M37:M38) -> 5500
K37: ○ 박람회 운영 및 조성 업무추진(4급) : 4,000,000원*1식 | L37: = | M37: 4000
K38: ○ 운영부 업무추진 : 1,500,000원*1식 | L38: = | M38: 1500
F39: 217 관서업무비 | H39: =SUM(M40,M42) -> 4500 | I39: 4420 | J39: =H39-I39 -> 80
G40: 01 정원가산업무비 | H40: =M40 -> 2400 | I40: 2320 | J40: =H40-I40 -> 80 | K40: [정원가산업무비] | M40: =M41 -> 2400
...

Sheet 행사부
A1: 지출예산(세부사업) - 행사부 | M1: 단위 : 천원
A2: 구 분 | B2: 사업 | E2: 편성목 | H2: 예산액 (A) | I2: 전년도본예산액 (B) | J2: 비교증감 (A-B) | K2: 산 출 기 초
B3: 정책 | C3: 단위 | D3: 세부 | E3: 그룹 | F3: 목 | G3: 세목
A4: 총계(사업예산 + 자본예산) | H4: =H5 -> 20648 | I4: 25268 | J4: =H4-I4 -> -4620
A5: 사업예산 | H5: =H6 -> 20648 | I5: 25268 | J5: =H5-I5 -> -4620
B6: 2026여수세계섬박람회 행사 | H6: =H7 -> 20648 | I6: 25268 | J6: =H6-I6 -> -4620
C7: 행사부 부서운영 | H7: =H8 -> 20648 | I7: 25268 | J7: =H7-I7 -> -4620
D8: 기본경비 | H8: =H9 -> 20648 | I8: 25268 | J8: =H8-I8 -> -4620
E9: 200 물건비 | H9: =SUM(H10,H15,H19,H22) -> 20648 | I9: 25268 | J9: =H9-I9 -> -4620
F10: 201 일반운영비 | H10: =SUM(H11,H13) -> 8048 | I10: 8568 | J10: =H10-I10 -> -520
G11: 01 사무관리비 | H11: =M11 -> 2000 | I11: 2520 | J11: =H11-I11 -> -520 | K11: [일반수용비] | M11: =SUM(M12:M12) -> 2000
K12: ○ 부서운영을 위한 소모품 구입 : 200,000원*10월 | L12: = | M12: 2000
G13: 15 복리후생비 | H13: =M13 -> 6048 | I13: 6048 | J13: =H13-I13 -> 0 | K13: [급량비] | M13: =SUM(M14) -> 6048
K14: ○ 기본업무수행 급량비 : 9,000원*7명*8일*12월 | L14: = | M14: 6048
F15: 202 여비 | H15: =H16 -> 9000 | I15: 12600 | J15: =H15-I15 -> -3600
G16: 01 국내여비 | H16: =M16 -> 9000 | I16: 12600 | J16: =H16-I16 -> -3600 | K16: [국내여비] | M16: =SUM(M17:M18) -> 9000
K17: ○ 행사부 기본업무 수행 관내여비 : 20,000원*6명*2일*10월 | L17: = | M17: 2400
K18: ○ 행사부 기본업무 수행 관외여비 : 110,000원*6명*10월 | L18: = | M18: 6600
F19: 203 업무추진비 | H19: =H20 -> 1500 | I19: 2000 | J19: =H19-I19 -> -500
G20: 07 사업업무추진비 | H20: =M20 -> 1500 | I20: 2000 | J20: =H20-I20 -> -500 | K20: [시책추진업무추진비] | M20: =SUM(M21) -> 1500
K21: ○ 행사부 업무추진 :1,500,000원*1식 | L21: = | M21: 1500
F22: 217 관서업무비 | H22: =H23 -> 2100 | I22: 2100 | J22: =H22-I22 -> 0
G23: 02 부서업무비 | H23: =M23 -> 2100 | I23: 2100 | J23: =H23-I23 -> 0 | K23: [부서업무비] | M23: =M24 -> 2100
K24: ○ 행사부 부서운영 총액계상 : 175,000원*12월 | L24: = | M24: 2100

Sheet 시설조성부
A1: 지출예산(세부사업) - 시설조성부 | M1: 단위 : 천원
A2: 구 분 | B2: 사업 | E2: 편성목 | H2: 예산액 (A) | I2: 전년도본예산액 (B) | J2: 비교증감 (A-B) | K2: 산 출 기 초
B3: 정책 | C3: 단위 | D3: 세부 | E3: 그룹 | F3: 목 | G3: 세목
A4: 총계(사업예산 + 자본예산) | H4: =H5+H31 -> 7998648 | I4: 25268 | J4: =H4-I4 -> 7973380
A5: 사업예산 | H5: =H6 -> 1765648 | I5: 25268 | J5: =H5-I5 -> 1740380
B6: 2026여수세계섬박람회 시설조성 | H6: =SUM(H7,H25) -> 1765648 | I6: 25268 | J6: =H6-I6 -> 1740380
C7: 시설조성부 부서운영 | H7: =H8 -> 20648 | I7: 25268 | J7: =H7-I7 -> -4620
D8: 기본경비 | H8: =H9 -> 20648 | I8: 25268 | J8: =H8-I8 -> -4620
E9: 200 물건비 | H9: =SUM(H10,H15,H19,H22) -> 20648 | I9: 25268 | J9: =H9-I9 -> -4620
F10: 201 일반운영비 | H10: =SUM(H11,H13) -> 8048 | I10: 8568 | J10: =H10-I10 -> -520
G11: 01 사무관리비 | H11: =M11 -> 2000 | I11: 2520 | J11: =H11-I11 -> -520 | K11: [일반수용비] | M11: =SUM(M12:M12) -> 2000
K12: ○ 부서운영을 위한 소모품 구입 : 200,000원*10월 | L12: = | M12: 2000
G13: 15 복리후생비 | H13: =M13 -> 6048 | I13: 6048 | J13: =H13-I13 -> 0 | K13: [급량비] | M13: =M14 -> 6048
K14: ○ 기본업무수행 급량비 : 9,000원*7명*8일*12월 | L14: = | M14: 6048
F15: 202 여비 | H15: =H16 -> 9000 | I15: 12600 | J15: =H15-I15 -> -3600
G16: 01 국내여비 | H16: =M16 -> 9000 | I16: 12600 | J16: =H16-I16 -> -3600 | K16: [국내여비] | M16: =SUM(M17:M18) -> 9000
K17: ○ 시설조성부 기본업무 수행 관내여비 : 20,000원*6명*2일*10월 | L17: = | M17: 2400
K18: ○ 시설조성부 기본업무 수행 관외여비 : 110,000원*6명*10월 | L18: = | M18: 6600
F19: 203 업무추진비 | H19: =H20 -> 1500 | I19: 2000 | J19: =H19-I19 -> -500
G20: 07 사업업무추진비 | H20: =M20 -> 1500 | I20: 2000 | J20: =H20-I20 -> -500 | K20: [시책추진업무추진비] | M20: =SUM(M21) -> 1500
K21: ○ 시설조성부 업무추진 : 1,500,000원*1식 | L21: = | M21: 1500
F22: 217 관서업무비 | H22: =H23 -> 2100 | I22: 2100 | J22: =H22-I22 -> 0
G23: 02 부서업무비 | H23: =M23 -> 2100 | I23: 2100 | J23: =H23-I23 -> 0 | K23: [부서업무비] | M23: =M24 -> 2100
K24: ○ 시설조성부 부서운영 총액계상 : 175,000원*12월 | L24: = | M24: 2100
C25: 2026여수세계섬박람회 시설조성(수익) | H25: =SUM(H26) -> 1745000 | I25: 0 | J25: =H25-I25 -> 1745000
D26: 전시관 및 운영·부대시설 설치 | H26: =H27 -> 1745000 | I26: 0 | J26: =H26-I26 -> 1745000
E27: 200 물건비 | H27: =H28 -> 1745000 | I27: 0 | J27: =H27-I27 -> 1745000
F28: 201 일반운영비 | H28: =H29 -> 1745000 | I28: 0 | J28: =H28-I28 -> 1745000
G29: 03 행사운영비 | H29: =M29 -> 1745000 | I29: 0 | J29: =H29-I29 -> 1745000 | K29: [행사운영비] | M29: =M30 -> 1745000
G30: [사업수익 1,745,000] | K30: ○ 섬박람회 전시관 및 운영·부대시설 설치 1,745,000,000원*1식 [사업수익 1,745,000] | L30: = | M30: 1745000
A31: 자본예산 | H31: =SUM(H32,H39,H46) -> 6233000 | I31: 0 | J31: =H31-I31 -> 6233000
B32: 2026여수세계섬박람회 조성연출 | H32: =SUM(H33,H53) -> 3233000 | I32: 0 | J32: =H32-I32 -> 3233000
C33: 박람회 조성 | H33: =SUM(H34) -> 3233000 | I33: 0 | J33: =H33-I33 -> 3233000
D34: 박람회 조성 | H34: =H35 -> 3233000 | I34: 0 | J34: =H34-I34 -> 3233000
E35: 400 자본지출 | H35: =H36 -> 3233000 | I35: 0 | J35: =H35-I35 -> 3233000
F36: 401 시설비 및 부대비 | H36: =H37 -> 3233000 | I36: 0 | J36: =H36-I36 -> 3233000
G37: 01 시설비 | H37: =M37 -> 3233000 | I37: 0 | J37: =H37-I37 -> 3233000 | K37: [시설비] | M37: =M38 -> 3233000
G38: [국 3,233,000] | K38: ○ 2026여수세계섬박람회 주행사장 조성사업 : 3,233,000,000원*1식 [국 3,233,000] | L38: = | M38: 3233000
B39: 섬박람회 랜드마크 조성사업(수익) | H39: =SUM(H40,H53) -> 1000000 | I39: 0 | J39: =H39-I39 -> 1000000
C40: 랜드마크 조성(수익) | H40: =SUM(H41) -> 1000000 | I40: 0 | J40: =H40-I40 -> 1000000
...

Sheet 전시연출부
A1: 지출예산(세부사업) - 전시연출부 | M1: 단위 : 천원
A2: 구 분 | B2: 사업 | E2: 편성목 | H2: 예산액 (A) | I2: 전년도본예산액 (B) | J2: 비교증감 (A-B) | K2: 산 출 기 초
B3: 정책 | C3: 단위 | D3: 세부 | E3: 그룹 | F3: 목 | G3: 세목
A4: 총계(사업예산 + 자본예산) | H4: =H5 -> 2121344 | I4: 25268 | J4: =H4-I4 -> 2096076
A5: 사업예산 | H5: =H6 -> 2121344 | I5: 25268 | J5: =H5-I5 -> 2096076
B6: 2026여수세계섬박람회 전시연출 | H6: =SUM(H7,H23) -> 2121344 | I6: 25268 | J6: =H6-I6 -> 2096076
C7: 2026여수세계섬박람회 전시연출 | H7: =SUM(H8,H13,H18) -> 2101200 | I7: 0 | J7: =H7-I7 -> 2101200
D8: 박람회 전시연출 | H8: =H9 -> 2098000 | I8: 0 | J8: =H8-I8 -> 2098000
E9: 200 물건비 | H9: =H10 -> 2098000 | I9: 0 | J9: =H9-I9 -> 2098000
F10: 201 일반운영비 | H10: =SUM(H11) -> 2098000 | I10: 0 | J10: =H10-I10 -> 2098000
G11: 03 행사운영비 | H11: =M11 -> 2098000 | I11: 0 | J11: =H11-I11 -> 2098000 | K11: [행사운영비] | M11: =SUM(M12) -> 2098000
K12: ○ 전시연출 콘텐츠 개발 2,098,000,000원*1식 | L12: = | M12: 2098000
D13: 섬 테마존 조성 업무 추진 | H13: =H14 -> 1600 | I13: 0 | J13: =H13-I13 -> 1600
E14: 200 물건비 | H14: =H15 -> 1600 | I14: 0 | J14: =H14-I14 -> 1600
F15: 201 일반운영비 | H15: =SUM(H16) -> 1600 | I15: 0 | J15: =H15-I15 -> 1600
G16: 01 사무관리비 | H16: =M16 -> 1600 | I16: 0 | J16: =H16-I16 -> 1600 | K16: [임차료] | M16: =SUM(M17) -> 1600
K17: ○ 회의실 임차료 : 400,000원*4회 | L17: = | M17: 1600
D18: 섬박람회 상징 아트포토존 조성 업무 추진 | H18: =H19 -> 1600 | I18: 0 | J18: =H18-I18 -> 1600
E19: 200 물건비 | H19: =H20 -> 1600 | I19: 0 | J19: =H19-I19 -> 1600
F20: 201 일반운영비 | H20: =SUM(H21) -> 1600 | I20: 0 | J20: =H20-I20 -> 1600
G21: 01 사무관리비 | H21: =M21 -> 1600 | I21: 0 | J21: =H21-I21 -> 1600 | K21: [임차료] | M21: =SUM(M22) -> 1600
K22: ○ 회의실 임차료 : 400,000원*4회 | L22: = | M22: 1600
C23: 전시연출부 부서운영 | H23: =H24 -> 20144 | I23: 25268 | J23: =H23-I23 -> -5124
D24: 기본경비 | H24: =H25 -> 20144 | I24: 25268 | J24: =H24-I24 -> -5124
E25: 200 물건비 | H25: =SUM(H26,H31,H35,H38) -> 20144 | I25: 25268 | J25: =H25-I25 -> -5124
F26: 201 일반운영비 | H26: =SUM(H27,H29) -> 7544 | I26: 8568 | J26: =H26-I26 -> -1024
G27: 01 사무관리비 | H27: =M27 -> 2000 | I27: 2520 | J27: =H27-I27 -> -520 | K27: [일반수용비] | M27: =SUM(M28:M28) -> 2000
K28: ○ 부서운영을 위한 소모품 구입 : 200,000원*10월 | L28: = | M28: 2000
G29: 15 복리후생비 | H29: =M29 -> 5544 | I29: 6048 | J29: =H29-I29 -> -504 | K29: [급량비] | M29: =SUM(M30) -> 5544
K30: ○ 기본업무수행 급량비 : 9,000원*7명*8일*11월 | L30: = | M30: 5544
F31: 202 여비 | H31: =H32 -> 9000 | I31: 12600 | J31: =H31-I31 -> -3600
G32: 01 국내여비 | H32: =M32 -> 9000 | I32: 12600 | J32: =H32-I32 -> -3600 | K32: [국내여비] | M32: =SUM(M33:M34) -> 9000
K33: ○ 전시연출부 기본업무 수행 관내여비 : 20,000원*6명*2일*10월 | L33: = | M33: 2400
K34: ○ 전시연출부 기본업무 수행 관외여비 : 110,000원*6명*10월 | L34: = | M34: 6600
F35: 203 업무추진비 | H35: =H36 -> 1500 | I35: 2000 | J35: =H35-I35 -> -500
G36: 07 사업업무추진비 | H36: =M36 -> 1500 | I36: 2000 | J36: =H36-I36 -> -500 | K36: [시책추진업무추진비] | M36: =SUM(M37) -> 1500
K37: ○ 전시연출부 업무추진 : 1,500,000원*1식 | L37: = | M37: 1500
F38: 217 관서업무비 | H38: =H39 -> 2100 | I38: 2100 | J38: =H38-I38 -> 0
G39: 02 부서업무비 | H39: =M39 -> 2100 | I39: 2100 | J39: =H39-I39 -> 0 | K39: [부서업무비] | M39: =M40 -> 2100
K40: ○ 전시연출부 부서운영 총액계상 : 175,000원*12월 | L40: = | M40: 2100

Sheet 종합상황실
A1: 지출예산(세부사업) - 종합상황실 | M1: 단위 : 천원
A2: 구 분 | B2: 사업 | E2: 편성목 | H2: 예산액 (A) | I2: 전년도본예산액 (B) | J2: 비교증감 (A-B) | K2: 산 출 기 초
B3: 정책 | C3: 단위 | D3: 세부 | E3: 그룹 | F3: 목 | G3: 세목
A4: 총계(사업예산 + 자본예산) | H4: =H5 -> 16292 | I4: 0 | J4: =H4-I4 -> 16292
A5: 사업예산 | H5: =H6 -> 16292 | I5: 0 | J5: =H5-I5 -> 16292
B6: 2026여수세계섬박람회 종합상황실 | H6: =H7 -> 16292 | I6: 0 | J6: =H6-I6 -> 16292
C7: 종합상황실 부서운영 | H7: =H8 -> 16292 | I7: 0 | J7: =H7-I7 -> 16292
D8: 기본경비 | H8: =H9 -> 16292 | I8: 0 | J8: =H8-I8 -> 16292
E9: 200 물건비 | H9: =SUM(H10,H15,H19,H22) -> 16292 | I9: 0 | J9: =H9-I9 -> 16292
F10: 201 일반운영비 | H10: =SUM(H11,H13) -> 4592 | I10: 0 | J10: =H10-I10 -> 4592
G11: 01 사무관리비 | H11: =M11 -> 2000 | I11: 0 | J11: =H11-I11 -> 2000 | K11: [일반수용비] | M11: =SUM(M12:M12) -> 2000
K12: ○ 부서운영을 위한 소모품 구입 : 200,000원*10월 | L12: = | M12: 2000
G13: 15 복리후생비 | H13: =M13 -> 2592 | I13: 0 | J13: =H13-I13 -> 2592 | K13: [급량비] | M13: =SUM(M14) -> 2592
K14: ○ 기본업무수행 급량비 : 9,000원*3명*8일*12월 | L14: = | M14: 2592
F15: 202 여비 | H15: =H16 -> 9000 | I15: 0 | J15: =H15-I15 -> 9000
G16: 01 국내여비 | H16: =M16 -> 9000 | I16: 0 | J16: =H16-I16 -> 9000 | K16: [국내여비] | M16: =SUM(M17:M18) -> 9000
K17: ○ 종합상황실 기본업무 수행 관내여비 : 20,000원*6명*2일*10월 | L17: = | M17: 2400
K18: ○ 종합상황실 기본업무 수행 관외여비 : 110,000원*6명*10월 | L18: = | M18: 6600
F19: 203 업무추진비 | H19: =H20 -> 1500 | I19: 0 | J19: =H19-I19 -> 1500
G20: 07 사업업무추진비 | H20: =M20 -> 1500 | I20: 0 | J20: =H20-I20 -> 1500 | K20: [시책추진업무추진비] | M20: =SUM(M21) -> 1500
K21: ○ 종합상황실 업무추진 : 1,500,000원*1식 | L21: = | M21: 1500
F22: 217 관서업무비 | H22: =H23 -> 1200 | I22: 0 | J22: =H22-I22 -> 1200
G23: 02 부서업무비 | H23: =M23 -> 1200 | I23: 0 | J23: =H23-I23 -> 1200 | K23: [부서업무비] | M23: =M24 -> 1200
K24: ○ 종합상황실 부서운영 총액계상 : 100,000원*12월 | L24: = | M24: 1200

Sheet 예비비
A1: 지출예산(세부사업) - 예비비 | M1: 단위 : 천원
A2: 구 분 | B2: 사업 | E2: 편성목 | H2: 예산액 (A) | I2: 전년도본예산액 (B) | J2: 비교증감 (A-B) | K2: 산 출 기 초
B3: 정책 | C3: 단위 | D3: 세부 | E3: 그룹 | F3: 목 | G3: 세목
A4: 총계(사업예산 + 자본예산) | H4: =H5+H13 -> 596200 | I4: 316640 | J4: =H4-I4 -> 279560
A5: 사업예산 | H5: =H6 -> 596200 | I5: 316640 | J5: =H5-I5 -> 279560
B6: 예비비 | H6: =H7 -> 596200 | I6: 316640 | J6: =H6-I6 -> 279560
C7: 예비비 | H7: =H8 -> 596200 | I7: 316640 | J7: =H7-I7 -> 279560
D8: 예비비 | H8: =H9 -> 596200 | I8: 316640 | J8: =H8-I8 -> 279560
E9: 800 예비비 | H9: =H10 -> 596200 | I9: 316640 | J9: =H9-I9 -> 279560
F10: 801 예비비 | H10: =H11 -> 596200 | I10: 316640 | J10: =H10-I10 -> 279560
G11: 01 일반예비비 | H11: =M11 -> 596200 | I11: 316640 | J11: =H11-I11 -> 279560 | K11: [일반예비비] | M11: =M12 -> 596200
K12: ○ 예비비 : 596,200,000원*1식 | L12: = | M12: 596200
A13: 자본예산 | H13: =SUM(H14,H27) -> 0 | J13: =H13-I13 -> 0
B14: 예비비(자본) | H14: =SUM(H15,H55) -> 0 | J14: =H14-I14 -> 0
C15: 예비비(자본) | H15: =H16 -> 0 | J15: =H15-I15 -> 0
D16: 예비비(자본) | H16: =H17 -> 0 | J16: =H16-I16 -> 0
E17: 800 예비비 | H17: =H18 -> 0 | J17: =H17-I17 -> 0
F18: 801 예비비 | H18: =H19 -> 0 | J18: =H18-I18 -> 0
G19: 01 일반예비비 | H19: =M19 -> 0 | J19: =H19-I19 -> 0 | K19: [일반예비비] | M19: =M20 -> 0
K20: ○ 예비비(자본) : 0원 | L20: = | M20: 0

Sheet 지출예산(위탁)
A1: 지출예산(위탁) - 본예산
I2: (단위 : 천 원)
A3: 과 목 | G3: 예산액 (A) | H3: 전년도본예산액 (B) | I3: 비교증감 (A-B)
A4: 구분 | B4: 정책사업 | C4: 단위사업 | D4: 세부사업 | E4: 목 | F4: 세목
A5: 총계(사업예산+자본예산) | G5: =G6+G47 -> 14320000 | H5: 22550000 | I5: =G5-H5 -> -8230000
A6: 사업예산 | G6: =SUM(G7,G17,G42) -> 10750000 | H6: 5450000 | I6: =G6-H6 -> 5300000
B7: 2026여수세계섬박람회 기획홍보(위탁) | G7: ='기획본부(위탁)'!H6 -> 1000000 | H7: 2000000 | I7: =G7-H7 -> -1000000
C8: 2026여수세계섬박람회 홍보 | G8: ='기획본부(위탁)'!H7 -> 1000000 | H8: 2000000 | I8: =G8-H8 -> -1000000
D9: 박람회 홍보 | G9: ='기획본부(위탁)'!H8 -> 1000000 | H9: 2000000 | I9: =G9-H9 -> -1000000
E10: 일반운영비 | G10: ='기획본부(위탁)'!H10 -> 965000 | H10: 1974000 | I10: =G10-H10 -> -1009000
F11: 사무관리비 | G11: ='기획본부(위탁)'!H11 -> 345000 | H11: 1419000 | I11: =G11-H11 -> -1074000
F12: 행사운영비 | G12: ='기획본부(위탁)'!H17 -> 120000 | H12: 55000 | I12: =G12-H12 -> 65000
F13: 광고선전비 | G13: ='기획본부(위탁)'!H21 -> 500000 | H13: 500000 | I13: =G13-H13 -> 0
E14: 일반보상금 | G14: ='기획본부(위탁)'!H24 -> 35000 | H14: 26000 | I14: =G14-H14 -> 9000
F15: 행사실비보상금 | G15: ='기획본부(위탁)'!H25 -> 10000 | H15: 26000 | I15: =G15-H15 -> -16000
F16: 기타보상금 | G16: ='기획본부(위탁)'!H27 -> 25000 | H16: 26000 | I16: =G16-H16 -> -1000
B17: 2026여수세계섬박람회 유치협력(위탁) | G17: =G18 -> 4250000 | H17: 950000 | I17: =G17-H17 -> 3300000
C18: 2026여수세계섬박람회 유치 | G18: ='기획본부(위탁)'!H31 -> 4250000 | H18: 950000 | I18: =G18-H18 -> 3300000
D19: 관람객 유치 | G19: ='기획본부(위탁)'!H32 -> 250000 | H19: 660000 | I19: =G19-H19 -> -410000
E20: 일반보상금 | G20: ='기획본부(위탁)'!H34 -> 250000 | H20: 162000 | I20: =G20-H20 -> 88000
F21: 기타보상금 | G21: ='기획본부(위탁)'!H35 -> 250000 | H21: 30000 | I21: =G21-H21 -> 220000
D22: 기업관 부스 운영 | G22: ='기획본부(위탁)'!H37 -> 60000 | H22: 0 | I22: =G22-H22 -> 60000
E23: 일반운영비 | G23: ='기획본부(위탁)'!H39 -> 60000 | H23: 0 | I23: =G23-H23 -> 60000
F24: 행사운영비 | G24: ='기획본부(위탁)'!H40 -> 60000 | H24: 0 | I24: =G24-H24 -> 60000
D25: 참가국 지원 | G25: ='기획본부(위탁)'!H42 -> 3070000 | H25: 0 | I25: =G25-H25 -> 3070000
E26: 일반운영비 | G26: ='기획본부(위탁)'!H44 -> 2340000 | H26: 0 | I26: =G26-H26 -> 2340000
F27: 행사운영비 | G27: ='기획본부(위탁)'!H45 -> 2340000 | H27: 0 | I27: =G27-H27 -> 2340000
E28: 일반보상금 | G28: ='기획본부(위탁)'!H48 -> 730000 | H28: 0 | I28: =G28-H28 -> 730000
F29: 외빈초청여비 | G29: ='기획본부(위탁)'!H49 -> 730000 | H29: 0 | I29: =G29-H29 -> 730000
D30: 2026국제섬포럼 in Yeosu | G30: ='기획본부(위탁)'!H51 -> 270000 | H30: 0 | I30: =G30-H30 -> 270000
E31: 일반운영비 | G31: ='기획본부(위탁)'!H53 -> 224000 | H31: 0 | I31: =G31-H31 -> 224000
F32: 사무관리비 | G32: ='기획본부(위탁)'!H54 -> 4000 | H32: 0 | I32: =G32-H32 -> 4000
F33: 행사운영비 | G33: ='기획본부(위탁)'!H57 -> 220000 | H33: 0 | I33: =G33-H33 -> 220000
E34: 일반보상금 | G34: ='기획본부(위탁)'!H60 -> 46000 | H34: 0 | I34: =G34-H34 -> 46000
F35: 외빈초청여비 | G35: ='기획본부(위탁)'!H61 -> 46000 | H35: 0 | I35: =G35-H35 -> 46000
D36: 세계섬도시대회 | G36: ='기획본부(위탁)'!H63 -> 600000 | H36: 0 | I36: =G36-H36 -> 600000
E37: 일반운영비 | G37: ='기획본부(위탁)'!H65 -> 358000 | H37: 0 | I37: =G37-H37 -> 358000
F38: 사무관리비 | G38: ='기획본부(위탁)'!H66 -> 4000 | H38: 0 | I38: =G38-H38 -> 4000
F39: 행사운영비 | G39: ='기획본부(위탁)'!H69 -> 354000 | H39: 0 | I39: =G39-H39 -> 354000
E40: 일반보상금 | G40: ='기획본부(위탁)'!H72 -> 242000 | H40: 0 | I40: =G40-H40 -> 242000
...

Sheet 기획본부(위탁)
A1: 지출예산 - 기획본부(위탁) | M1: 단위 : 천 원
A2: 구 분 | B2: 사업 | E2: 편성목 | H2: 예산액 (A) | I2: 전년도본예산액 (B) | J2: 비교증감 (A-B) | K2: 산 출 기 초
B3: 정책 | C3: 단위 | D3: 세부 | E3: 그룹 | F3: 목 | G3: 세목
A4: 총계(사업예산 + 자본예산) | H4: =H5 -> 5250000 | I4: 2950000 | J4: =H4-I4 -> 2300000
A5: 사업예산 | H5: =H6+H30 -> 5250000 | I5: 2950000 | J5: =H5-I5 -> 2300000
B6: 2026여수세계섬박람회 기획홍보(위탁) | H6: =H7 -> 1000000 | I6: 2000000 | J6: =H6-I6 -> -1000000
C7: 2026여수세계섬박람회 홍보 | H7: =H8 -> 1000000 | I7: 2000000 | J7: =H7-I7 -> -1000000
D8: 박람회 홍보 | H8: =H9+H23 -> 1000000 | I8: 2000000 | J8: =H8-I8 -> -1000000
E9: 200 물건비 | H9: =H10 -> 965000 | I9: 1974000 | J9: =H9-I9 -> -1009000
F10: 201 일반운영비 | H10: =SUM(H11,H17,H21) -> 965000 | I10: 1974000 | J10: =H10-I10 -> -1009000
G11: 01 사무관리비 | H11: =M11 -> 345000 | I11: 1419000 | J11: =H11-I11 -> -1074000 | K11: [사무관리비] | M11: =SUM(M12:M16) -> 345000
G12: [도 103,500, 시 241,500] | K12: ○ 홍보물품 등 제작 : 200,000,000원*1식 | L12: = | M12: 200000
K13: ○ 홍보콘텐츠 등 제작 : 100,000,000원*1식 | L13: = | M13: 100000
K14: ○ 홍보부스 참가비 : 40,000,000원*1식 | L14: = | M14: 40000
K15: ○ 제안서, 공모전 평가위원 수당 : 4,000,000원*1식 | L15: = | M15: 4000
K16: ○ 제안서, 공모전 평가위원 실비 : 1,000,000원*1식 | L16: = | M16: 1000
G17: 03 행사운영비 | H17: =M17 -> 120000 | I17: 55000 | J17: =H17-I17 -> 65000 | K17: [행사운영비] | M17: =SUM(M18:M20) -> 120000
G18: [도 36,000, 시 84,000] | K18: ○ 사전 홍보 이벤트 : 50,000,000원*1식 | L18: = | M18: 50000
K19: ○ 홍보부스 운영 : 5,000,000원*10회 | L19: = | M19: 50000
K20: ○ 홍보대사, 서포터즈 운영 : 20,000,000원*1식 | L20: = | M20: 20000
G21: 16 광고선전비 | H21: =M21 -> 500000 | I21: 500000 | J21: =H21-I21 -> 0 | K21: [광고료] | M21: =SUM(M22) -> 500000
G22: [도 150,000, 시 350,000] | K22: ○ 섬박람회 광고 홍보료 : 500,000,000원*1식 | L22: = | M22: 500000
E23: 300 경상이전 | H23: =H24 -> 35000 | I23: 26000 | J23: =H23-I23 -> 9000
F24: 301 일반보상금 | H24: =SUM(H25,H27) -> 35000 | I24: 26000 | J24: =H24-I24 -> 9000
G25: 10 행사실비보상금 | H25: =M25 -> 10000 | I25: 0 | J25: =H25-I25 -> 10000 | K25: [행사실비보상금] | M25: =SUM(M26:M26) -> 10000
G26: [도 3,000, 시 7,000] | K26: ○ 홍보대사, 서포터즈 등 실비 : 100,000원*20명*5회 | L26: = | M26: 10000
G27: 14 기타보상금 | H27: =M27 -> 25000 | I27: 26000 | J27: =H27-I27 -> -1000 | K27: [기타보상금] | M27: =SUM(M28:M29) -> 25000
G28: [도 7,500, 시 17,500] | K28: ○ 공모전 시상금 : 5,000,000원*3회 | L28: = | M28: 15000
K29: ○ 각종 이벤트 경품 : 10,000,000원*1식 | L29: = | M29: 10000
B30: 2026여수세계섬박람회 유치협력(위탁) | H30: =H31 -> 4250000 | I30: 950000 | J30: =H30-I30 -> 3300000
C31: 2026여수세계섬박람회 유치 | H31: =SUM(H32,H37,H42,H51,H63) -> 4250000 | I31: 950000 | J31: =H31-I31 -> 3300000
D32: 관람객 유치 | H32: =H33 -> 250000 | I32: 660000 | J32: =H32-I32 -> -410000
E33: 300 경상이전 | H33: =H34 -> 250000 | I33: 162000 | J33: =H33-I33 -> 88000
F34: 301 일반보상금 | H34: =SUM(H35) -> 250000 | I34: 162000 | J34: =H34-I34 -> 88000
G35: 14 기타보상금 | H35: =SUM(M35) -> 250000 | I35: 30000 | J35: =H35-I35 -> 220000 | K35: [기타보상금] | M35: =SUM(M36:M36) -> 250000
G36: [도 75,000, 시 175,000] | K36: ○ 공식여행사 인센티브 지급 250,000,000원*1식 | L36: = | M36: 250000
D37: 기업관 부스 운영 | H37: =H38 -> 60000 | I37: 0 | J37: =H37-I37 -> 60000
E38: 200 물건비 | H38: =H39 -> 60000 | I38: 0 | J38: =H38-I38 -> 60000
F39: 201 일반운영비 | H39: =SUM(H40) -> 60000 | I39: 0 | J39: =H39-I39 -> 60000
G40: 03 행사운영비 | H40: =SUM(M40) -> 60000 | I40: 0 | J40: =H40-I40 -> 60000 | K40: [행사운영비] | M40: =SUM(M41:M41) -> 60000
...

Sheet 운영본부(위탁)
A1: 지출예산 - 운영본부(위탁) | M1: 단위 : 천 원
A2: 구 분 | B2: 사업 | E2: 편성목 | H2: 예산액 (A) | I2: 전년도본예산액 (B) | J2: 비교증감 (A-B) | K2: 산 출 기 초
B3: 정책 | C3: 단위 | D3: 세부 | E3: 그룹 | F3: 목 | G3: 세목
A4: 총계(사업예산 + 자본예산) | H4: =H5+H13 -> 9070000 | I4: 19600000 | J4: =H4-I4 -> -10530000
A5: 사업예산 | H5: =H6 -> 5500000 | I5: 2500000 | J5: =H5-I5 -> 3000000
B6: 2026여수세계섬박람회 행사(위탁) | H6: =H7 -> 5500000 | I6: 1000000 | J6: =H6-I6 -> 4500000
C7: 2026여수세계섬박람회 행사 | H7: =H8 -> 5500000 | I7: 1000000 | J7: =H7-I7 -> 4500000
D8: 문화행사 추진 | H8: =H9 -> 5500000 | I8: 600000 | J8: =H8-I8 -> 4900000
E9: 200 물건비 | H9: =H10 -> 5500000 | I9: 600000 | J9: =H9-I9 -> 4900000
F10: 201 일반운영비 | H10: =H11 -> 5500000 | I10: 600000 | J10: =H10-I10 -> 4900000
G11: 03 행사운영비 | H11: =M11 -> 5500000 | I11: 600000 | J11: =H11-I11 -> 4900000 | K11: [행사운영비] | M11: =M12 -> 5500000
G12: [도 1,650,000, 시 3,850,000] | K12: ○ 2026여수세계섬박람회 문화행사 운영 : 5,500,000,000원*1식 [도 1,650,000, 시 3,850,000] | L12: = | M12: 5500000
A13: 자본예산 | H13: =H14+H36 -> 3570000 | I13: 17100000 | J13: =H13-I13 -> -13530000
B14: 2026여수세계섬박람회 시설조성(위탁) | H14: =H15 -> 1980000 | I14: 10300000 | J14: =H14-I14 -> -8320000
C15: 2026여수세계섬박람회 시설조성 | H15: =SUM(H16,H21,H26,H31) -> 1980000 | I15: 10300000 | J15: =H15-I15 -> -8320000
D16: 섬박람회 랜드마크 조성사업 | H16: =H17 -> 1200000 | I16: 5000000 | J16: =H16-I16 -> -3800000
E17: 400 자본지출 | H17: =H18 -> 1200000 | I17: 5000000 | J17: =H17-I17 -> -3800000
F18: 401 시설비및부대비 | H18: =SUM(H19) -> 1200000 | I18: 5000000 | J18: =H18-I18 -> -3800000
G19: 01 시설비 | H19: =M19 -> 1200000 | I19: 4986500 | J19: =H19-I19 -> -3786500 | K19: [시설비] | M19: =SUM(M20) -> 1200000
G20: [도 1,200,000] | K20: ○ 섬박람회 랜드마크 조성사업 : 1,200,000,000원*1식 [도 1,200,000] | L20: = | M20: 1200000
D21: 섬박람회장 안전시설물 설치사업 | H21: =H22 -> 300000 | I21: 3000000 | J21: =H21-I21 -> -2700000
E22: 400 자본지출 | H22: =H23 -> 300000 | I22: 3000000 | J22: =H22-I22 -> -2700000
F23: 401 시설비및부대비 | H23: =SUM(H24) -> 300000 | I23: 3000000 | J23: =H23-I23 -> -2700000
G24: 01 시설비 | H24: =M24 -> 300000 | I24: 2989200 | J24: =H24-I24 -> -2689200 | K24: [시설비] | M24: =SUM(M25) -> 300000
G25: [도 300,000] | K25: ○ 섬박람회장 안전시설물 설치사업 : 300,000,000원*1식 [도 300,000] | L25: = | M25: 300000
D26: 섬박람회장 입구게이트 조성 | H26: =H27 -> 90000 | I26: 500000 | J26: =H26-I26 -> -410000
E27: 400 자본지출 | H27: =H28 -> 90000 | I27: 496400 | J27: =H27-I27 -> -406400
F28: 401 시설비및부대비 | H28: =SUM(H29) -> 90000 | I28: 496400 | J28: =H28-I28 -> -406400
G29: 01 시설비 | H29: =M29 -> 90000 | I29: 496400 | J29: =H29-I29 -> -406400 | K29: [시설비] | M29: =M30 -> 90000
G30: [도 90,000] | K30: ○ 섬박람회장 입구게이트 조성 : 90,000,000원*1식 [도 90,000] | L30: = | M30: 90000
D31: 섬박람회장 열린문화공간 조성 | H31: =H32 -> 390000 | I31: 1800000 | J31: =H31-I31 -> -1410000
E32: 400 자본지출 | H32: =H33 -> 390000 | I32: 1793520 | J32: =H32-I32 -> -1403520
F33: 401 시설비및부대비 | H33: =SUM(H34) -> 390000 | I33: 1793520 | J33: =H33-I33 -> -1403520
G34: 01 시설비 | H34: =M34 -> 390000 | I34: 1793520 | J34: =H34-I34 -> -1403520 | K34: [시설비] | M34: =M35 -> 390000
G35: [도 390,000] | K35: ○ 섬박람회장 열린문화공간 조성 390,000,000원*1식 [도 390,000] | L35: = | M35: 390000
B36: 2026여수세계섬박람회 전시연출(위탁) | H36: =H37 -> 1590000 | I36: 6800000 | J36: =H36-I36 -> -5210000
C37: 2026여수세계섬박람회 전시연출 | H37: =SUM(H38,H43) -> 1590000 | I37: 6800000 | J37: =H37-I37 -> -5210000
D38: 세계 섬‧한국의 섬 테마존 조성 | H38: =H39 -> 1200000 | I38: 5000000 | J38: =H38-I38 -> -3800000
E39: 400 자본지출 | H39: =H40 -> 1200000 | I39: 5000000 | J39: =H39-I39 -> -3800000
F40: 401 시설비및부대비 | H40: =H41 -> 1200000 | I40: 5000000 | J40: =H40-I40 -> -3800000
...
