Workbook
Name ㄹㄹㄹ: #REF!
Name ㄹㄹㄹ: #REF!
Name ㄹㄹㄹ: #REF!
Name ㄹㄹㄹ: #REF!
Name ㄹㄹㄹ: #REF!
Name ㅁ1: #REF!
Name ㅁ1: #REF!
Name ㅁ1: #REF!
Name ㅁ1: #REF!
Name ㅁ1: #REF!
Name ㅁ1: #REF!
Name ㅇㅇ: #REF!
Name ㅇㅇ: #REF!
Name ㅇㅇ: #REF!
Name ㅇㅇㅇ: #REF!
Name ㅇㅇㅇ: #REF!
Name ㅇㅇㅇ: #REF!

Sheet 표지
M3: 2026. 5. 12.
A13: 섬박람회 조직위원회 2026년 제1회 추경예산서
D22: (재)2026여수세계섬박람회 조직위원회

Sheet 수입예산 총괄표
A1: 수입예산 총괄표(출연금+위탁사업비)
H2: (단위 : 천 원)
A3: 과 목 | F3: 경정액 (A) | G3: 기정액(본예산) (B) | H3: 비교증감
A4: 구분 | B4: 관 | C4: 항 | D4: 세항 | E4: 목
A5: 총계(사업예산+자본예산) | F5: =F6 -> 33799578 | G5: 30150147 | H5: =F5-G5 -> 3649431
A6: 자체수입금 | F6: =SUM(F7,F28) -> 33799578 | G6: 30150147 | H6: =F6-G6 -> 3649431
B7: 600 사업수익 | F7: =SUM(F8,F23) -> 27219881 | G7: 24012100 | H7: =F7-G7 -> 3207781
C8: 610 영업수익 | F8: =SUM(F9,F11,F13,F15,F17,F19,F21) -> 26962100 | G8: 24012100 | H8: =F8-G8 -> 2950000
D9: 621 상품등판매수익 | F9: =F10 -> 120000 | G9: 120000 | H9: =F9-G9 -> 0
E10: 01 상품판매수익 | F10: 120000 | G10: 120000 | H10: =F10-G10 -> 0
D11: 623 대행사업수익 | F11: =F12 -> 17270000 | G11: 14320000 | H11: =F11-G11 -> 2950000
E12: 01 직접관리비수익 | F12: =G12+1000000+1700000+250000 -> 17270000 | G12: =1000000+3380000+600000+270000+5500000+1200000+300000+90000+390000+1200000+390000 -> 14320000 | H12: =F12-G12 -> 2950000
D13: 624 입장료수익 | F13: =F14 -> 6600000 | G13: 6600000 | H13: =F13-G13 -> 0
E14: 01 입장료수익 | F14: 6600000 | G14: 6600000 | H14: =F14-G14 -> 0
D15: 647 기부금수익 | F15: =F16 -> 689000 | G15: 689000 | H15: =F15-G15 -> 0
E16: 01 기부금수익 | F16: 689000 | G16: 689000 | H16: =F16-G16 -> 0
D17: 648 출연금 수익 | F17: =F18 -> 1245100 | G17: 1245100 | H17: =F17-G17 -> 0
E18: 02 자치단체출연금수익 | F18: 1245100 | G18: 1245100 | H18: =F18-G18 -> 0
D19: 649 후원금 수익 | F19: =F20 -> 410000 | G19: 410000 | H19: =F19-G19 -> 0
E20: 01 지정후원금수익 | F20: 410000 | G20: 410000 | H20: =F20-G20 -> 0
D21: 661 기타영업수익 | F21: =F22 -> 628000 | G21: 628000 | H21: =F21-G21 -> 0
E22: 05 부대시설임대수익 | F22: 628000 | G22: 628000 | H22: =F22-G22 -> 0
C23: 670 영업외수익 | F23: =F24+F26 -> 257781 | G23: 0 | H23: =F23-G23 -> 257781
D24: 671 이자수익 | F24: =F25 -> 200000 | G24: 0 | H24: =F24-G24 -> 200000
E25: 01 예금이자수익 | F25: 200000 | G25: 0 | H25: =F25-G25 -> 200000
D26: 679 기타영업외수익 | F26: =F27 -> 57781 | G26: 0 | H26: =F26-G26 -> 57781
E27: 09 기타영업외수익 | F27: =41680+16101 -> 57781 | G27: 0 | H27: =F27-G27 -> 57781
B28: 100 자본적수입 | F28: =F29+F32 -> 6579697 | G28: 6138047 | H28: =F28-G28 -> 441650
C29: 170 자본잉여금수입 | F29: =F30 -> 3233000 | G29: 3233000 | H29: =F29-G29 -> 0
D30: 177 출연금 수입 | F30: =F31 -> 3233000 | G30: 3233000 | H30: =F30-G30 -> 0
E31: 01 정부출연금 | F31: 3233000 | G31: 3233000 | H31: =F31-G31 -> 0
C32: 180 유보자금 | F32: =F33 -> 3346697 | G32: 2905047 | H32: =F32-G32 -> 441650
D33: 181 순세계잉여금 | F33: =F34+F35 -> 3346697 | G33: 2905047 | H33: =F33-G33 -> 441650
E34: 01 순세계잉여금 | F34: =2905047+441650 -> 3346697 | G34: 2905047 | H34: =F34-G34 -> 441650
E35: 03 대행사업비 사용잔액 | F35: 0 | G35: 0 | H35: =F35-G35 -> 0

Sheet 지출예산 총괄표
A1: 지출예산 총괄표(출연금+위탁사업비)
I2: (단위 : 천 원)
A3: 과 목 | G3: 경정액 (A) | H3: 기정액(본예산) (B) | I3: 비교증감
A4: 구분 | B4: 정책사업
A5: 총계(직접사업비+위탁사업비) | G5: =G6+G23 -> 33799578 | H5: 30150147 | I5: =G5-H5 -> 3649431
A6: 직접사업비(사업예산+자본예산) | G6: =SUM(G7,G18) -> 16529578 | H6: 15830147 | I6: =G6-H6 -> 699431
A7: 사업예산 | G7: =SUM(G8:G17) -> 12980477 | H7: 9597147 | I7: =G7-H7 -> 3383330
B8: 2026여수세계섬박람회 종합상황실 | G8: =종합상황실!H5 -> 21920 | H8: 16292 | I8: =G8-H8 -> 5628
B9: 2026여수세계섬박람회 행정관리 | G9: =행정관리부!H5 -> 1092031 | H9: 974983 | I9: =G9-H9 -> 117048
B10: 2026여수세계섬박람회 기획홍보 | G10: =기획홍보부!H5 -> 225012 | H10: 170012 | I10: =G10-H10 -> 55000
B11: 2026여수세계섬박람회 수익사업 | G11: =수익사업부!H5 -> 232436 | H11: 197636 | I11: =G11-H11 -> 34800
B12: 2026여수세계섬박람회 유치협력 | G12: =유치협력부!H5 -> 308648 | H12: 47440 | I12: =G12-H12 -> 261208
B13: 2026여수세계섬박람회 운영 | G13: =운영부!H5 -> 3868944 | H13: 3686944 | I13: =G13-H13 -> 182000
B14: 2026여수세계섬박람회 행사 | G14: =행사부!H5 -> 96648 | H14: 20648 | I14: =G14-H14 -> 76000
B15: 2026여수세계섬박람회 시설조성 | G15: =시설조성부!H5 -> 1823648 | H15: 1765648 | I15: =G15-H15 -> 58000
B16: 2026여수세계섬박람회 전시연출 | G16: =전시연출부!H5 -> 2121344 | H16: 2121344 | I16: =G16-H16 -> 0
B17: 예비비 | G17: =예비비!H5 -> 3189846 | H17: 596200 | I17: =G17-H17 -> 2593646
A18: 자본예산 | G18: =시설조성부!H38 -> 3549101 | H18: 6233000 | I18: =G18-H18 -> -2683899
B19: 2026여수세계섬박람회 조성연출 | G19: =시설조성부!H39 -> 3249101 | H19: 3233000 | I19: =G19-H19 -> 16101
B20: 섬박람회 랜드마크 조성사업(수익) | G20: =시설조성부!H48 -> 0 | H20: 1000000 | I20: =G20-H20 -> -1000000
B21: 섬박람회 안전시설물 설치사업(수익) | G21: =시설조성부!H57 -> 300000 | H21: 2000000 | I21: =G21-H21 -> -1700000
B22: 예비비(자본) | G22: =예비비!H21 -> 0 | H22: 0 | I22: =G22-H22 -> 0
A23: 위탁사업비(사업예산+자본예산) | G23: =G24+G28 -> 17270000 | H23: 14320000 | I23: =G23-H23 -> 2950000
A24: 사업예산 | G24: =SUM(G25:G27) -> 11000000 | H24: 10750000 | I24: =G24-H24 -> 250000
B25: 2026여수세계섬박람회 기획홍보(위탁) | G25: ='기획본부(위탁)'!H6 -> 1000000 | H25: 1000000 | I25: =G25-H25 -> 0
B26: 2026여수세계섬박람회 유치협력(위탁) | G26: ='기획본부(위탁)'!H30 -> 4500000 | H26: 4250000 | I26: =G26-H26 -> 250000
B27: 2026여수세계섬박람회 행사(위탁) | G27: ='운영본부(위탁)'!H6 -> 5500000 | H27: 5500000 | I27: =G27-H27 -> 0
A28: 자본예산 | G28: =SUM(G29:G30) -> 6270000 | H28: 3570000 | I28: =G28-H28 -> 2700000
B29: 2026여수세계섬박람회 시설조성(위탁) | G29: ='운영본부(위탁)'!H14 -> 4680000 | H29: 1980000 | I29: =G29-H29 -> 2700000
B30: 2026여수세계섬박람회 전시연출(위탁) | G30: ='운영본부(위탁)'!H43 -> 1590000 | H30: 1590000 | I30: =G30-H30 -> 0

Sheet 지출예산(직접)
A1: 지출예산 총괄표
I2: (단위 : 천 원)
A3: 과 목 | G3: 경정액 (A) | H3: 기정액(본예산) (B) | I3: 비교증감 (A-B)
A4: 구분 | B4: 정책사업 | C4: 단위사업 | D4: 세부사업 | E4: 목 | F4: 세목
A5: 총계 | G5: =G6+G237 -> 16529578 | H5: =SUM(H6,H237) -> 15830147 | I5: =G5-H5 -> 699431
A6: 사업예산 | G6: =SUM(G24,G57,G95,G125,G153,G172,G188,G208,G7,G230) -> 12980477 | H6: 9597147 | I6: =G6-H6 -> 3383330
B7: 2026여수세계섬박람회 종합상황실 | G7: =종합상황실!H4 -> 21920 | H7: 16292 | I7: =G7-H7 -> 5628
C8: 종합상황실 시설운영 | G8: =종합상황실!H7 -> 3500 | H8: 0 | I8: =G8-H8 -> 3500
D9: 종합상황실 시설운영 | G9: =종합상황실!H8 -> 3500 | H9: 0 | I9: =G9-H9 -> 3500
E10: 일반운영비 | G10: =종합상황실!H10 -> 3500 | H10: 0 | I10: =G10-H10 -> 3500
F11: 사무관리비 | G11: =종합상황실!H11 -> 3500 | H11: 0 | I11: =G11-H11 -> 3500
C12: 종합상황실 부서운영 | G12: =종합상황실!H15 -> 18420 | H12: 16292 | I12: =G12-H12 -> 2128
D13: 기본경비 | G13: =종합상황실!H16 -> 18420 | H13: 16292 | I13: =G13-H13 -> 2128
E14: 일반운영비 | G14: =종합상황실!H18 -> 6320 | H14: 4592 | I14: =G14-H14 -> 1728
F15: 사무관리비 | G15: =종합상황실!H19 -> 2000 | H15: 2000 | I15: =G15-H15 -> 0
F16: 복리후생비 | G16: =종합상황실!H21 -> 4320 | H16: 2592 | I16: =G16-H16 -> 1728
E17: 여비 | G17: =종합상황실!H25 -> 9000 | H17: 9000 | I17: =G17-H17 -> 0
F18: 국내여비 | G18: =종합상황실!H26 -> 9000 | H18: 9000 | I18: =G18-H18 -> 0
E19: 업무추진비 | G19: =종합상황실!H29 -> 1500 | H19: 1500 | I19: =G19-H19 -> 0
F20: 사업업무추진비 | G20: =종합상황실!H30 -> 1500 | H20: 1500 | I20: =G20-H20 -> 0
E21: 관서업무비 | G21: =종합상황실!H32 -> 1600 | H21: 1200 | I21: =G21-H21 -> 400
F22: 정원가산업무비 | G22: =종합상황실!H33 -> 400 | H22: 0 | I22: =G22-H22 -> 400
F23: 부서운영비 | G23: =종합상황실!H36 -> 1200 | H23: 1200 | I23: =G23-H23 -> 0
B24: 2026여수세계섬박람회 행정관리 | G24: =SUM(G25,G30) -> 1092031 | H24: 974983 | I24: =G24-H24 -> 117048
C25: 2026여수세계섬박람회 행정 업무추진 | G25: =SUM(,G26) -> 26100 | H25: 26100 | I25: =G25-H25 -> 0
D26: 이사회 및 각종 위원회 운영 | G26: =G27 -> 26100 | H26: 26100 | I26: =G26-H26 -> 0
E27: 일반운영비 | G27: =행정관리부!H10 -> 26100 | H27: 26100 | I27: =G27-H27 -> 0
F28: 사무관리비 | G28: =행정관리부!H11 -> 24900 | H28: 24900 | I28: =G28-H28 -> 0
F29: 회의비 | G29: =행정관리부!H19 -> 1200 | H29: 1200 | I29: =G29-H29 -> 0
C30: 사무국운영 | G30: =G31 -> 1065931 | H30: 948883 | I30: =G30-H30 -> 117048
D31: 기본경비 | G31: =SUM(G32,G36,G38,G43,G45,G47,G50,G52,G55) -> 1065931 | H31: 948883 | I31: =G31-H31 -> 117048
E32: 인건비 | G32: =행정관리부!H24 -> 652637 | H32: 651710 | I32: =G32-H32 -> 927
F33: 보수 | G33: =행정관리부!H25 -> 402600 | H33: 402600 | I33: =G33-H33 -> 0
F34: 기타직보수 | G34: =행정관리부!H30 -> 220208 | H34: 219281 | I34: =G34-H34 -> 927
F35: 기간제근로자등보수 | G35: =행정관리부!H39 -> 29829 | H35: 29829 | I35: =G35-H35 -> 0
E36: 퇴직급여 | G36: =행정관리부!H43 -> 52200 | H36: 52200 | I36: =G36-H36 -> 0
F37: 퇴직급여충당금 | G37: =행정관리부!H44 -> 52200 | H37: 52200 | I37: =G37-H37 -> 0
E38: 일반운영비 | G38: =행정관리부!H49 -> 233980 | H38: 137760 | I38: =G38-H38 -> 96220
F39: 사무관리비 | G39: =행정관리부!H50 -> 153220 | H39: 82220 | I39: =G39-H39 -> 71000
F40: 공공운영비 | G40: =행정관리부!H71 -> 35460 | H40: 35460 | I40: =G40-H40 -> 0
...

Sheet 종합상황실
A1: 지출예산(세부사업) - 종합상황실 | M1: 단위 : 천원
A2: 구 분 | B2: 사업 | E2: 편성목 | H2: 경정액 (A) | I2: 기정액(본예산) (B) | J2: 비교증감 (A-B) | K2: 산 출 기 초
B3: 정책 | C3: 단위 | D3: 세부 | E3: 그룹 | F3: 목 | G3: 세목
A4: 총계(사업예산 + 자본예산) | H4: =H5 -> 21920 | I4: 16292 | J4: =H4-I4 -> 5628
A5: 사업예산 | H5: =H6 -> 21920 | I5: 16292 | J5: =H5-I5 -> 5628
B6: 2026여수세계섬박람회 종합상황실 | H6: =SUM(H7,H15) -> 21920 | I6: 16292 | J6: =H6-I6 -> 5628
C7: 종합상황실 시설운영 | H7: =H8 -> 3500 | I7: 0 | J7: =H7-I7 -> 3500
D8: 종합상황실 시설운영 | H8: =H9 -> 3500 | I8: 0 | J8: =H8-I8 -> 3500
E9: 200 물건비 | H9: =H10 -> 3500 | I9: 0 | J9: =H9-I9 -> 3500
F10: 201 일반운영비 | H10: =H11 -> 3500 | I10: 0 | J10: =H10-I10 -> 3500
G11: 01 사무관리비 | H11: =M11 -> 3500 | I11: 0 | J11: =H11-I11 -> 3500 | K11: [일반수용비] | M11: =SUM(M13,M14) -> 3500
G12: [사업수익 3,500] | K12: 추경1회
K13: ○ 콜센터 대표회선 운영 : 2,000,000원*1식 | L13: = | M13: 2000
K14: ○ 전자상황판 운영 : 750,000원*2월 | L14: = | M14: 1500
C15: 종합상황실 부서운영 | H15: =H16 -> 18420 | I15: 16292 | J15: =H15-I15 -> 2128
D16: 기본경비 | H16: =H17 -> 18420 | I16: 16292 | J16: =H16-I16 -> 2128
E17: 200 물건비 | H17: =SUM(H18,H25,H29,H32) -> 18420 | I17: 16292 | J17: =H17-I17 -> 2128
F18: 201 일반운영비 | H18: =SUM(H19,H21) -> 6320 | I18: 4592 | J18: =H18-I18 -> 1728
G19: 01 사무관리비 | H19: =M19 -> 2000 | I19: 2000 | J19: =H19-I19 -> 0 | K19: [일반수용비] | M19: =SUM(M20:M20) -> 2000
K20: ○ 부서운영을 위한 소모품 구입 : 200,000원*10월 | L20: = | M20: 2000
G21: 15 복리후생비 | H21: =M21 -> 4320 | I21: 2592 | J21: =H21-I21 -> 1728 | K21: [급량비] | M21: =M24 -> 4320
K22: ○ 기본업무수행 급량비 : 9,000원*3명*8일*12월 | L22: = | M22: 2592
K23: 추경1회
K24: ○ 기본업무수행 급량비 : 경정 4,320,000원 | L24: = | M24: 4320
F25: 202 여비 | H25: =H26 -> 9000 | I25: 9000 | J25: =H25-I25 -> 0
G26: 01 국내여비 | H26: =M26 -> 9000 | I26: 9000 | J26: =H26-I26 -> 0 | K26: [국내여비] | M26: =SUM(M27:M28) -> 9000
K27: ○ 종합상황실 기본업무 수행 관내여비 : 20,000원*6명*2일*10월 | L27: = | M27: 2400
K28: ○ 종합상황실 기본업무 수행 관외여비 : 110,000원*6명*10월 | L28: = | M28: 6600
F29: 203 업무추진비 | H29: =H30 -> 1500 | I29: 1500 | J29: =H29-I29 -> 0
G30: 07 사업업무추진비 | H30: =M30 -> 1500 | I30: 1500 | J30: =H30-I30 -> 0 | K30: [시책추진업무추진비] | M30: =SUM(M31) -> 1500
K31: ○ 종합상황실 업무추진 : 1,500,000원*1식 | L31: = | M31: 1500
F32: 217 관서업무비 | H32: =SUM(H33,H36) -> 1600 | I32: 1200 | J32: =H32-I32 -> 400
G33: 01 정원가산업무비 | H33: =M33 -> 400 | I33: 0 | J33: =H33-I33 -> 400 | K33: [정원가산업무비] | M33: =M35 -> 400
K34: 추경1회
K35: ○ 종합상황실 정원가산 총액계상 : 80,000원*5명 | L35: = | M35: 400
G36: 02 부서업무비 | H36: =M36 -> 1200 | I36: 1200 | J36: =H36-I36 -> 0 | K36: [부서업무비] | M36: =M37 -> 1200
K37: ○ 종합상황실 부서운영 총액계상 : 100,000원*12월 | L37: = | M37: 1200

Sheet 행정관리부
A1: 지출예산(세부사업) - 행정관리부 | M1: 단위 : 천원
A2: 구 분 | B2: 사업 | E2: 편성목 | H2: 경정액 (A) | I2: 기정액(본예산) (B) | J2: 비교증감 (A-B) | K2: 산 출 기 초
B3: 정책 | C3: 단위 | D3: 세부 | E3: 그룹 | F3: 목 | G3: 세목
A4: 총계(사업예산 + 자본예산) | H4: =H5 -> 1092031 | I4: 974983 | J4: =H4-I4 -> 117048
A5: 사업예산 | H5: =H6 -> 1092031 | I5: 974983 | J5: =H5-I5 -> 117048
B6: 2026여수세계섬박람회 행정관리 | H6: =SUM(H7,H21) -> 1092031 | I6: 974983 | J6: =H6-I6 -> 117048
C7: 2026여수세계섬박람회 행정 업무추진 | H7: =H8 -> 26100 | I7: 26100 | J7: =H7-I7 -> 0
D8: 이사회 및 각종 위원회 운영 | H8: =H9 -> 26100 | I8: 26100 | J8: =H8-I8 -> 0
E9: 200 물건비 | H9: =H10 -> 26100 | I9: 26100 | J9: =H9-I9 -> 0
F10: 201 일반운영비 | H10: =SUM(H11,H19) -> 26100 | I10: 26100 | J10: =H10-I10 -> 0
G11: 01 사무관리비 | H11: =SUM(M11,M13,M17) -> 24900 | I11: 24900 | J11: =H11-I11 -> 0 | K11: [일반수용비] | M11: =SUM(M12:M12) -> 800
K12: ○ 변경등기 수수료 : 200,000원*4회 | L12: = | M12: 800
K13: [운영수당] | M13: =SUM(M14:M16) -> 21300
K14: ○ 이사회 참석수당 : 150,000원*12명*7회 | L14: = | M14: 12600
K15: ○ 이사회 참석자 실비보상 : 100,000원*12명*7회 | L15: = | M15: 8400
K16: ○ 인사위원회 위원 참석수당 : 100,000원*3명*1회 | L16: = | M16: 300
K17: [임차료] | M17: =M18 -> 2800
K18: ○ 회의실 임차료 : 400,000원*7회 | L18: = | M18: 2800
G19: 14 회의비 | H19: =M19 -> 1200 | I19: 1200 | J19: =H19-I19 -> 0 | K19: [회의비] | M19: =M20 -> 1200
K20: ○ 이사회 등 회의 운영비 : 400,000원*3회 | L20: = | M20: 1200
C21: 사무국운영 | H21: =H22 -> 1065931 | I21: 948883 | J21: =H21-I21 -> 117048
D22: 기본경비 | H22: =SUM(H23,H48,H119) -> 1065931 | I22: 948883 | J22: =H22-I22 -> 117048
E23: 100 인건비 | H23: =SUM(H24,H43) -> 704837 | I23: 703910 | J23: =H23-I23 -> 927
F24: 101 인건비 | H24: =SUM(H25,H30,H39) -> 652637 | I24: 651710 | J24: =H24-I24 -> 927
G25: 01 보수 | H25: =SUM(M25,M28) -> 402600 | I25: 402600 | J25: =H25-I25 -> 0 | K25: [직원파견수당] | M25: =SUM(M26:M27) -> 303600
K26: ○ 4급이상 : 600,000원*2명*11월 | L26: = | M26: 13200
K27: ○ 5급이하 : 400,000원*66명*11월 | L27: = | M27: 290400
K28: [주거지원비] | M28: =M29 -> 99000
K29: ○ 타시군(도) 주거지원비 : 500,000원*18명*11월 | L29: = | M29: 99000
G30: 02 기타직 보수 | H30: =SUM(M30,M36) -> 220208 | I30: 219281 | J30: =H30-I30 -> 927 | K30: [사무총장] | M30: =SUM(M34:M35) -> 98208
K31: ○ 연봉 : 8,468,460원*11월 | L31: = | M31: 93154
K32: ○ 연차수당 : 8,468,460원*86%*1/30*17일 | L32: = | M32: 4127
K33: 추경1회
K34: ○ 연봉 : 경정 94,041,000원 | L34: = | M34: 94041
K35: ○ 연차수당 : 경정 4,167,000원 | L35: = | M35: 4167
K36: [총감독 급여] | M36: =SUM(M37:M38) -> 122000
K37: ○ 비상임 급여 : 7,000,000원*2월 | L37: = | M37: 14000
K38: ○ 월급여 : 12,000,000원*9월 | L38: = | M38: 108000
G39: 04 기간제근로자등보수 | H39: =M39 -> 29829 | I39: 29829 | J39: =H39-I39 -> 0 | K39: [본부장실 관리요원] | M39: =SUM(M40:M42) -> 29829
K40: ○ 인부임 : 98,440원*1명*22일*11월 | L40: = | M40: 23823
...

Sheet 기획홍보부
A1: 지출예산(세부사업) - 기획홍보부 | M1: 단위 : 천원
A2: 구 분 | B2: 사업 | E2: 편성목 | H2: 경정액 (A) | I2: 기정액(본예산) (B) | J2: 비교증감 (A-B) | K2: 산 출 기 초
B3: 정책 | C3: 단위 | D3: 세부 | E3: 그룹 | F3: 목 | G3: 세목
A4: 총계(사업예산 + 자본예산) | H4: =H5 -> 225012 | I4: 170012 | J4: =H4-I4 -> 55000
A5: 사업예산 | H5: =H6 -> 225012 | I5: 170012 | J5: =H5-I5 -> 55000
B6: 2026여수세계섬박람회 기획홍보 | H6: =SUM(H7,H25,H36,H54) -> 225012 | I6: 170012 | J6: =H6-I6 -> 55000
C7: 2026여수세계섬박람회 기획 | H7: =H8+H16 -> 75200 | I7: 20200 | J7: =H7-I7 -> 55000
D8: 박람회 기획 | H8: =SUM(H9) -> 60000 | I8: 5000 | J8: =H8-I8 -> 55000
E9: 200 물건비 | H9: =SUM(H10) -> 60000 | I9: 5000 | J9: =H9-I9 -> 55000
F10: 201 일반운영비 | H10: =H11 -> 60000 | I10: 5000 | J10: =H10-I10 -> 55000
G11: 01 사무관리비 | H11: =M11 -> 60000 | I11: 5000 | J11: =H11-I11 -> 55000 | K11: [일반수용비] | M11: =SUM(M14:M15) -> 60000
K12: ○ 추진상황 보고 PPT 제작 : 2,500,000원*2회 | L12: = | M12: 5000
K13: 추경1회
K14: ○ 추진상황 보고 PPT 제작 : 경정 10,000,000원 | L14: = | M14: 10000
K15: ○ 섬박람회 백서 제작 용역 50,000,000원*1식 | L15: = | M15: 50000
D16: 자문위원회 운영 | H16: =H17 -> 15200 | I16: 15200 | J16: =H16-I16 -> 0
E17: 200 물건비 | H17: =SUM(H18) -> 15200 | I17: 15200 | J17: =H17-I17 -> 0
F18: 201 일반운영비 | H18: =SUM(H19,H23) -> 15200 | I18: 15200 | J18: =H18-I18 -> 0
G19: 01 사무관리비 | H19: =M19 -> 15000 | I19: 15000 | J19: =H19-I19 -> 0 | K19: [운영수당] | M19: =SUM(M20:M22) -> 15000
K20: ○ 자문위원회 자문수당(대면) : 150,000원*2회*25명 | L20: = | M20: 7500
K21: ○ 자문위원회 자문수당(서면) : 100,000원*2회*25명 | L21: = | M21: 5000
K22: ○ 자문위원회 참석자 실비 보상 : 2,500,000원*1식 | L22: = | M22: 2500
G23: 14 회의비 | H23: =M23 -> 200 | I23: 200 | J23: =H23-I23 -> 0 | K23: [회의비] | M23: =M24 -> 200
K24: ○ 자문위원회 회의 운영비 : 100,000원*2회 | L24: = | M24: 200
C25: 2026여수세계섬박람회 홍보 | H25: =SUM(H26,H31) -> 53300 | I25: 53300 | J25: =H25-I25 -> 0
D26: 홈페이지 유지관리 | H26: =H27 -> 50000 | I26: 50000 | J26: =H26-I26 -> 0
E27: 200 물건비 | H27: =H28 -> 50000 | I27: 50000 | J27: =H27-I27 -> 0
F28: 214 수선유지교체비 | H28: =H29 -> 50000 | I28: 50000 | J28: =H28-I28 -> 0
G29: 05 수선유지비 | H29: =M29 -> 50000 | I29: 50000 | J29: =H29-I29 -> 0 | K29: [수선유지비] | M29: =SUM(M30:M30) -> 50000
K30: ○ 누리집 유지관리 용역 : 50,000,000원*1식 | L30: = | M30: 50000
D31: 박람회 홍보 | H31: =SUM(H32) -> 3300 | I31: 3300 | J31: =H31-I31 -> 0
E32: 200 물건비 | H32: =H33 -> 3300 | I32: 3300 | J32: =H32-I32 -> 0
F33: 202 여비 | H33: =H34 -> 3300 | I33: 3300 | J33: =H33-I33 -> 0
G34: 01 국내여비 | H34: =M34 -> 3300 | I34: 3300 | J34: =H34-I34 -> 0 | K34: [국내여비] | M34: =SUM(M35:M35) -> 3300
K35: ○ 박람회 홍보 관외여비 110,000원*2명*3일*5월 | L35: = | M35: 3300
C36: 기획홍보부 부서운영 | H36: =H37 -> 21512 | I36: 21512 | J36: =H36-I36 -> 0
D37: 기본경비 | H37: =H38 -> 21512 | I37: 21512 | J37: =H37-I37 -> 0
E38: 200 물건비 | H38: =SUM(H39,H44,H48,H51) -> 21512 | I38: 21512 | J38: =H38-I38 -> 0
F39: 201 일반운영비 | H39: =H40+H42 -> 8912 | I39: 8912 | J39: =H39-I39 -> 0
G40: 01 사무관리비 | H40: =M40 -> 2000 | I40: 2000 | J40: =H40-I40 -> 0 | K40: [일반수용비] | M40: =SUM(M41:M41) -> 2000
...

Sheet 수익사업부
A1: 지출예산(세부사업) - 수익사업부 | M1: 단위 : 천원
A2: 구 분 | B2: 사업 | E2: 편성목 | H2: 경정액 (A) | I2: 기정액(본예산) (B) | J2: 비교증감 (A-B) | K2: 산 출 기 초
B3: 정책 | C3: 단위 | D3: 세부 | E3: 그룹 | F3: 목 | G3: 세목
A4: 총계(사업예산 + 자본예산) | H4: =H5 -> 232436 | I4: 197636 | J4: =H4-I4 -> 34800
A5: 사업예산 | H5: =H6 -> 232436 | I5: 197636 | J5: =H5-I5 -> 34800
B6: 2026여수세계섬박람회 수익사업 | H6: =SUM(H7,H52) -> 232436 | I6: 197636 | J6: =H6-I6 -> 34800
C7: 2026여수세계섬박람회 수익사업 | H7: =SUM(H8,,H21,H35,H40) -> 207060 | I7: 174760 | J7: =H7-I7 -> 32300
D8: 박람회 휘장업무 추진 | H8: =H9 -> 8100 | I8: 11300 | J8: =H8-I8 -> -3200
E9: 200 물건비 | H9: =H10 -> 8100 | I9: 11300 | J9: =H9-I9 -> -3200
F10: 201 일반운영비 | H10: =H11 -> 8100 | I10: 11300 | J10: =H10-I10 -> -3200
G11: 01 사무관리비 | H11: =SUM(M11,M15) -> 8100 | I11: 11300 | J11: =H11-I11 -> -3200 | K11: [일반수용비] | M11: =SUM(M12:M14) -> 8100
K12: ○ 후원 유치를 위한 홍보물 등 제작 : 4,000,000원*1식 | L12: = | M12: 4000
K13: ○ 휘장업무 추진 사무용품 등 구입 : 110,000원*10월 | L13: = | M13: 1100 | N13: ○ 직원 병가 및 휴직 등 공백발생 시 채용(인건비 23년 기준)
K14: ○ 후원 관련 협약식 등 소모품 구입 : 500,000원*6회 | L14: = | M14: 3000
K15: [운영수당] | M15: =SUM(M19:M20) -> 0
K16: ○ 공식공급권자 선정 심사수당 : 250,000원*10명*1회 | L16: = | M16: 2500
K17: ○ 공식공급권자 선정 심사위원 교통비 등 기타실비 : 700,000원*1식 | L17: = | M17: 700
K18: 추경1회
K19: ○ 공식공급권자 선정 심사수당 : 경정 0원 | L19: = | M19: 0
K20: ○ 공식공급권자 선정 심사위원 교통비 등 기타실비 : 경정 0원 | L20: = | M20: 0
D21: 박람회 입장권 사업 | H21: =SUM(H22,H31) -> 63460 | I21: 63460 | J21: =H21-I21 -> 0
E22: 200 물건비 | H22: =SUM(H23,H28) -> 23460 | I22: 23460 | J22: =H22-I22 -> 0
F23: 201 일반운영비 | H23: =H24 -> 20160 | I23: 20160 | J23: =H23-I23 -> 0
G24: 01 사무관리비 | H24: =M24 -> 20160 | I24: 20160 | J24: =H24-I24 -> 0 | K24: [일반수용비] | M24: =SUM(M25:M27) -> 20160
K25: ○ 입장권 판촉 홍보물 제작 : 15,000,000원*1식 | L25: = | M25: 15000
K26: ○ 입장권 제휴 할인 홍보물 제작 : 3,000,000원*1식 | L26: = | M26: 3000
K27: ○ 입장권 사업 추진 사무용품 구입 : 216,000원*10월 | L27: = | M27: 2160
F28: 202 여비 | H28: =H29 -> 3300 | I28: 3300 | J28: =H28-I28 -> 0
G29: 01 국내여비 | H29: =M29 -> 3300 | I29: 3300 | J29: =H29-I29 -> 0 | K29: [국내여비] | M29: =SUM(M30:M31) -> 3300
K30: ○ 입장권 판촉활동 등 관외여비 : 110,000원*2명*3일*5월 | L30: = | M30: 3300 | N30: ○ 한글 250천원, ms오피스 420천원 | P30: 670000 | Q30: 1 | R30: 1
E31: 300 경상이전 | H31: =H32 -> 40000 | I31: 40000 | J31: =H31-I31 -> 0
F32: 301 일반보상금 | H32: =H33 -> 40000 | I32: 40000 | J32: =H32-I32 -> 0
G33: 14 기타보상금 | H33: =M33 -> 40000 | I33: 40000 | J33: =H33-I33 -> 0 | K33: [기타보상금] | M33: =M34 -> 40000
K34: ○ 입장권 구매보상금 지급 : 40,000,000원*1식 | L34: = | M34: 40000
D35: 박람회 굿즈 제작 | H35: =SUM(H36) -> 100000 | I35: 100000 | J35: =H35-I35 -> 0
E36: 200 물건비 | H36: =SUM(H37) -> 100000 | I36: 100000 | J36: =H36-I36 -> 0
F37: 201 일반운영비 | H37: =H38 -> 100000 | I37: 100000 | J37: =H37-I37 -> 0
G38: 01 사무관리비 | H38: =M38 -> 100000 | I38: 100000 | J38: =H38-I38 -> 0 | K38: [일반수용비] | M38: =SUM(M39:M39) -> 100000
K39: ○ 박람회 굿즈 제작 100,000,000원*1식 | L39: = | M39: 100000
D40: 기타 수익사업 | H40: =SUM(H41) -> 35500 | I40: 0 | J40: =H40-I40 -> 35500
...

Sheet 유치협력부
A1: 지출예산(세부사업) - 유치협력부 | M1: 단위 : 천원
A2: 구 분 | B2: 사업 | E2: 편성목 | H2: 경정액 (A) | I2: 기정액(본예산) (B) | J2: 비교증감 (A-B) | K2: 산 출 기 초
B3: 정책 | C3: 단위 | D3: 세부 | E3: 그룹 | F3: 목 | G3: 세목
A4: 총계(사업예산 + 자본예산) | H4: =H5 -> 308648 | I4: 47440 | J4: =H4-I4 -> 261208
A5: 사업예산 | H5: =H6 -> 308648 | I5: 47440 | J5: =H5-I5 -> 261208
B6: 2026여수세계섬박람회 유치협력 | H6: =SUM(H7,H35) -> 308648 | I6: 47440 | J6: =H6-I6 -> 261208
C7: 2026여수세계섬박람회 유치 | H7: =SUM(H8,H18,H23,H29) -> 287508 | I7: 26300 | J7: =H7-I7 -> 261208
D8: 국가기업 등 유치 | H8: =H9 -> 26300 | I8: 26300 | J8: =H8-I8 -> 0
E9: 200 물건비 | H9: =SUM(H10,H13) -> 26300 | I9: 26300 | J9: =H9-I9 -> 0
F10: 201 일반운영비 | H10: =H11 -> 5000 | I10: 5000 | J10: =H10-I10 -> 0
G11: 02 공공운영비 | H11: =M11 -> 5000 | I11: 5000 | J11: =H11-I11 -> 0 | K11: [우편료] | M11: =SUM(M12:M12) -> 5000
K12: ○ 국내·외 관람객 홍보물 등 발송 우편료 : 2,500원*2,000개소 | L12: = | M12: 5000
F13: 202 여비 | H13: =SUM(H14,H16) -> 21300 | I13: 21300 | J13: =H13-I13 -> 0
G14: 01 국내여비 | H14: =M14 -> 3300 | I14: 3300 | J14: =H14-I14 -> 0 | K14: [국내여비] | M14: =M15 -> 3300
K15: ○ 국가·기업 등 유치활동을 위한 관외여비 : 110,000원*2명*3일*5월 | L15: = | M15: 3300 | AC15: 9
G16: 03 국외업무여비 | H16: =M16 -> 18000 | I16: 18000 | J16: =H16-I16 -> 0 | K16: [국외업무여비] | M16: =M17 -> 18000
K17: ○ 국제교류 등 각종 국제행사 참가 : 3,000,000원*2명*3회 | L17: = | M17: 18000 | AC17: 9
D18: 학술회의 유치 | H18: =H19 -> 1208 | I18: 0 | J18: =H18-I18 -> 1208
E19: 770 영업외비용 | H19: =H20 -> 1208 | I19: 0 | J19: =H19-I19 -> 1208
F20: 751 반환금 | H20: =H21 -> 1208 | I20: 0 | J20: =H20-I20 -> 1208
G21: 04 대행사업비반환금 | H21: =M21 -> 1208 | I21: 0 | J21: =H21-I21 -> 1208 | K21: 추경1회 | M21: =SUM(M22:M22) -> 1208
G22: [영업외수익 1,208] | K22: ○ 2025국제섬포럼 in YEOSU 이자발생액 반납 1,207,700원*1식 | L22: = | M22: 1208
D23: 기업관 부스 운영(자체) | H23: =H24 -> 50000 | I23: 0 | J23: =H23-I23 -> 50000
E24: 200 물건비 | H24: =H25 -> 50000 | I24: 0 | J24: =H24-I24 -> 50000
F25: 201 일반운영비 | H25: =SUM(H26) -> 50000 | I25: 0 | J25: =H25-I25 -> 50000
G26: 03 행사운영비 | H26: =SUM(M26) -> 50000 | I26: 0 | J26: =H26-I26 -> 50000 | K26: [행사운영비] | M26: =SUM(M28:M28) -> 50000
K27: 추경1회
K28: ○ 기업관 부스 운영 인력지원 등 : 50,000,000원*1식 | L28: = | M28: 50000
D29: 참가국 지원(자체) | H29: =H30 -> 210000 | I29: 0 | J29: =H29-I29 -> 210000
E30: 200 물건비 | H30: =H31 -> 210000 | I30: 0 | J30: =H30-I30 -> 210000
F31: 201 일반운영비 | H31: =SUM(H32) -> 210000 | I31: 0 | J31: =H31-I31 -> 210000
G32: 03 행사운영비 | H32: =SUM(M32) -> 210000 | I32: 0 | J32: =H32-I32 -> 210000 | K32: [행사운영비] | M32: =SUM(M34:M34) -> 210000
K33: 추경1회
K34: ○ 참가국, 기업 유치 및 운영 : 210,000,000원*1식 | L34: = | M34: 210000
C35: 유치협력부 부서운영 | H35: =H36 -> 21140 | I35: 21140 | J35: =H35-I35 -> 0
D36: 기본경비 | H36: =H37 -> 21140 | I36: 21140 | J36: =H36-I36 -> 0
E37: 200 물건비 | H37: =SUM(H38,H43,H47,H51) -> 21140 | I37: 21140 | J37: =H37-I37 -> 0
F38: 201 일반운영비 | H38: =SUM(H39,H41) -> 7040 | I38: 7040 | J38: =H38-I38 -> 0
G39: 01 사무관리비 | H39: =M39 -> 2000 | I39: 2000 | J39: =H39-I39 -> 0 | K39: [일반수용비] | M39: =SUM(M40:M40) -> 2000
K40: ○ 부서 운영을 위한 소모품 구입 : 200,000원*10월 | L40: = | M40: 2000
...

Sheet 운영부
A1: 지출예산(세부사업) - 운영부 | M1: 단위 : 천원
A2: 구 분 | B2: 사업 | E2: 편성목 | H2: 경정액 (A) | I2: 기정액(본예산) (B) | J2: 비교증감 (A-B) | K2: 산 출 기 초
B3: 정책 | C3: 단위 | D3: 세부 | E3: 그룹 | F3: 목 | G3: 세목
A4: 총계(사업예산 + 자본예산) | H4: =H5 -> 3868944 | I4: 3686944 | J4: =H4-I4 -> 182000
A5: 사업예산 | H5: =H6 -> 3868944 | I5: 3686944 | J5: =H5-I5 -> 182000
B6: 2026여수세계섬박람회 운영 | H6: =SUM(H7,H21) -> 3868944 | I6: 3686944 | J6: =H6-I6 -> 182000
C7: 박람회장 운영 | H7: =SUM(H8) -> 3817156 | I7: 3635156 | J7: =H7-I7 -> 182000
D8: 대행사 선정 | H8: =SUM(H9) -> 3817156 | I8: 3635156 | J8: =H8-I8 -> 182000
E9: 200 물건비 | H9: =H10 -> 3817156 | I9: 3635156 | J9: =H9-I9 -> 182000
F10: 201 일반운영비 | H10: =SUM(M11,M13,M15,M19) -> 3817156 | I10: 3635156 | J10: =H10-I10 -> 182000
G11: 01 사무관리비 | H11: =M11+M13 -> 5000 | I11: 5000 | J11: =H11-I11 -> 0 | K11: [운영수당] | M11: =SUM(M12:M12) -> 4000
K12: ○ 세부실행계획 보고회 등 참석수당 : 100,000원*10명*4회 | L12: = | M12: 4000
K13: [임차료] | M13: =SUM(M14:M14) -> 1000
K14: ○ 세부실행계획 보고회 회의실 임차비 : 250,000원*4회 | L14: = | M14: 1000
G15: 03 행사운영비 | H15: =M15 -> 3810156 | I15: 3628156 | J15: =H15-I15 -> 182000 | K15: [행사운영비] | M15: =M18 -> 3810156
G16: [사업수익 3,810,156] | K16: ○ 2026여수세계섬박람회 회장운영 대행 용역비(2차분) : 3,628,156,000원*1식 | L16: = | M16: 3628156
K17: 추경1회
K18: ○ 2026여수세계섬박람회 회장운영 대행 용역비(2차분) : 경정 3,816,156,000원 | L18: = | M18: 3810156
G19: 14 회의비 | H19: =M19 -> 2000 | I19: 2000 | J19: =H19-I19 -> 0 | K19: [회의비] | M19: =M20 -> 2000
K20: ○ 세부실행계획 추진상황 보고회 등 운영비 500,000원*4회 | L20: = | M20: 2000
C21: 운영부 사무국운영 | H21: =H22 -> 51788 | I21: 51788 | J21: =H21-I21 -> 0
D22: 기본경비 | H22: =H23 -> 51788 | I22: 51788 | J22: =H22-I22 -> 0
E23: 200 물건비 | H23: =SUM(H24,H31,H35,H41) -> 51788 | I23: 51788 | J23: =H23-I23 -> 0
F24: 201 일반운영비 | H24: =SUM(H25,H29) -> 25128 | I24: 25128 | J24: =H24-I24 -> 0
G25: 01 사무관리비 | H25: =M25 -> 18000 | I25: 18000 | J25: =H25-I25 -> 0 | K25: [일반수용비] | M25: =SUM(M26:M28) -> 18000
K26: ○ 운영본부 사무용품 등 구입 : 6,000,000원*1식 | L26: = | M26: 6000
K27: ○ 운영본부 복사용지 및 토너 구입 : 7,000,000원*1식 | L27: = | M27: 7000
K28: ○ 운영본부 환경정비 및 청소용품 구입 : 5,000,000원*1식 | L28: = | M28: 5000
G29: 15 복리후생비 | H29: =M30 -> 7128 | I29: 7128 | J29: =H29-I29 -> 0 | K29: [급량비] | M29: =M30 -> 7128
K30: ○ 기본업무수행 급량비 : 9,000원*9명*8일*11월 | L30: = | M30: 7128
F31: 202 여비 | H31: =H32 -> 10060 | I31: 10060 | J31: =H31-I31 -> 0
G32: 01 국내여비 | H32: =M32 -> 10060 | I32: 10060 | J32: =H32-I32 -> 0 | K32: [국내여비] | M32: =SUM(M33:M34) -> 10060
K33: ○ 운영부 기본업무 수행 관내여비 : 20,000원*7명*2일*10월 | L33: = | M33: 2800
K34: ○ 운영부 기본업무 수행 관외여비 : 110,000원*6명*11월 | L34: = | M34: 7260
F35: 203 업무추진비 | H35: =H36 -> 12100 | I35: 12100 | J35: =H35-I35 -> 0
G36: 07 사업업무추진비 | H36: =SUM(M36,M38) -> 12100 | I36: 12100 | J36: =H36-I36 -> 0 | K36: [기관운영업무추진비] | M36: =SUM(M37:M37) -> 6600
K37: ○ 4급보조기관장(운영본부장) : 6,600,000원*1식 | L37: = | M37: 6600
K38: [시책추진업무추진비] | M38: =SUM(M39:M40) -> 5500
K39: ○ 박람회 운영 및 조성 업무추진(4급) : 4,000,000원*1식 | L39: = | M39: 4000
K40: ○ 운영부 업무추진 : 1,500,000원*1식 | L40: = | M40: 1500
...

Sheet 행사부
A1: 지출예산(세부사업) - 행사부 | M1: 단위 : 천원
A2: 구 분 | B2: 사업 | E2: 편성목 | H2: 경정액 (A) | I2: 기정액(본예산) (B) | J2: 비교증감 (A-B) | K2: 산 출 기 초
B3: 정책 | C3: 단위 | D3: 세부 | E3: 그룹 | F3: 목 | G3: 세목
A4: 총계(사업예산 + 자본예산) | H4: =H5 -> 96648 | I4: 20648 | J4: =H4-I4 -> 76000
A5: 사업예산 | H5: =H6 -> 96648 | I5: 20648 | J5: =H5-I5 -> 76000
B6: 2026여수세계섬박람회 행사 | H6: =SUM(H7,H25) -> 96648 | I6: 20648 | J6: =H6-I6 -> 76000
C7: 행사부 부서운영 | H7: =H8 -> 20648 | I7: 20648 | J7: =H7-I7 -> 0
D8: 기본경비 | H8: =H9 -> 20648 | I8: 20648 | J8: =H8-I8 -> 0
E9: 200 물건비 | H9: =SUM(H10,H15,H19,H22) -> 20648 | I9: 20648 | J9: =H9-I9 -> 0
F10: 201 일반운영비 | H10: =SUM(H11,H13) -> 8048 | I10: 8048 | J10: =H10-I10 -> 0
G11: 01 사무관리비 | H11: =M11 -> 2000 | I11: 2000 | J11: =H11-I11 -> 0 | K11: [일반수용비] | M11: =SUM(M12:M12) -> 2000
K12: ○ 부서운영을 위한 소모품 구입 : 200,000원*10월 | L12: = | M12: 2000
G13: 15 복리후생비 | H13: =M13 -> 6048 | I13: 6048 | J13: =H13-I13 -> 0 | K13: [급량비] | M13: =SUM(M14) -> 6048
K14: ○ 기본업무수행 급량비 : 9,000원*7명*8일*12월 | L14: = | M14: 6048
F15: 202 여비 | H15: =H16 -> 9000 | I15: 9000 | J15: =H15-I15 -> 0
G16: 01 국내여비 | H16: =M16 -> 9000 | I16: 9000 | J16: =H16-I16 -> 0 | K16: [국내여비] | M16: =SUM(M17:M18) -> 9000
K17: ○ 행사부 기본업무 수행 관내여비 : 20,000원*6명*2일*10월 | L17: = | M17: 2400
K18: ○ 행사부 기본업무 수행 관외여비 : 110,000원*6명*10월 | L18: = | M18: 6600
F19: 203 업무추진비 | H19: =H20 -> 1500 | I19: 1500 | J19: =H19-I19 -> 0
G20: 07 사업업무추진비 | H20: =M20 -> 1500 | I20: 1500 | J20: =H20-I20 -> 0 | K20: [시책추진업무추진비] | M20: =SUM(M21) -> 1500
K21: ○ 행사부 업무추진 :1,500,000원*1식 | L21: = | M21: 1500
F22: 217 관서업무비 | H22: =H23 -> 2100 | I22: 2100 | J22: =H22-I22 -> 0
G23: 02 부서업무비 | H23: =M23 -> 2100 | I23: 2100 | J23: =H23-I23 -> 0 | K23: [부서업무비] | M23: =M24 -> 2100
K24: ○ 행사부 부서운영 총액계상 : 175,000원*12월 | L24: = | M24: 2100
C25: 2026여수세계섬박람회 문화행사 운영(수익) | H25: =SUM(H26) -> 76000 | I25: 0 | J25: =H25-I25 -> 76000
D26: 문화행사 추진 | H26: =H27 -> 76000 | I26: 0 | J26: =H26-I26 -> 76000
E27: 200 물건비 | H27: =H28 -> 76000 | I27: 0 | J27: =H27-I27 -> 76000
F28: 201 일반운영비 | H28: =H29 -> 76000 | I28: 0 | J28: =H28-I28 -> 76000
G29: 03 행사운영비 | H29: =M29 -> 76000 | I29: 0 | J29: =H29-I29 -> 76000 | K29: [행사운영비] | M29: =M31 -> 76000
G30: [사업수익 76,000] | K30: 추경1회
K31: ○ 2026여수세계섬박람회 문화행사 운영 76,000,000원*1식 | L31: = | M31: 76000

Sheet 시설조성부
A1: 지출예산(세부사업) - 시설조성부 | M1: 단위 : 천원
A2: 구 분 | B2: 사업 | E2: 편성목 | H2: 경정액 (A) | I2: 기정액(본예산) (B) | J2: 비교증감 (A-B) | K2: 산 출 기 초
B3: 정책 | C3: 단위 | D3: 세부 | E3: 그룹 | F3: 목 | G3: 세목
A4: 총계(사업예산 + 자본예산) | H4: =H5+H38 -> 5372749 | I4: 7998648 | J4: =H4-I4 -> -2625899
A5: 사업예산 | H5: =H6 -> 1823648 | I5: 1765648 | J5: =H5-I5 -> 58000
B6: 2026여수세계섬박람회 시설조성 | H6: =SUM(H7,H14,H32) -> 1823648 | I6: 1765648 | J6: =H6-I6 -> 58000
C7: 2026여수세계섬박람회 시설조성 | H7: =H8 -> 58000 | I7: 0 | J7: =H7-I7 -> 58000
D8: 섬박람회장 전기·소방 안전관리대행 | H8: =H9 -> 58000 | I8: 0 | J8: =H8-I8 -> 58000
E9: 200 물건비 | H9: =H10 -> 58000 | I9: 0 | J9: =H9-I9 -> 58000
F10: 201 일반운영비 | H10: =H11 -> 58000 | I10: 0 | J10: =H10-I10 -> 58000
G11: 01 사무관리비 | H11: =M11 -> 58000 | I11: 0 | J11: =H11-I11 -> 58000 | K11: [일반수용비] | M11: =SUM(M13:M13) -> 58000
G12: [사업수익 58,000] | K12: 추경1회
K13: ○ 섬박람회장 전기·소방 안전관리대행 용역 58,000,000원*1식(법정경비) | L13: = | M13: 58000
C14: 시설조성부 부서운영 | H14: =H15 -> 20648 | I14: 20648 | J14: =H14-I14 -> 0
D15: 기본경비 | H15: =H16 -> 20648 | I15: 20648 | J15: =H15-I15 -> 0
E16: 200 물건비 | H16: =SUM(H17,H22,H26,H29) -> 20648 | I16: 20648 | J16: =H16-I16 -> 0
F17: 201 일반운영비 | H17: =SUM(H18,H20) -> 8048 | I17: 8048 | J17: =H17-I17 -> 0
G18: 01 사무관리비 | H18: =M18 -> 2000 | I18: 2000 | J18: =H18-I18 -> 0 | K18: [일반수용비] | M18: =SUM(M19:M19) -> 2000
K19: ○ 부서운영을 위한 소모품 구입 : 200,000원*10월 | L19: = | M19: 2000
G20: 15 복리후생비 | H20: =M20 -> 6048 | I20: 6048 | J20: =H20-I20 -> 0 | K20: [급량비] | M20: =M21 -> 6048
K21: ○ 기본업무수행 급량비 : 9,000원*7명*8일*12월 | L21: = | M21: 6048
F22: 202 여비 | H22: =H23 -> 9000 | I22: 9000 | J22: =H22-I22 -> 0
G23: 01 국내여비 | H23: =M23 -> 9000 | I23: 9000 | J23: =H23-I23 -> 0 | K23: [국내여비] | M23: =SUM(M24:M25) -> 9000
K24: ○ 시설조성부 기본업무 수행 관내여비 : 20,000원*6명*2일*10월 | L24: = | M24: 2400
K25: ○ 시설조성부 기본업무 수행 관외여비 : 110,000원*6명*10월 | L25: = | M25: 6600
F26: 203 업무추진비 | H26: =H27 -> 1500 | I26: 1500 | J26: =H26-I26 -> 0
G27: 07 사업업무추진비 | H27: =M27 -> 1500 | I27: 1500 | J27: =H27-I27 -> 0 | K27: [시책추진업무추진비] | M27: =SUM(M28) -> 1500
K28: ○ 시설조성부 업무추진 : 1,500,000원*1식 | L28: = | M28: 1500
F29: 217 관서업무비 | H29: =H30 -> 2100 | I29: 2100 | J29: =H29-I29 -> 0
G30: 02 부서업무비 | H30: =M30 -> 2100 | I30: 2100 | J30: =H30-I30 -> 0 | K30: [부서업무비] | M30: =M31 -> 2100
K31: ○ 시설조성부 부서운영 총액계상 : 175,000원*12월 | L31: = | M31: 2100
C32: 2026여수세계섬박람회 시설조성(수익) | H32: =SUM(H33) -> 1745000 | I32: 1745000 | J32: =H32-I32 -> 0
D33: 전시관 및 운영·부대시설 설치 | H33: =H34 -> 1745000 | I33: 1745000 | J33: =H33-I33 -> 0
E34: 200 물건비 | H34: =H35 -> 1745000 | I34: 1745000 | J34: =H34-I34 -> 0
F35: 201 일반운영비 | H35: =H36 -> 1745000 | I35: 1745000 | J35: =H35-I35 -> 0
G36: 03 행사운영비 | H36: =M36 -> 1745000 | I36: 1745000 | J36: =H36-I36 -> 0 | K36: [행사운영비] | M36: =M37 -> 1745000
G37: [사업수익 1,745,000] | K37: ○ 섬박람회 전시관 및 운영·부대시설 설치 1,745,000,000원*1식 | L37: = | M37: 1745000
A38: 자본예산 | H38: =SUM(H39,H48,H57) -> 3549101 | I38: 6233000 | J38: =H38-I38 -> -2683899
B39: 2026여수세계섬박람회 조성연출 | H39: =SUM(H40,H66) -> 3249101 | I39: 3233000 | J39: =H39-I39 -> 16101
C40: 박람회 조성 | H40: =SUM(H41) -> 3249101 | I40: 3233000 | J40: =H40-I40 -> 16101
...

Sheet 전시연출부
A1: 지출예산(세부사업) - 전시연출부 | M1: 단위 : 천원
A2: 구 분 | B2: 사업 | E2: 편성목 | H2: 경정액 (A) | I2: 기정액(본예산) (B) | J2: 비교증감 (A-B) | K2: 산 출 기 초
B3: 정책 | C3: 단위 | D3: 세부 | E3: 그룹 | F3: 목 | G3: 세목
A4: 총계(사업예산 + 자본예산) | H4: =H5 -> 2121344 | I4: 2121344 | J4: =H4-I4 -> 0
A5: 사업예산 | H5: =H6 -> 2121344 | I5: 2121344 | J5: =H5-I5 -> 0
B6: 2026여수세계섬박람회 전시연출 | H6: =SUM(H7,H31) -> 2121344 | I6: 2121344 | J6: =H6-I6 -> 0
C7: 2026여수세계섬박람회 전시연출 | H7: =SUM(H8,H21,H26) -> 2101200 | I7: 2101200 | J7: =H7-I7 -> 0
D8: 박람회 전시연출 | H8: =H9 -> 2098000 | I8: 2098000 | J8: =H8-I8 -> 0
E9: 200 물건비 | H9: =H10 -> 2098000 | I9: 2098000 | J9: =H9-I9 -> 0
F10: 201 일반운영비 | H10: =SUM(H11,H17) -> 2098000 | I10: 2098000 | J10: =H10-I10 -> 0
G11: 01 사무관리비 | H11: =SUM(M12,M16) -> 5600 | I11: 5600 | J11: =H11-I11 -> 0 | K11: [세출예산 변경사용] - 2026. 3. 10.
K12: [운영수당] | M12: =SUM(M13:M14) -> 4000
K13: ○ 제안서 평가위원 심사수당 300,000원*10명 | L13: = | M13: 3000
K14: ○ 제안서 평가위원 실비 1,000,000원*1식 | M14: 1000
K15: [임차료]
K16: ○ 회의실 임차료 : 400,000원*4회 | L16: = | M16: 1600
G17: 03 행사운영비 | H17: =M17 -> 2092400 | I17: 2092400 | J17: =H17-I17 -> 0 | K17: [행사운영비] | M17: =M20 -> 2092400
K18: ○ 전시연출 콘텐츠 개발 2,098,000,000원*1식 | L18: = | M18: 2098000
K19: [세출예산 변경사용] - 2026. 3. 10.
K20: ○ 전시연출 콘텐츠 개발 : 경정 2,092,400,000원 | L20: = | M20: 2092400
D21: 섬 테마존 조성 업무 추진 | H21: =H22 -> 1600 | I21: 1600 | J21: =H21-I21 -> 0
E22: 200 물건비 | H22: =H23 -> 1600 | I22: 1600 | J22: =H22-I22 -> 0
F23: 201 일반운영비 | H23: =SUM(H24) -> 1600 | I23: 1600 | J23: =H23-I23 -> 0
G24: 01 사무관리비 | H24: =M24 -> 1600 | I24: 1600 | J24: =H24-I24 -> 0 | K24: [임차료] | M24: =SUM(M25) -> 1600
K25: ○ 회의실 임차료 : 400,000원*4회 | L25: = | M25: 1600
D26: 섬박람회 상징 아트포토존 조성 업무 추진 | H26: =H27 -> 1600 | I26: 1600 | J26: =H26-I26 -> 0
E27: 200 물건비 | H27: =H28 -> 1600 | I27: 1600 | J27: =H27-I27 -> 0
F28: 201 일반운영비 | H28: =SUM(H29) -> 1600 | I28: 1600 | J28: =H28-I28 -> 0
G29: 01 사무관리비 | H29: =M29 -> 1600 | I29: 1600 | J29: =H29-I29 -> 0 | K29: [임차료] | M29: =SUM(M30) -> 1600
K30: ○ 회의실 임차료 : 400,000원*4회 | L30: = | M30: 1600
C31: 전시연출부 부서운영 | H31: =H32 -> 20144 | I31: 20144 | J31: =H31-I31 -> 0
D32: 기본경비 | H32: =H33 -> 20144 | I32: 20144 | J32: =H32-I32 -> 0
E33: 200 물건비 | H33: =SUM(H34,H39,H43,H46) -> 20144 | I33: 20144 | J33: =H33-I33 -> 0
F34: 201 일반운영비 | H34: =SUM(H35,H37) -> 7544 | I34: 7544 | J34: =H34-I34 -> 0
G35: 01 사무관리비 | H35: =M35 -> 2000 | I35: 2000 | J35: =H35-I35 -> 0 | K35: [일반수용비] | M35: =SUM(M36:M36) -> 2000
K36: ○ 부서운영을 위한 소모품 구입 : 200,000원*10월 | L36: = | M36: 2000
G37: 15 복리후생비 | H37: =M37 -> 5544 | I37: 5544 | J37: =H37-I37 -> 0 | K37: [급량비] | M37: =SUM(M38) -> 5544
K38: ○ 기본업무수행 급량비 : 9,000원*7명*8일*11월 | L38: = | M38: 5544
F39: 202 여비 | H39: =H40 -> 9000 | I39: 9000 | J39: =H39-I39 -> 0
G40: 01 국내여비 | H40: =M40 -> 9000 | I40: 9000 | J40: =H40-I40 -> 0 | K40: [국내여비] | M40: =SUM(M41:M42) -> 9000
...

Sheet 예비비
A1: 지출예산(세부사업) - 예비비 | M1: 단위 : 천원
A2: 구 분 | B2: 사업 | E2: 편성목 | H2: 경정액 (A) | I2: 기정액(본예산) (B) | J2: 비교증감 (A-B) | K2: 산 출 기 초
B3: 정책 | C3: 단위 | D3: 세부 | E3: 그룹 | F3: 목 | G3: 세목
A4: 총계(사업예산 + 자본예산) | H4: =H5+H21 -> 3189846 | I4: 596200 | J4: =H4-I4 -> 2593646
A5: 사업예산 | H5: =H6 -> 3189846 | I5: 596200 | J5: =H5-I5 -> 2593646
B6: 예비비 | H6: =H7 -> 3189846 | I6: 596200 | J6: =H6-I6 -> 2593646
C7: 예비비 | H7: =SUM(H8,H15) -> 3189846 | I7: 596200 | J7: =H7-I7 -> 2593646
D8: 예비비 | H8: =H9 -> 3119546 | I8: 596200 | J8: =H8-I8 -> 2523346
E9: 800 예비비 | H9: =H10 -> 3119546 | I9: 596200 | J9: =H9-I9 -> 2523346
F10: 801 예비비 | H10: =H11 -> 3119546 | I10: 596200 | J10: =H10-I10 -> 2523346
G11: 01 일반예비비 | H11: =M11 -> 3119546 | I11: 596200 | J11: =H11-I11 -> 2523346 | K11: [일반예비비] | M11: =M14 -> 3119546
G12: [출연금 3,326, 사업수익 2,938,953, 영업외수익 177,267] | K12: ○ 예비비 : 596,200,000원*1식 | L12: = | M12: 596200
K13: 추경1회
K14: ○ 예비비 : 경정 3,119,546,000원 | L14: = | M14: 3119546
D15: 재해·재난·안전 목적 예비비 | H15: =H16 -> 70300 | I15: 0 | J15: =H15-I15 -> 70300
E16: 800 예비비 | H16: =H17 -> 70300 | I16: 0 | J16: =H16-I16 -> 70300
F17: 801 예비비 | H17: =H18 -> 70300 | I17: 0 | J17: =H17-I17 -> 70300
G18: 02 재해·재난목적예비비 | H18: =M18 -> 70300 | I18: 0 | J18: =H18-I18 -> 70300 | K18: [일반예비비] | M18: =M20 -> 70300
G19: [영업외수익 70,300] | K19: 추경1회
K20: ○ 재해·재난·안전 목적 예비비 : 70,300,000원*1식 | L20: = | M20: 70300
A21: 자본예산 | H21: =SUM(H22,H35) -> 0 | I21: 0 | J21: =H21-I21 -> 0
B22: 예비비(자본) | H22: =SUM(H23,H63) -> 0 | I22: 0 | J22: =H22-I22 -> 0
C23: 예비비(자본) | H23: =H24 -> 0 | I23: 0 | J23: =H23-I23 -> 0
D24: 예비비(자본) | H24: =H25 -> 0 | I24: 0 | J24: =H24-I24 -> 0
E25: 800 예비비 | H25: =H26 -> 0 | I25: 0 | J25: =H25-I25 -> 0
F26: 801 예비비 | H26: =H27 -> 0 | I26: 0 | J26: =H26-I26 -> 0
G27: 01 일반예비비 | H27: =M27 -> 0 | I27: 0 | J27: =H27-I27 -> 0 | K27: [일반예비비] | M27: =M28 -> 0
K28: ○ 예비비(자본) : 0원 | L28: = | M28: 0

Sheet 지출예산(위탁)
A1: 지출예산(위탁) - 본예산
I2: (단위 : 천 원)
A3: 과 목 | G3: 경정액 (A) | H3: 기정액(본예산) (B) | I3: 비교증감 (A-B)
A4: 구분 | B4: 정책사업 | C4: 단위사업 | D4: 세부사업 | E4: 목 | F4: 세목
A5: 총계(사업예산+자본예산) | G5: =G6+G54 -> 17270000 | H5: 14320000 | I5: =G5-H5 -> 2950000
A6: 사업예산 | G6: =SUM(G7,G17,G49) -> 11000000 | H6: 10750000 | I6: =G6-H6 -> 250000
B7: 2026여수세계섬박람회 기획홍보(위탁) | G7: ='기획본부(위탁)'!H6 -> 1000000 | H7: 1000000 | I7: =G7-H7 -> 0
C8: 2026여수세계섬박람회 홍보 | G8: ='기획본부(위탁)'!H7 -> 1000000 | H8: 1000000 | I8: =G8-H8 -> 0
D9: 박람회 홍보 | G9: ='기획본부(위탁)'!H8 -> 1000000 | H9: 1000000 | I9: =G9-H9 -> 0
E10: 일반운영비 | G10: ='기획본부(위탁)'!H10 -> 965000 | H10: 965000 | I10: =G10-H10 -> 0
F11: 사무관리비 | G11: ='기획본부(위탁)'!H11 -> 345000 | H11: 345000 | I11: =G11-H11 -> 0
F12: 행사운영비 | G12: ='기획본부(위탁)'!H17 -> 120000 | H12: 120000 | I12: =G12-H12 -> 0
F13: 광고선전비 | G13: ='기획본부(위탁)'!H21 -> 500000 | H13: 500000 | I13: =G13-H13 -> 0
E14: 일반보상금 | G14: ='기획본부(위탁)'!H24 -> 35000 | H14: 35000 | I14: =G14-H14 -> 0
F15: 행사실비보상금 | G15: ='기획본부(위탁)'!H25 -> 10000 | H15: 10000 | I15: =G15-H15 -> 0
F16: 기타보상금 | G16: ='기획본부(위탁)'!H27 -> 25000 | H16: 25000 | I16: =G16-H16 -> 0
B17: 2026여수세계섬박람회 유치협력(위탁) | G17: ='기획본부(위탁)'!H30 -> 4500000 | H17: 4250000 | I17: =G17-H17 -> 250000
C18: 2026여수세계섬박람회 유치 | G18: ='기획본부(위탁)'!H31 -> 4250000 | H18: 4250000 | I18: =G18-H18 -> 0
D19: 관람객 유치 | G19: ='기획본부(위탁)'!H32 -> 250000 | H19: 250000 | I19: =G19-H19 -> 0
E20: 일반보상금 | G20: ='기획본부(위탁)'!H34 -> 250000 | H20: 250000 | I20: =G20-H20 -> 0
F21: 기타보상금 | G21: ='기획본부(위탁)'!H35 -> 250000 | H21: 250000 | I21: =G21-H21 -> 0
D22: 기업관 부스 운영 | G22: ='기획본부(위탁)'!H41 -> 60000 | H22: 60000 | I22: =G22-H22 -> 0
E23: 일반운영비 | G23: ='기획본부(위탁)'!H43 -> 60000 | H23: 60000 | I23: =G23-H23 -> 0
F24: 행사운영비 | G24: ='기획본부(위탁)'!H44 -> 60000 | H24: 60000 | I24: =G24-H24 -> 0
D25: 참가국 지원 | G25: ='기획본부(위탁)'!H46 -> 3070000 | H25: 3070000 | I25: =G25-H25 -> 0
E26: 일반운영비 | G26: ='기획본부(위탁)'!H48 -> 2340000 | H26: 2340000 | I26: =G26-H26 -> 0
F27: 행사운영비 | G27: ='기획본부(위탁)'!H49 -> 2340000 | H27: 2340000 | I27: =G27-H27 -> 0
E28: 일반보상금 | G28: ='기획본부(위탁)'!H52 -> 730000 | H28: 730000 | I28: =G28-H28 -> 0
F29: 외빈초청여비 | G29: ='기획본부(위탁)'!H53 -> 730000 | H29: 730000 | I29: =G29-H29 -> 0
D30: 2026국제섬포럼 in Yeosu | G30: ='기획본부(위탁)'!H55 -> 270000 | H30: 270000 | I30: =G30-H30 -> 0
E31: 일반운영비 | G31: ='기획본부(위탁)'!H57 -> 224000 | H31: 224000 | I31: =G31-H31 -> 0
F32: 사무관리비 | G32: ='기획본부(위탁)'!H58 -> 4000 | H32: 4000 | I32: =G32-H32 -> 0
F33: 행사운영비 | G33: ='기획본부(위탁)'!H61 -> 220000 | H33: 220000 | I33: =G33-H33 -> 0
E34: 일반보상금 | G34: ='기획본부(위탁)'!H64 -> 46000 | H34: 46000 | I34: =G34-H34 -> 0
F35: 외빈초청여비 | G35: ='기획본부(위탁)'!H65 -> 46000 | H35: 46000 | I35: =G35-H35 -> 0
D36: 세계섬도시대회 | G36: ='기획본부(위탁)'!H67 -> 600000 | H36: 600000 | I36: =G36-H36 -> 0
E37: 일반운영비 | G37: ='기획본부(위탁)'!H69 -> 358000 | H37: 358000 | I37: =G37-H37 -> 0
F38: 사무관리비 | G38: ='기획본부(위탁)'!H70 -> 4000 | H38: 4000 | I38: =G38-H38 -> 0
F39: 행사운영비 | G39: ='기획본부(위탁)'!H73 -> 354000 | H39: 354000 | I39: =G39-H39 -> 0
E40: 일반보상금 | G40: ='기획본부(위탁)'!H76 -> 242000 | H40: 242000 | I40: =G40-H40 -> 0
...

Sheet 기획본부(위탁)
A1: 지출예산 - 기획본부(위탁) | M1: 단위 : 천 원
A2: 구 분 | B2: 사업 | E2: 편성목 | H2: 경정액 (A) | I2: 기정액(본예산) (B) | J2: 비교증감 (A-B) | K2: 산 출 기 초
B3: 정책 | C3: 단위 | D3: 세부 | E3: 그룹 | F3: 목 | G3: 세목
A4: 총계(사업예산 + 자본예산) | H4: =H5 -> 5500000 | I4: 5250000 | J4: =H4-I4 -> 250000
A5: 사업예산 | H5: =H6+H30 -> 5500000 | I5: 5250000 | J5: =H5-I5 -> 250000
B6: 2026여수세계섬박람회 기획홍보(위탁) | H6: =H7 -> 1000000 | I6: 1000000 | J6: =H6-I6 -> 0
C7: 2026여수세계섬박람회 홍보 | H7: =H8 -> 1000000 | I7: 1000000 | J7: =H7-I7 -> 0
D8: 박람회 홍보 | H8: =H9+H23 -> 1000000 | I8: 1000000 | J8: =H8-I8 -> 0
E9: 200 물건비 | H9: =H10 -> 965000 | I9: 965000 | J9: =H9-I9 -> 0
F10: 201 일반운영비 | H10: =SUM(H11,H17,H21) -> 965000 | I10: 965000 | J10: =H10-I10 -> 0
G11: 01 사무관리비 | H11: =M11 -> 345000 | I11: 345000 | J11: =H11-I11 -> 0 | K11: [사무관리비] | M11: =SUM(M12:M16) -> 345000
G12: [도 103,500, 시 241,500] | K12: ○ 홍보물품 등 제작 : 200,000,000원*1식 | L12: = | M12: 200000
K13: ○ 홍보콘텐츠 등 제작 : 100,000,000원*1식 | L13: = | M13: 100000
K14: ○ 홍보부스 참가비 : 40,000,000원*1식 | L14: = | M14: 40000
K15: ○ 제안서, 공모전 평가위원 수당 : 4,000,000원*1식 | L15: = | M15: 4000
K16: ○ 제안서, 공모전 평가위원 실비 : 1,000,000원*1식 | L16: = | M16: 1000
G17: 03 행사운영비 | H17: =M17 -> 120000 | I17: 120000 | J17: =H17-I17 -> 0 | K17: [행사운영비] | M17: =SUM(M18:M20) -> 120000
G18: [도 36,000, 시 84,000] | K18: ○ 사전 홍보 이벤트 : 50,000,000원*1식 | L18: = | M18: 50000
K19: ○ 홍보부스 운영 : 5,000,000원*10회 | L19: = | M19: 50000
K20: ○ 홍보대사, 서포터즈 운영 : 20,000,000원*1식 | L20: = | M20: 20000
G21: 16 광고선전비 | H21: =M21 -> 500000 | I21: 500000 | J21: =H21-I21 -> 0 | K21: [광고료] | M21: =SUM(M22) -> 500000
G22: [도 150,000, 시 350,000] | K22: ○ 섬박람회 광고 홍보료 : 500,000,000원*1식 | L22: = | M22: 500000
E23: 300 경상이전 | H23: =H24 -> 35000 | I23: 35000 | J23: =H23-I23 -> 0
F24: 301 일반보상금 | H24: =SUM(H25,H27) -> 35000 | I24: 35000 | J24: =H24-I24 -> 0
G25: 10 행사실비보상금 | H25: =M25 -> 10000 | I25: 10000 | J25: =H25-I25 -> 0 | K25: [행사실비보상금] | M25: =SUM(M26:M26) -> 10000
G26: [도 3,000, 시 7,000] | K26: ○ 홍보대사, 서포터즈 등 실비 : 100,000원*20명*5회 | L26: = | M26: 10000
G27: 14 기타보상금 | H27: =M27 -> 25000 | I27: 25000 | J27: =H27-I27 -> 0 | K27: [기타보상금] | M27: =SUM(M28:M29) -> 25000
G28: [도 7,500, 시 17,500] | K28: ○ 공모전 시상금 : 5,000,000원*3회 | L28: = | M28: 15000
K29: ○ 각종 이벤트 경품 : 10,000,000원*1식 | L29: = | M29: 10000
B30: 2026여수세계섬박람회 유치협력(위탁) | H30: =SUM(H31,H79) -> 4500000 | I30: 1770000 | J30: =H30-I30 -> 2730000
C31: 2026여수세계섬박람회 유치 | H31: =SUM(H32,H41,H46,H55,H67) -> 4250000 | I31: 1520000 | J31: =H31-I31 -> 2730000
D32: 관람객 유치 | H32: =H33 -> 250000 | I32: 250000 | J32: =H32-I32 -> 0
E33: 300 경상이전 | H33: =H34 -> 250000 | I33: 250000 | J33: =H33-I33 -> 0
F34: 301 일반보상금 | H34: =SUM(H35) -> 250000 | I34: 250000 | J34: =H34-I34 -> 0
G35: 14 기타보상금 | H35: =SUM(M35) -> 250000 | I35: 250000 | J35: =H35-I35 -> 0 | K35: [기타보상금] | M35: =SUM(M36:M36) -> 250000
G36: [도 75,000, 시 175,000] | K36: ○ 공식여행사 인센티브 지급 250,000,000원*1식 | L36: = | M36: 250000
E37: 300 경상이전 | H37: =H38 -> 730000 | I37: 730000 | J37: =H37-I37 -> 0
F38: 301 일반보상금 | H38: =SUM(H39) -> 730000 | I38: 730000 | J38: =H38-I38 -> 0
G39: 13 외빈초청여비 | H39: =SUM(M39) -> 730000 | I39: 730000 | J39: =H39-I39 -> 0 | K39: [외빈초청여비] | M39: =SUM(M40:M40) -> 730000
G40: [도 219,000, 시 511,000] | K40: ○ 참가국 초청대상자 등 외빈 초청 730,000,000원*1식 | L40: = | M40: 730000
...

Sheet 운영본부(위탁)
A1: 지출예산 - 운영본부(위탁) | M1: 단위 : 천 원
A2: 구 분 | B2: 사업 | E2: 편성목 | H2: 경정액 (A) | I2: 기정액(본예산) (B) | J2: 비교증감 (A-B) | K2: 산 출 기 초
B3: 정책 | C3: 단위 | D3: 세부 | E3: 그룹 | F3: 목 | G3: 세목
A4: 총계(사업예산 + 자본예산) | H4: =H5+H13 -> 11770000 | I4: 9070000 | J4: =H4-I4 -> 2700000
A5: 사업예산 | H5: =H6 -> 5500000 | I5: 5500000 | J5: =H5-I5 -> 0
B6: 2026여수세계섬박람회 행사(위탁) | H6: =H7 -> 5500000 | I6: 5500000 | J6: =H6-I6 -> 0
C7: 2026여수세계섬박람회 행사 | H7: =H8 -> 5500000 | I7: 5500000 | J7: =H7-I7 -> 0
D8: 문화행사 추진 | H8: =H9 -> 5500000 | I8: 5500000 | J8: =H8-I8 -> 0
E9: 200 물건비 | H9: =H10 -> 5500000 | I9: 5500000 | J9: =H9-I9 -> 0
F10: 201 일반운영비 | H10: =H11 -> 5500000 | I10: 5500000 | J10: =H10-I10 -> 0
G11: 03 행사운영비 | H11: =M11 -> 5500000 | I11: 5500000 | J11: =H11-I11 -> 0 | K11: [행사운영비] | M11: =M12 -> 5500000
G12: [도 1,650,000, 시 3,850,000] | K12: ○ 2026여수세계섬박람회 문화행사 운영 : 5,500,000,000원*1식 | L12: = | M12: 5500000
A13: 자본예산 | H13: =H14+H43 -> 6270000 | I13: 3570000 | J13: =H13-I13 -> 2700000
B14: 2026여수세계섬박람회 시설조성(위탁) | H14: =H15 -> 4680000 | I14: 1980000 | J14: =H14-I14 -> 2700000
C15: 2026여수세계섬박람회 시설조성 | H15: =SUM(H16,H23,H33,H38) -> 4680000 | I15: 1980000 | J15: =H15-I15 -> 2700000
D16: 섬박람회 랜드마크 조성사업 | H16: =H17 -> 2200000 | I16: 1200000 | J16: =H16-I16 -> 1000000
E17: 400 자본지출 | H17: =H18 -> 2200000 | I17: 1200000 | J17: =H17-I17 -> 1000000
F18: 401 시설비및부대비 | H18: =SUM(H19) -> 2200000 | I18: 1200000 | J18: =H18-I18 -> 1000000
G19: 01 시설비 | H19: =M19 -> 2200000 | I19: 1200000 | J19: =H19-I19 -> 1000000 | K19: [시설비] | M19: =SUM(M22) -> 2200000
G20: [도 1,500,000, 시 700,000] | K20: ○ 섬박람회 랜드마크 조성사업 : 1,200,000,000원*1식 [도 1,200,000] | L20: = | M20: 1200000
K21: 추경1회
K22: ○ 섬박람회 랜드마크 조성사업 : 경정 2,200,000,000원*1식 [도 1,500,000, 시 700,000] | L22: = | M22: 2200000
D23: 섬박람회장 안전시설물 설치사업 | H23: =H24 -> 2000000 | I23: 300000 | J23: =H23-I23 -> 1700000
E24: 400 자본지출 | H24: =H25 -> 2000000 | I24: 300000 | J24: =H24-I24 -> 1700000
F25: 401 시설비및부대비 | H25: =SUM(H26,H30) -> 2000000 | I25: 300000 | J25: =H25-I25 -> 1700000
G26: 01 시설비 | H26: =M26 -> 1990956 | I26: 300000 | J26: =H26-I26 -> 1690956 | K26: [시설비] | M26: =SUM(M29) -> 1990956
G27: [도 600,000, 시 1,390,956] | K27: ○ 섬박람회장 안전시설물 설치사업 : 300,000,000원*1식 [도 300,000] | L27: = | M27: 300000
K28: 추경1회
K29: ○ 섬박람회장 안전시설물 설치사업 : 경정 1,990,956,000원*1식 [도 600,000, 시 1,390,956] | L29: = | M29: 1990956
G30: 03 시설부대비 | H30: =M30 -> 9044 | I30: 0 | J30: =H30-I30 -> 9044 | K30: [시설부대비] | M30: =SUM(M32) -> 9044
G31: [시 9,044] | K31: 추경1회
K32: ○ 섬박람회장 안전시설물 설치사업 : 9,044,000원*1식 | L32: = | M32: 9044
D33: 섬박람회장 입구게이트 조성 | H33: =H34 -> 90000 | I33: 90000 | J33: =H33-I33 -> 0
E34: 400 자본지출 | H34: =H35 -> 90000 | I34: 90000 | J34: =H34-I34 -> 0
F35: 401 시설비및부대비 | H35: =SUM(H36) -> 90000 | I35: 90000 | J35: =H35-I35 -> 0
G36: 01 시설비 | H36: =M36 -> 90000 | I36: 90000 | J36: =H36-I36 -> 0 | K36: [시설비] | M36: =M37 -> 90000
G37: [도 90,000] | K37: ○ 섬박람회장 입구게이트 조성 : 90,000,000원*1식 | L37: = | M37: 90000
D38: 섬박람회장 열린문화공간 조성 | H38: =H39 -> 390000 | I38: 390000 | J38: =H38-I38 -> 0
E39: 400 자본지출 | H39: =H40 -> 390000 | I39: 390000 | J39: =H39-I39 -> 0
F40: 401 시설비및부대비 | H40: =SUM(H41) -> 390000 | I40: 390000 | J40: =H40-I40 -> 0
...
